Workbook

Sheet controls_macro
A1: date | B1: ExcR | C1: Stock R | D1: infl | E1: log Q | F1: FFR_real | G1: Real 10y r | H1: jln_f | I1: jln_m | J1: ip
A2: 25934 | B2: 2.9069392 | C2: 0.98673688 | D2: 0 | E2: 1.9707652 | F2: 3.8789975 | G2: -1.9202023 | H2: 0.98585718 | I2: 0.69054331 | J2: -1.10393
A3: 25965 | B3: 2.1552336 | C3: -0.016199972 | D3: 0.25125628 | E3: 1.987264 | F3: 3.72 | G3: -2.1714336 | H3: 0.93514852 | I3: 0.65402447 | J3: -1.22731
A4: 25993 | B4: 2.2596316 | C4: -0.38344474 | D4: 0.25062657 | E4: 1.9982593 | F4: 3.450725 | G4: -2.6430763 | H4: 0.91392248 | I4: 0.62728172 | J4: -1.20619
A5: 26024 | B5: 1.6889314 | C5: -0.52338063 | D5: 0.25 | E5: 2.0128372 | F5: 3.9002494 | G5: -2.212312 | H5: 0.89663865 | I5: 0.61762489 | J5: -0.39507
A6: 26054 | B6: 1.9720664 | C6: 0.10390743 | D6: 0.49875312 | E6: 2.0068937 | F6: 4.1107444 | G6: -1.8681589 | H6: 0.89624408 | I6: 0.6178311 | J6: 0.22719
A7: 26085 | B7: 2.1075067 | C7: 0.54539188 | D7: 0.74441687 | E7: 1.9987823 | F7: 4.3919259 | G7: -1.5621148 | H7: 0.88967799 | I7: 0.6309478 | J7: 0.97395
A8: 26115 | B8: 1.8203843 | C8: 0.56486701 | D8: 0.24630542 | E8: 1.9956352 | F8: 5.0506158 | G8: -1.2555173 | H8: 0.90538703 | I8: 0.63885358 | J8: 0.43431
A9: 26146 | B9: 1.5625619 | C9: 0.13821978 | D9: 0.24570025 | E9: 1.987845 | F9: 5.3106143 | G9: -1.4243421 | H9: 0.89876795 | I9: 0.63661393 | J9: 0.02977
A10: 26177 | B10: 1.7798269 | C10: -0.078476908 | D10: 0 | E10: 1.9973864 | F10: 5.291299 | G10: -1.8583038 | H10: 0.89046401 | I10: 0.63044534 | J10: 2.36101
A11: 26207 | B11: 1.6400858 | C11: -0.30851431 | D11: 0.24509804 | E11: 1.9880682 | F11: 4.9427873 | G11: -1.9486001 | H11: 0.90189955 | I11: 0.61805996 | J11: 5.23241
A12: 26238 | B12: 2.7600406 | C12: 0.79033508 | D12: 0 | E12: 1.9674544 | F12: 4.654122 | G12: -1.9697056 | H12: 0.90334507 | I12: 0.61788141 | J12: 6.32293
A13: 26268 | B13: 0.55071478 | C13: -0.60866979 | D13: 0.48899756 | E13: 1.9963803 | F13: 3.886618 | G13: -1.1593846 | H13: 0.9236977 | I13: 0.63142392 | J13: 5.13564
... A567: 43132 | B567: 7.2760109 | C567: 4.9117557 | D567: 0.453469 | E567: 3.432193 | F567: 1.1476814 | G567: -2.3642552 | H567: 0.75815761 | I567: 0.58632664 | J567: 3.38649

Sheet controls_fin
A1: date | B1: 10y_rf_f | C1: mkt_rf | D1: smb | E1: hml | F1: intermediary_capital_ratio | G1: intermediary_capital_risk_factor | H1: intermediary_value_weighted_investment_return | I1: interm_cr_growth | J1: 10y_inv_return_f | K1: unw_primdeal_ratio | L1: fin_industry_rato
A2: 25934 | B2: 0.35110026 | C2: 0.0484 | D2: 0.0744 | E2: 0.0135 | F2: 0.0706 | G2: -0.0233 | H2: -0.0147 | I2: 0.023311994 | J2: {=(PRODUCT(1+controls_fin!H2:H121)^(1/120)-1)*100} -> 0.36135513 | K2: 0.00225 | L2: 0.0050071429
A3: 25965 | B3: 0.352268 | C3: 0.0141 | D3: 0.019 | E3: -0.0134 | F3: 0.0716 | G3: 0.0163 | H3: 0.0236 | I3: 0.032134062 | J3: {=(PRODUCT(1+controls_fin!H3:H122)^(1/120)-1)*100} -> 0.35127907 | K3: 0.00225 | L3: 0.016825276
A4: 25993 | B4: 0.3536031 | C4: 0.0413 | D4: 0.0257 | E4: -0.0399 | F4: 0.0761 | G4: 0.0662 | H4: 0.0996 | I4: 0.098586466 | J4: {=(PRODUCT(1+controls_fin!H4:H123)^(1/120)-1)*100} -> 0.36312341 | K4: 0.00225 | L4: 0.069396056
A5: 26024 | B5: 0.35427053 | C5: 0.0315 | D5: -0.0048 | E5: 0.0074 | F5: 0.0728 | G5: -0.0405 | H5: -0.0394 | I5: 0.04217119 | J5: {=(PRODUCT(1+controls_fin!H5:H124)^(1/120)-1)*100} -> 0.30078735 | K5: 0.01475 | L5: 0.068828947
A6: 26054 | B6: 0.35527177 | C6: -0.0398 | D6: -0.0111 | E6: -0.0137 | F6: 0.0681 | G6: -0.0617 | H6: -0.0694 | I6: -0.036775106 | J6: {=(PRODUCT(1+controls_fin!H6:H125)^(1/120)-1)*100} -> 0.35070413 | K6: 0.01475 | L6: 0.066443812
A7: 26085 | B7: 0.35685638 | C7: -0.001 | D7: -0.0143 | E7: -0.02 | F7: 0.0632 | G7: -0.0698 | H7: -0.0303 | I7: -0.11701013 | J7: {=(PRODUCT(1+controls_fin!H7:H126)^(1/120)-1)*100} -> 0.4717929 | K7: 0.01475 | L7: 0.00079219512
A8: 26115 | B8: 0.35852401 | C8: -0.045 | D8: -0.015 | E8: 0.0017 | F8: 0.0613 | G8: -0.0292 | H8: -0.0371 | I8: -0.14910353 | J8: {=(PRODUCT(1+controls_fin!H8:H127)^(1/120)-1)*100} -> 0.50090091 | K8: 0.0005 | L8: -0.010542803
A9: 26146 | B9: 0.36094151 | C9: 0.0379 | D9: -0.0018 | E9: 0.0271 | F9: 0.0623 | G9: 0.0169 | H9: 0.0296 | I9: -0.13945324 | J9: {=(PRODUCT(1+controls_fin!H9:H128)^(1/120)-1)*100} -> 0.49601606 | K9: 0.0005 | L9: -0.0022848297
A10: 26177 | B10: 0.36286023 | C10: -0.0085 | D10: 0.0041 | E10: -0.0294 | F10: 0.0615 | G10: -0.013 | H10: 0.0091 | I10: -0.1563786 | J10: {=(PRODUCT(1+controls_fin!H10:H129)^(1/120)-1)*100} -> 0.43567135 | K10: 0.0005 | L10: 0.0072878049
A11: 26207 | B11: 0.36452845 | C11: -0.0442 | D11: -0.0178 | E11: -0.0047 | F11: 0.0605 | G11: -0.0148 | H11: -0.0218 | I11: -0.17570253 | J11: {=(PRODUCT(1+controls_fin!H11:H130)^(1/120)-1)*100} -> 0.41467696 | K11: 0.012 | L11: 0.021817788
A12: 26238 | B12: 0.36602973 | C12: -0.0046 | D12: -0.0283 | E12: -0.0174 | F12: 0.0631 | G12: 0.043 | H12: 0.039 | I12: -0.14772919 | J12: {=(PRODUCT(1+controls_fin!H12:H131)^(1/120)-1)*100} -> 0.49281157 | K12: 0.012 | L12: 0.016494771
A13: 26268 | B13: 0.36786502 | C13: 0.0871 | D13: 0.0329 | E13: -0.003 | F13: 0.0786 | G13: 0.2461 | H13: 0.0554 | I13: 0.053972511 | J13: {=(PRODUCT(1+controls_fin!H13:H132)^(1/120)-1)*100} -> 0.48804269 | K13: 0.012 | L13: -0.0023054945
... A505: 41244 | B505: 0.13655739 | C505: 0.0118 | D505: 0.0166 | E505: 0.0328 | F505: 0.049 | G505: 0.0533 | H505: 0.0565 | I505: 0.15628971 | J505: {=(PRODUCT(1+controls_fin!H505:H624)^(1/120)-1)*100} -> 0.045811789 | K505: 0.0121 | L505: 0.0093193859
A506: 41275 | B506: 0.13563998 | K506: -0.00945 | L506: 0.011304428
A507: 41306 | B507: 0.13480593 | K507: -0.01895 | L507: 0.010878202
A508: 41334 | B508: 0.13405526 | K508: -0.01895 | L508: 0.0052730657
A509: 41365 | B509: 0.13322123 | K509: 0.00205 | L509: 0.0052837632
A510: 41395 | B510: 0.13238721 | K510: 0.00205 | L510: 0.0051727314
A511: 41426 | B511: 0.13163656 | K511: -0.01535 | L511: 0.0023576212
A512: 41456 | B512: 0.13080255 | K512: -0.0095 | L512: 0.0028475391
A513: 41487 | B513: 0.13021866 | K513: -0.0095 | L513: 0.0018417755
A514: 41518 | B514: 0.12963477 | K514: 0.01405 | L514: 0.007633846
A515: 41548 | B515: 0.12896751 | K515: 0.0157 | L515: 0.0096460772
A516: 41579 | B516: 0.12838363 | K516: 0.0157 | L516: 0.0098046647
A517: 41609 | B517: 0.12779975 | K517: 0.00565 | L517: -0.00016364602
... A555: 42767 | B555: 0.052437092 | K555: -0.016882353 | L555: -0.0021262389
A556: 42795 | K556: -0.016764706 | L556: 0.043719457
A557: 42826 | K557: -0.0031176471 | L557: 0.041397418
A558: 42856 | K558: -0.0031176471 | L558: 0.040676355
A559: 42887 | K559: 0.0078235294 | L559: -0.035563594
A560: 42917 | K560: 0.0080588235 | L560: -0.036838091
A561: 42948 | K561: 0.0080588235 | L561: -0.03818465
A562: 42979 | K562: -0.012470588 | L562: 0.0099733774
A563: 43009 | K563: 0.0065882353 | L563: 0.012876613
A564: 43040 | K564: 0.0065882353 | L564: 0.01559168
A565: 43070 | K565: 0.016470588 | L565: -0.0043267972
A566: 43101 | K566: -0.0051176471 | L566: -0.0026018186
A567: 43132 | K567: -0.0051176471 | L567: -0.005306112

Sheet assets
A1: date | B1: portf | C1: sp500 | D1: cs | E1: ebp | F1: gz | G1: term_pr | H1: term_pr2 | I1: 10y_inv_return_f
A2: 197101 | B2: 0.41506231 | C2: 0.050840358 | G2: 1.6830075 | H2: -1.8828 | I2: {=(PRODUCT(1+controls_fin!H2:H121)^(1/120)-1)*100-controls_fin!B2} -> 0.010254864 | K2: =AVERAGE(B2:B636) -> 0.62088522 | L2: =AVERAGE(C2:C636) -> 0.51266737 | M2: =AVERAGE(D2:D636) -> 1.30087 | N2: =AVERAGE(E2:E636) -> 0.031620971 | O2: =AVERAGE(F2:F636) -> 1.3324909 | P2: =AVERAGE(G2:G636) -> 1.457707 | Q2: =AVERAGE(H2:H636) -> -1.6149226 | R2: =AVERAGE(I2:I636) -> 0.25415653
A3: 197102 | B3: 0.35688043 | C3: 0.051228001 | G3: 2.323194 | H3: -2.6931 | I3: {=(PRODUCT(1+controls_fin!H3:H122)^(1/120)-1)*100-controls_fin!B3} -> -0.00098892695
A4: 197103 | B4: 0.3776085 | C4: 0.043079348 | G4: 2.237915 | H4: -1.8398 | I4: {=(PRODUCT(1+controls_fin!H4:H123)^(1/120)-1)*100-controls_fin!B4} -> 0.009520311
A5: 197104 | B5: 0.33979572 | C5: -0.010762564 | G5: 1.8731438 | H5: -2.0958 | I5: {=(PRODUCT(1+controls_fin!H5:H124)^(1/120)-1)*100-controls_fin!B5} -> -0.053483178
A6: 197105 | B6: 0.32076948 | C6: 0.019075893 | G6: 2.137448 | H6: -1.9802 | I6: {=(PRODUCT(1+controls_fin!H6:H125)^(1/120)-1)*100-controls_fin!B6} -> -0.0045676365
A7: 197106 | B7: 0.34246521 | C7: 0.0020542746 | G7: 1.637374 | H7: -1.4082 | I7: {=(PRODUCT(1+controls_fin!H7:H126)^(1/120)-1)*100-controls_fin!B7} -> 0.11493651
A8: 197107 | B8: 0.3287264 | C8: 0.030423539 | G8: 1.1763275 | H8: -1.4669 | I8: {=(PRODUCT(1+controls_fin!H8:H127)^(1/120)-1)*100-controls_fin!B8} -> 0.1423769
A9: 197108 | B9: 0.31255177 | C9: -0.058115591 | G9: 1.5043491 | H9: -1.7345 | I9: {=(PRODUCT(1+controls_fin!H9:H128)^(1/120)-1)*100-controls_fin!B9} -> 0.13507454
A10: 197109 | B10: 0.21446054 | C10: -0.10417867 | G10: 1.3245568 | H10: -1.4861 | I10: {=(PRODUCT(1+controls_fin!H10:H129)^(1/120)-1)*100-controls_fin!B10} -> 0.072811128
A11: 197110 | B11: 0.26801501 | C11: -0.034763866 | G11: 1.3531777 | H11: -1.596 | I11: {=(PRODUCT(1+controls_fin!H11:H130)^(1/120)-1)*100-controls_fin!B11} -> 0.050148514
A12: 197111 | B12: 0.33552699 | C12: -0.0072484537 | G12: 1.4816333 | H12: -1.6911 | I12: {=(PRODUCT(1+controls_fin!H12:H131)^(1/120)-1)*100-controls_fin!B12} -> 0.12678184
A13: 197112 | B13: 0.32748036 | C13: -0.10432422 | G13: 1.8182374 | H13: -2.2238 | I13: {=(PRODUCT(1+controls_fin!H13:H132)^(1/120)-1)*100-controls_fin!B13} -> 0.12017768
A14: 197201 | B14: 0.21959499 | C14: -0.13715693 | G14: 2.4874716 | H14: -2.7519 | I14: {=(PRODUCT(1+controls_fin!H14:H133)^(1/120)-1)*100-controls_fin!B14} -> 0.029866072
... A25: 197212 | B25: 0.29994689 | C25: -0.13554254 | G25: 1.1501368 | H25: -1.1363 | I25: {=(PRODUCT(1+controls_fin!H25:H144)^(1/120)-1)*100-controls_fin!B25} -> 0.18065795
A26: 197301 | B26: 0.34525565 | C26: -0.094690138 | D26: =-E26+F26 -> 0.624 | E26: 0.0811 | F26: 0.7051 | G26: 0.89460041 | H26: -0.7261 | I26: {=(PRODUCT(1+controls_fin!H26:H145)^(1/120)-1)*100-controls_fin!B26} -> 0.11704995
A27: 197302 | B27: 0.41252451 | C27: -0.046632124 | D27: =-E27+F27 -> 0.7055 | E27: 0.0446 | F27: 0.7501 | G27: 0.87455168 | H27: -0.6946 | I27: {=(PRODUCT(1+controls_fin!H27:H146)^(1/120)-1)*100-controls_fin!B27} -> 0.20029787
A28: 197303 | B28: 0.49909441 | C28: -0.018095932 | D28: =-E28+F28 -> 0.84 | E28: -0.063 | F28: 0.777 | G28: 0.43483301 | H28: -0.2268 | I28: {=(PRODUCT(1+controls_fin!H28:H147)^(1/120)-1)*100-controls_fin!B28} -> 0.31167553
A29: 197304 | B29: 0.56837498 | C29: 0.075258879 | D29: =-E29+F29 -> 0.9187 | E29: -0.1161 | F29: 0.8026 | G29: 0.2194902 | H29: -0.3907 | I29: {=(PRODUCT(1+controls_fin!H29:H148)^(1/120)-1)*100-controls_fin!B29} -> 0.38347107
A30: 197305 | B30: 0.63761965 | C30: 0.080728016 | D30: =-E30+F30 -> 0.8528 | E30: -0.0252 | F30: 0.8276 | G30: 0.29495519 | H30: 0.2571 | I30: {=(PRODUCT(1+controls_fin!H30:H149)^(1/120)-1)*100-controls_fin!B30} -> 0.5289531
A31: 197306 | B31: 0.71248324 | C31: 0.11402164 | D31: =-E31+F31 -> 0.8098 | E31: 0.0467 | F31: 0.8565 | G31: -0.52124285 | H31: 0.8061 | I31: {=(PRODUCT(1+controls_fin!H31:H150)^(1/120)-1)*100-controls_fin!B31} -> 0.51412207
A32: 197307 | B32: 0.7094789 | C32: 0.054704119 | D32: =-E32+F32 -> 1.2962 | E32: -0.3716 | F32: 0.9246 | G32: -1.1590832 | H32: 0.9169 | I32: {=(PRODUCT(1+controls_fin!H32:H151)^(1/120)-1)*100-controls_fin!B32} -> 0.47655725
A33: 197308 | B33: 0.63582904 | C33: 0.094079049 | D33: =-E33+F33 -> 1.1137 | E33: -0.2531 | F33: 0.8606 | G33: -1.5591625 | H33: 1.6387 | I33: {=(PRODUCT(1+controls_fin!H33:H152)^(1/120)-1)*100-controls_fin!B33} -> 0.33174983
A34: 197309 | B34: 0.67995362 | C34: 0.070606025 | D34: =-E34+F34 -> 1.2029 | E34: -0.3183 | F34: 0.8846 | G34: -1.4884256 | H34: 0.2221 | I34: {=(PRODUCT(1+controls_fin!H34:H153)^(1/120)-1)*100-controls_fin!B34} -> 0.33435642
A35: 197310 | B35: 0.58400114 | C35: 0.058432428 | D35: =-E35+F35 -> 0.7279 | E35: 0.1412 | F35: 0.8691 | G35: -0.66051523 | H35: 0.7083 | I35: {=(PRODUCT(1+controls_fin!H35:H154)^(1/120)-1)*100-controls_fin!B35} -> 0.21267426
A36: 197311 | B36: 0.61391254 | C36: 0.17159336 | D36: =-E36+F36 -> 0.9529 | E36: 0.0308 | F36: 0.9837 | G36: -1.3601024 | H36: 0.7508 | I36: {=(PRODUCT(1+controls_fin!H36:H155)^(1/120)-1)*100-controls_fin!B36} -> 0.1426579
A37: 197312 | B37: 0.74223816 | C37: 0.1511697 | D37: =-E37+F37 -> 1.0564 | E37: -0.015 | F37: 1.0414 | G37: -0.95016865 | H37: 0.7143 | I37: {=(PRODUCT(1+controls_fin!H37:H156)^(1/120)-1)*100-controls_fin!B37} -> 0.28557503
... A478: 201009 | B478: 0.90198616 | C478: 1.0337339 | D478: =-E478+F478 -> 1.8413 | E478: -0.1238 | F478: 1.7175 | G478: 2.4938308 | H478: -2.4693 | I478: {=(PRODUCT(1+controls_fin!H478:H597)^(1/120)-1)*100-controls_fin!B478} -> -0.11387634
A479: 201010 | B479: 0.82520186 | C479: 0.97929779 | G479: 2.3997954 | I479: {=(PRODUCT(1+controls_fin!H479:H598)^(1/120)-1)*100-controls_fin!B479} -> -0.14912491
A480: 201011 | B480: 0.92916442 | C480: 1.0666607 | G480: 2.6113885 | I480: {=(PRODUCT(1+controls_fin!H480:H599)^(1/120)-1)*100-controls_fin!B480} -> -0.14637799
A481: 201012 | B481: 0.97279839 | C481: 1.0463235 | G481: 3.1354117 | I481: {=(PRODUCT(1+controls_fin!H481:H600)^(1/120)-1)*100-controls_fin!B481} -> -0.10023283
A482: 201101 | B482: 0.93672435 | C482: 1.0184231 | G482: 3.2273924 | I482: {=(PRODUCT(1+controls_fin!H482:H601)^(1/120)-1)*100-controls_fin!B482} -> -0.15443345
A483: 201102 | B483: 0.9843488 | C483: 1.0132669 | G483: 3.4371026 | I483: {=(PRODUCT(1+controls_fin!H483:H602)^(1/120)-1)*100-controls_fin!B483} -> -0.19163324
A484: 201103 | B484: 0.97670769 | C484: 1.0484907 | G484: 3.2915564 | I484: {=(PRODUCT(1+controls_fin!H484:H603)^(1/120)-1)*100-controls_fin!B484} -> -0.24163254
A485: 201104 | B485: 0.99397988 | C485: 1.0682299 | G485: 3.383276 | I485: {=(PRODUCT(1+controls_fin!H485:H604)^(1/120)-1)*100-controls_fin!B485} -> -0.20004489
A486: 201105 | B486: 0.99127836 | C486: 1.0829827 | G486: 3.1195149 | I486: {=(PRODUCT(1+controls_fin!H486:H605)^(1/120)-1)*100-controls_fin!B486} -> -0.21785182
A487: 201106 | B487: 1.0131939 | C487: 1.1166474 | G487: 2.9594403 | I487: {=(PRODUCT(1+controls_fin!H487:H606)^(1/120)-1)*100-controls_fin!B487} -> -0.1884371
A488: 201107 | B488: 1.0142122 | C488: 1.1537033 | G488: 2.9517068 | I488: {=(PRODUCT(1+controls_fin!H488:H607)^(1/120)-1)*100-controls_fin!B488} -> -0.1555531
A489: 201108 | B489: 1.0621737 | C489: 1.226225 | G489: 2.2725525 | I489: {=(PRODUCT(1+controls_fin!H489:H608)^(1/120)-1)*100-controls_fin!B489} -> -0.10818372
A490: 201109 | B490: 1.1064255 | C490: 1.247826 | G490: 1.9655925 | I490: {=(PRODUCT(1+controls_fin!H490:H609)^(1/120)-1)*100-controls_fin!B490} -> -0.0019920972
...

Sheet Bonds
A1: date | B1: ebp | C1: gz
A2: 25934
A3: 25965
A4: 25993
A5: 26024
A6: 26054
A7: 26085
A8: 26115
A9: 26146
A10: 26177
A11: 26207
A12: 26238
A13: 26268
... A25: 26634
A26: 26665 | B26: 0.0811 | C26: 0.7051
A27: 26696 | B27: 0.0446 | C27: 0.7501
A28: 26724 | B28: -0.063 | C28: 0.777
A29: 26755 | B29: -0.1161 | C29: 0.8026
A30: 26785 | B30: -0.0252 | C30: 0.8276
A31: 26816 | B31: 0.0467 | C31: 0.8565
A32: 26846 | B32: -0.3716 | C32: 0.9246
A33: 26877 | B33: -0.2531 | C33: 0.8606
A34: 26908 | B34: -0.3183 | C34: 0.8846
A35: 26938 | B35: 0.1412 | C35: 0.8691
A36: 26969 | B36: 0.0308 | C36: 0.9837
A37: 26999 | B37: -0.015 | C37: 1.0414
... A478: 40422 | B478: -0.1238 | C478: 1.7175
A479: 40452
A480: 40483
A481: 40513
A482: 40544
A483: 40575
A484: 40603
A485: 40634
A486: 40664
A487: 40695
A488: 40725
A489: 40756
A490: 40787
... A567: 43132

Sheet Options
A1: date | B1: o1 | C1: o2 | D1: o3 | E1: o4 | F1: o5 | G1: o6 | H1: o7 | I1: o8 | J1: o9 | K1: o10 | L1: o11 | M1: o12 | N1: o13 | O1: o14 | P1: o15 | Q1: o16 | R1: o17 | S1: o18
A2: 25934
A3: 25965
A4: 25993
A5: 26024
A6: 26054
A7: 26085
A8: 26115
A9: 26146
A10: 26177
A11: 26207
A12: 26238
A13: 26268
... A184: 31472
A185: 31503 | B185: 0.0088 | C185: 0.0077 | D185: 0.0036 | E185: 0.004 | F185: 0.0022 | G185: -0.0021 | H185: -0.0045 | I185: -0.0061 | J185: -0.0062 | K185: 0.008 | L185: 0.0061 | M185: 0.0059 | N185: 0.0073 | O185: 0.008 | P185: 0.0065 | Q185: 0.0073 | R185: 0.0065 | S185: 0.007
A186: 31533 | B186: 0.0602 | C186: 0.0619 | D186: 0.0596 | E186: 0.0555 | F186: 0.0524 | G186: 0.054 | H186: 0.0471 | I186: 0.042 | J186: 0.0154 | K186: 0.0695 | L186: 0.0708 | M186: 0.0791 | N186: 0.0807 | O186: 0.0734 | P186: 0.07 | Q186: 0.0683 | R186: 0.0662 | S186: 0.0663
A187: 31564 | B187: 0.0175 | C187: 0.0177 | D187: 0.0169 | E187: 0.0153 | F187: 0.0135 | G187: 0.011 | H187: 0.0063 | I187: 0.005 | J187: 0.0042 | K187: 0.0252 | L187: 0.0264 | M187: 0.0265 | N187: 0.0288 | O187: 0.0249 | P187: 0.0238 | Q187: 0.0238 | R187: 0.0241 | S187: 0.0251
A188: 31594 | B188: -0.0588 | C188: -0.06 | D188: -0.0608 | E188: -0.0613 | F188: -0.0625 | G188: -0.0595 | H188: -0.0551 | I188: -0.0584 | J188: -0.0558 | K188: -0.0657 | L188: -0.0749 | M188: -0.0725 | N188: -0.0704 | O188: -0.0723 | P188: -0.0689 | Q188: -0.0683 | R188: -0.0685 | S188: -0.0678
A189: 31625 | B189: 0.0816 | C189: 0.0801 | D189: 0.0786 | E189: 0.0758 | F189: 0.0745 | G189: 0.0689 | H189: 0.0587 | I189: 0.0579 | J189: 0.0548 | K189: 0.0521 | L189: 0.0802 | M189: 0.0864 | N189: 0.0888 | O189: 0.0899 | P189: 0.0908 | Q189: 0.0942 | R189: 0.0898 | S189: 0.0882
A190: 31656 | B190: -0.0714 | C190: -0.0681 | D190: -0.0598 | E190: -0.0558 | F190: -0.0523 | G190: -0.0437 | H190: -0.0352 | I190: -0.0336 | J190: -0.0326 | K190: -0.14 | L190: -0.1473 | M190: -0.1393 | N190: -0.1165 | O190: -0.1008 | P190: -0.0907 | Q190: -0.0842 | R190: -0.0811 | S190: -0.0786
A191: 31686 | B191: 0.0452 | C191: 0.0435 | D191: 0.0389 | E191: 0.0364 | F191: 0.0328 | G191: 0.0247 | H191: 0.0195 | I191: 0.0102 | J191: 0.0007 | K191: 0.0628 | L191: 0.0637 | M191: 0.0658 | N191: 0.0638 | O191: 0.0607 | P191: 0.0575 | Q191: 0.0534 | R191: 0.052 | S191: 0.048
A192: 31717 | B192: 0.0175 | C192: 0.0153 | D192: 0.0169 | E192: 0.0159 | F192: 0.0129 | G192: 0.0128 | H192: 0.0094 | I192: 0.0034 | J192: -0.002 | K192: 0.0125 | L192: 0.0213 | M192: 0.0206 | N192: 0.0233 | O192: 0.0213 | P192: 0.0195 | Q192: 0.0197 | R192: 0.0162 | S192: 0.0153
A193: 31747 | B193: -0.027 | C193: -0.0295 | D193: -0.0318 | E193: -0.0347 | F193: -0.0376 | G193: -0.0386 | H193: -0.0408 | I193: -0.031 | J193: -0.0201 | K193: 0.0097 | L193: 0.01 | M193: -0.0051 | N193: -0.0125 | O193: -0.0166 | P193: -0.0219 | Q193: -0.0228 | R193: -0.0247 | S193: -0.0255
A194: 31778 | B194: 0.1203 | C194: 0.1236 | D194: 0.1256 | E194: 0.1253 | F194: 0.1371 | G194: 0.145 | H194: 0.145 | I194: 0.1404 | J194: 0.1497 | K194: 0.0613 | L194: 0.0748 | M194: 0.0719 | N194: 0.0826 | O194: 0.0908 | P194: 0.0962 | Q194: 0.0979 | R194: 0.0951 | S194: 0.0968
A195: 31809 | B195: 0.0255 | C195: 0.0223 | D195: 0.0205 | E195: 0.0174 | F195: 0.0144 | G195: 0.012 | H195: 0.0089 | I195: 0.006 | J195: 0.0048 | K195: 0.0385 | L195: 0.0398 | M195: 0.0396 | N195: 0.038 | O195: 0.036 | P195: 0.0319 | Q195: 0.0277 | R195: 0.028 | S195: 0.028
A196: 31837 | B196: 0.0295 | C196: 0.0306 | D196: 0.0289 | E196: 0.0277 | F196: 0.0298 | G196: 0.0278 | H196: 0.0228 | I196: 0.0211 | J196: 0.0199 | K196: 0.0278 | L196: 0.0266 | M196: 0.0312 | N196: 0.0311 | O196: 0.0318 | P196: 0.0325 | Q196: 0.0312 | R196: 0.0302 | S196: 0.0304
... A494: 40909 | B494: 0.02 | C494: 0.0174 | D494: 0.0145 | E494: 0.0107 | F494: 0.0051 | G494: -0.0013 | H494: -0.0031 | I494: -0.0053 | J494: -0.0053 | K494: 0.0749 | L494: 0.068 | M494: 0.0633 | N494: 0.0573 | O494: 0.0498 | P494: 0.0436 | Q494: 0.038 | R494: 0.0341 | S494: 0.032
A495: 40940
A496: 40969
A497: 41000
A498: 41030
A499: 41061
A500: 41091
A501: 41122
A502: 41153
A503: 41183
A504: 41214
A505: 41244
A506: 41275
... A589: 43800

Sheet CDS
A1: date | B1: CDS_01 | C1: CDS_02 | D1: CDS_03 | E1: CDS_04 | F1: CDS_05 | G1: CDS_06 | H1: CDS_07 | I1: CDS_08 | J1: CDS_09 | K1: CDS_10 | L1: CDS_11 | M1: CDS_12 | N1: CDS_13 | O1: CDS_14 | P1: CDS_15 | Q1: CDS_16 | R1: CDS_17 | S1: CDS_18 | T1: CDS_19 | U1: CDS_20
A2: 25934
A3: 25965
A4: 25993
A5: 26024
A6: 26054
A7: 26085
A8: 26115
A9: 26146
A10: 26177
A11: 26207
A12: 26238
A13: 26268
... A362: 36892
A363: 36923 | B363: 0.0039 | C363: 0.004 | D363: 0.0033 | E363: 0.0024 | F363: 0.0093 | G363: 0.003 | H363: 0.002 | I363: 0.0048 | J363: 0.0044 | K363: 0.0039 | L363: 0.0078 | M363: -0.0036 | N363: 0.0042 | O363: 0.0057 | P363: 0.0027 | Q363: -0.0153 | R363: -0.0032 | S363: 0.007 | T363: 0.0005 | U363: 0.0193
A364: 36951 | B364: 0.0012 | C364: 0.0041 | D364: 0.0061 | E364: 0.0045 | F364: 0.0073 | G364: 0.0059 | H364: 0.0079 | I364: 0.0071 | J364: 0.0087 | K364: -0.0112 | L364: 0.006 | M364: 0.0042 | N364: 0.0032 | O364: 0.0068 | P364: -0.0012 | Q364: 0.0093 | R364: 0.0083 | S364: -0.0012 | T364: 0.0072 | U364: 0.0219
A365: 36982 | B365: 0.0033 | C365: 0.0044 | D365: 0.0044 | E365: 0.006 | F365: 0.0054 | G365: 0.0037 | H365: 0.0044 | I365: 0.0044 | J365: 0.0068 | K365: 0.0021 | L365: 0.0098 | M365: 0.0106 | N365: 0.0084 | O365: 0.0098 | P365: 0.0083 | Q365: 0.0124 | R365: 0.0061 | S365: 0.0109 | T365: 0.0041 | U365: -0.0018
A366: 37012 | B366: 0.0038 | C366: 0.0043 | D366: 0.0045 | E366: 0.0039 | F366: 0.0044 | G366: 0.0039 | H366: 0.004 | I366: 0.0075 | J366: 0.0045 | K366: 0.0034 | L366: 0.0076 | M366: 0.0078 | N366: 0.0049 | O366: 0.0117 | P366: 0.0108 | Q366: 0.0061 | R366: 0.015 | S366: 0.0152 | T366: 0.0184 | U366: 0.014
A367: 37043 | B367: 0.003 | C367: 0.0027 | D367: 0.0044 | E367: 0.0037 | F367: 0.0079 | G367: 0.0042 | H367: 0.0053 | I367: 0.0035 | J367: 0.004 | K367: 0.0011 | L367: 0.0031 | M367: 0.0029 | N367: 0.0038 | O367: 0.0045 | P367: 0.0034 | Q367: 0.0044 | R367: 0.002 | S367: 0.0073 | T367: 0.0065 | U367: -0.0007
A368: 37073 | B368: 0.003 | C368: 0.0037 | D368: 0.0029 | E368: 0.0038 | F368: 0.0023 | G368: 0.0031 | H368: 0.0027 | I368: 0.004 | J368: 0.0017 | K368: 0.003 | L368: 0.003 | M368: 0.0015 | N368: 0.0028 | O368: 0.0037 | P368: 0.0058 | Q368: 0.0057 | R368: 0.007 | S368: 0.0045 | T368: 0.008 | U368: 0.0168
A369: 37104 | B369: 0.003 | C369: 0.0031 | D369: 0.0033 | E369: 0.0021 | F369: 0.0041 | G369: 0.0024 | H369: 0.0043 | I369: 0.0039 | J369: 0.0048 | K369: 0.0012 | L369: 0.0048 | M369: 0.0008 | N369: 0.0049 | O369: 0.009 | P369: 0.0051 | Q369: 0.0074 | R369: 0.0091 | S369: 0.0055 | T369: 0.011 | U369: 0.0014
A370: 37135 | B370: -0.0058 | C370: -0.0007 | D370: -0.0008 | E370: -0.0074 | F370: -0.0045 | G370: -0.0019 | H370: -0.0029 | I370: -0.0038 | J370: -0.0111 | K370: -0.0056 | L370: -0.0048 | M370: -0.0047 | N370: -0.0054 | O370: -0.0091 | P370: -0.0086 | Q370: -0.0044 | R370: -0.0134 | S370: -0.0094 | T370: -0.0103 | U370: -0.027
A371: 37165 | B371: 0.0023 | C371: 0.0026 | D371: 0.0017 | E371: 0.004 | F371: 0.0035 | G371: 0.002 | H371: 0.0013 | I371: 0.0054 | J371: -0.0033 | K371: -0.0007 | L371: 0.0046 | M371: -0.0048 | N371: 0.0017 | O371: 0.0005 | P371: -0.0005 | Q371: -0.0026 | R371: -0.0065 | S371: 0.0015 | T371: 0.0031 | U371: -0.0032
A372: 37196 | B372: 0.0023 | C372: 0.0022 | D372: 0.0044 | E372: 0.0045 | F372: 0.0062 | G372: 0.0046 | H372: 0.0007 | I372: 0.007 | J372: 0.0071 | K372: 0.0053 | L372: 0.0061 | M372: 0.0077 | N372: 0.003 | O372: 0.0075 | P372: 0.0124 | Q372: 0.009 | R372: 0.0155 | S372: 0.0098 | T372: 0.0163 | U372: 0.0075
A373: 37226 | B373: 0.0011 | C373: 0.0015 | D373: 0.0016 | E373: 0.0027 | F373: 0.0014 | G373: 0.0029 | H373: 0.0041 | I373: 0.0033 | J373: 0.0024 | K373: 0.0011 | L373: 0.0034 | M373: 0.0014 | N373: 0.0025 | O373: 0.0025 | P373: 0.0061 | Q373: -0.0245 | R373: -0.0019 | S373: -0.0012 | T373: -0.0464 | U373: 0.0098
A374: 37257 | B374: 0.0018 | C374: 0.0011 | D374: 0.0017 | E374: -0.0035 | F374: 0.0021 | G374: -0.0023 | H374: -0.0007 | I374: 0.0018 | J374: 0.0008 | K374: 0.0042 | L374: 0.0044 | M374: 0.0028 | N374: 0.0022 | O374: 0.0031 | P374: 0.004 | Q374: 0.0033 | R374: 0.003 | S374: 0.0098 | T374: 0.0075 | U374: 0.0063
... A505: 41244 | B505: 0.0008 | C505: 0.0009 | D505: 0.0008 | E505: 0.0011 | F505: 0.0018 | G505: 0.0016 | H505: 0.0028 | I505: 0.0026 | J505: 0.0014 | K505: 0.003 | L505: 0.0027 | M505: 0.0025 | N505: 0.0028 | O505: 0.0027 | P505: 0.0036 | Q505: 0.0029 | R505: 0.0019 | S505: 0.0068 | T505: 0.0068 | U505: 0.0101
A506: 41275
A507: 41306
A508: 41334
A509: 41365
A510: 41395
A511: 41426
A512: 41456
A513: 41487
A514: 41518
A515: 41548
A516: 41579
A517: 41609
... A589: 43800

Sheet FX
A1: date | B1: FX_01 | C1: FX_02 | D1: FX_03 | E1: FX_04 | F1: FX_05 | G1: FX_06 | H1: FX_07 | I1: FX_08 | J1: FX_09 | K1: FX_10 | L1: FX_11 | M1: FX_12 | N1: Avg | O1: 10y_ret
A2: 25934
A3: 25965
A4: 25993
A5: 26024
A6: 26054
A7: 26085
A8: 26115
A9: 26146
A10: 26177
A11: 26207
A12: 26238
A13: 26268
... A63: 27791
A64: 27820 | B64: -0.0172 | C64: -0.0332 | D64: 0.0062 | E64: -0.0334 | F64: -0.0135 | G64: 0.0039 | H64: 0.0001 | I64: 0.006 | J64: 0.0094 | K64: -0.0144 | L64: -0.0134 | M64: -0.0361 | N64: =AVERAGE(B64:M64) -> -0.0113
A65: 27851 | B65: -0.0432 | C65: -0.0104 | D65: -0.0012 | E65: 0.0021 | F65: 0.0052 | G65: 0.0007 | H65: 0.0022 | I65: 0.0009 | J65: 0.0022 | K65: 0.0095 | L65: -0.0211 | M65: -0.008 | N65: =AVERAGE(B65:M65) -> -0.0050916667
A66: 27881 | B66: -0.0024 | C66: -0.0328 | D66: -0.0137 | E66: -0.0071 | F66: -0.0156 | G66: -0.02 | H66: -0.0021 | I66: -0.0118 | J66: -0.0047 | K66: -0.0026 | L66: -0.0297 | M66: 0.0057 | N66: =AVERAGE(B66:M66) -> -0.0114
A67: 27912 | B67: 0.0172 | C67: -0.0051 | D67: -0.0017 | E67: -0.0038 | F67: 0.0028 | G67: 0.0022 | H67: -0.0038 | I67: 0.0007 | J67: 0.0084 | K67: 0.0031 | L67: 0.0043 | M67: 0.0113 | N67: =AVERAGE(B67:M67) -> 0.0029666667
A68: 27942 | B68: 0.0029 | C68: -0.0156 | D68: 0.0027 | E68: 0.0006 | F68: -0.0032 | G68: 0.0081 | H68: -0.0048 | I68: 0.0134 | J68: 0.0059 | K68: -0.0094 | L68: 0.0036 | M68: 0.0161 | N68: =AVERAGE(B68:M68) -> 0.0016916667
A69: 27973 | B69: -0.0074 | C69: 0.0007 | D69: 0.0087 | E69: 0.0091 | F69: -0.0021 | G69: 0.0086 | H69: 0 | I69: 0.0093 | J69: 0.0116 | K69: 0.0066 | L69: 0.0087 | M69: 0.0101 | N69: =AVERAGE(B69:M69) -> 0.005325
A70: 28004 | B70: -0.0186 | C70: -0.0014 | D70: -0.0003 | E70: 0.0338 | F70: 0.0267 | G70: 0.0371 | H70: 0.0144 | I70: 0.0149 | J70: 0.0046 | K70: 0.0073 | L70: -0.0038 | M70: 0.0263 | N70: =AVERAGE(B70:M70) -> 0.01175
A71: 28034 | B71: -0.0408 | C71: -0.0056 | D71: -0.0054 | E71: 0.0089 | F71: 0.0148 | G71: 0.0077 | H71: 0.0037 | I71: 0.0013 | J71: -0.0032 | K71: 0.0091 | L71: -0.0125 | M71: 0.0216 | N71: =AVERAGE(B71:M71) -> -3.3333333e-05
A72: 28065 | B72: 0.0479 | C72: -0.0149 | D72: -0.035 | E72: 0.0006 | F72: 0.0003 | G72: -0.0053 | H72: 0.0007 | I72: -0.0044 | J72: -0.0802 | K72: 0.0058 | L72: 0.0106 | M72: 0.0314 | N72: =AVERAGE(B72:M72) -> -0.0035416667
A73: 28095 | B73: 0.0025 | C73: 0.0099 | D73: 0.012 | E73: 0.0141 | F73: 0.0053 | G73: 0.0336 | H73: 0.0029 | I73: 0.0193 | J73: 0.0404 | K73: 0.0174 | L73: 0.0237 | M73: 0.0257 | N73: =AVERAGE(B73:M73) -> 0.017233333
A74: 28126 | B74: -0.0192 | C74: -0.022 | D74: -0.0247 | E74: -0.0385 | F74: -0.0292 | G74: 0.0126 | H74: -0.0166 | I74: -0.0007 | J74: -0.0198 | K74: -0.008 | L74: -0.0169 | M74: 0.0086 | N74: =AVERAGE(B74:M74) -> -0.014533333
A75: 28157 | B75: 0.0016 | C75: 0.0107 | D75: 0.0093 | E75: -0.0143 | F75: 0.0017 | G75: 0.0079 | H75: -0.0056 | I75: 0.0125 | J75: 0.0013 | K75: 0.0104 | L75: -0.0011 | M75: 0.0131 | N75: =AVERAGE(B75:M75) -> 0.0039583333
... A470: 40179 | B470: -0.019 | C470: -0.0175 | D470: -0.0053 | E470: 0.0056 | F470: 0.0032 | G470: -0.0127 | H470: -0.0038 | I470: -0.007 | J470: -0.0063 | K470: -0.0093 | L470: -0.0009 | M470: -0.0079 | N470: =AVERAGE(B470:M470) -> -0.0067416667
A471: 40210 | N471: =AVERAGE(B471:M471) -> #DIV/0!
A472: 40238 | N472: =AVERAGE(B472:M472) -> #DIV/0!
A473: 40269 | N473: =AVERAGE(B473:M473) -> #DIV/0!
A474: 40299 | N474: =AVERAGE(B474:M474) -> #DIV/0!
A475: 40330 | N475: =AVERAGE(B475:M475) -> #DIV/0!
A476: 40360 | N476: =AVERAGE(B476:M476) -> #DIV/0!
A477: 40391 | N477: =AVERAGE(B477:M477) -> #DIV/0!
A478: 40422 | N478: =AVERAGE(B478:M478) -> #DIV/0!
A479: 40452 | N479: =AVERAGE(B479:M479) -> #DIV/0!
A480: 40483 | N480: =AVERAGE(B480:M480) -> #DIV/0!
A481: 40513 | N481: =AVERAGE(B481:M481) -> #DIV/0!
A482: 40544 | N482: =AVERAGE(B482:M482) -> #DIV/0!
... A589: 43800 | N589: =AVERAGE(B589:M589) -> #DIV/0!

Sheet shocks
A1: date | B1: um shock | C1: ip shock | D1: uf shock | E1: vol_shock
A2: 25934 | B2: -1.7838832 | C2: 3.8945187 | D2: 0.0087081105 | E2: -0.10282695
A3: 25965 | B3: -0.82839333 | C3: -0.28078449 | D3: -0.37020214 | E3: -0.35828553
A4: 25993 | B4: -1.588291 | C4: -0.094017903 | D4: 0.40942254 | E4: -0.53142309
A5: 26024 | B5: 0.37903655 | C5: -0.55112581 | D5: -0.025343468 | E5: 0.3219754
A6: 26054 | B6: 0.44325543 | C6: -0.073314177 | D6: 0.0043514928 | E6: 0.55648963
A7: 26085 | B7: 0.24694372 | C7: -0.70156167 | D7: -0.18251657 | E7: -0.7670773
A8: 26115 | B8: -0.88465851 | C8: -0.51805209 | D8: 1.1994533 | E8: 2.2440297
A9: 26146 | B9: -1.9326083 | C9: -0.049276584 | D9: 0.28677838 | E9: -1.9967563
A10: 26177 | B10: 1.7376812 | C10: 0.86625476 | D10: -1.0775891 | E10: 0.060527445
A11: 26207 | B11: 0.37731253 | C11: 0.95791869 | D11: 0.68120695 | E11: 1.5950223
A12: 26238 | B12: 0.3984019 | C12: -0.61012323 | D12: -0.16253292 | E12: -1.0728148
A13: 26268 | B13: 1.6231168 | C13: -0.6145481 | D13: -0.039198153 | E13: -0.59413962
... A533: 42095 | B533: -0.3910144 | C533: 0.5303932 | D533: 0.12045721 | E533: -0.1883844

Sheet FamaFrench
A1: date
A2: 25934 | B2: 0.1527 | C2: 0.1378 | D2: 0.1631 | E2: 0.1412 | F2: 0.1593 | G2: 0.0754 | H2: 0.1319 | I2: 0.1262 | J2: 0.109 | K2: 0.1308 | L2: 0.0825 | M2: 0.0885 | N2: 0.1118 | O2: 0.0781 | P2: 0.0868 | Q2: 0.0524 | R2: 0.07 | S2: 0.0529 | T2: 0.0865 | U2: 0.14 | V2: 0.041 | W2: 0.0431 | X2: 0.033 | Y2: 0.03 | Z2: 0.0403
A3: 25965 | B3: 0.08 | C3: 0.0747 | D3: 0.061 | E3: 0.0332 | F3: 0.0406 | G3: 0.0403 | H3: 0.0358 | I3: 0.0279 | J3: 0.0134 | K3: 0.0089 | L3: 0.0407 | M3: 0.0194 | N3: 0.0229 | O3: 0.0132 | P3: 0.0184 | Q3: 0.0343 | R3: 0.0309 | S3: 0.003 | T3: 0.0324 | U3: 0.0121 | V3: 0.0234 | W3: 0.0035 | X3: 0.0063 | Y3: 0.005 | Z3: 0.0125
A4: 25993 | B4: 0.0834 | C4: 0.0463 | D4: 0.0786 | E4: 0.0649 | F4: 0.0513 | G4: 0.0795 | H4: 0.0667 | I4: 0.0589 | J4: 0.0437 | K4: 0.0139 | L4: 0.1041 | M4: 0.093 | N4: 0.0345 | O4: 0.0332 | P4: 0.0468 | Q4: 0.0693 | R4: 0.0602 | S4: 0.0463 | T4: 0.0235 | U4: 0.0351 | V4: 0.0586 | W4: 0.029 | X4: 0.0483 | Y4: 0.0148 | Z4: 0.025
A5: 26024 | B5: 0.0078 | C5: 0.0326 | D5: 0.0224 | E5: 0.0274 | F5: 0.0186 | G5: 0.0221 | H5: 0.026 | I5: 0.0209 | J5: 0.036 | K5: 0.0703 | L5: 0.0619 | M5: 0.0473 | N5: 0.048 | O5: 0.022 | P5: 0.0805 | Q5: 0.0289 | R5: 0.0329 | S5: 0.0196 | T5: 0.0414 | U5: 0.0917 | V5: 0.0363 | W5: 0.0566 | X5: 0.0071 | Y5: 0.0256 | Z5: 0.0615
A6: 26054 | B6: -0.066 | C6: -0.051 | D6: -0.0734 | E6: -0.0496 | F6: -0.0657 | G6: -0.035 | H6: -0.0554 | I6: -0.0473 | J6: -0.0463 | K6: -0.0447 | L6: -0.0457 | M6: -0.0256 | N6: -0.0492 | O6: -0.0374 | P6: -0.031 | Q6: -0.0214 | R6: -0.0332 | S6: -0.0419 | T6: -0.0315 | U6: -0.0437 | V6: -0.0243 | W6: -0.0435 | X6: -0.041 | Y6: -0.0505 | Z6: -0.0365
A7: 26085 | B7: -0.0042 | C7: -0.0359 | D7: -0.0229 | E7: -0.0124 | F7: -0.0216 | G7: 0.0397 | H7: -0.0237 | I7: 0.0043 | J7: -0.0202 | K7: -0.0336 | L7: -0.0169 | M7: 0.0174 | N7: -0.015 | O7: -0.0185 | P7: -0.0249 | Q7: 0.0125 | R7: 0.0127 | S7: 0.0225 | T7: 0.0058 | U7: -0.0394 | V7: 0.0124 | W7: -0.0085 | X7: -0.0036 | Y7: 0.0088 | Z7: -0.0028
A8: 26115 | B8: -0.0862 | C8: -0.0806 | D8: -0.0725 | E8: -0.0604 | F8: -0.0591 | G8: -0.0641 | H8: -0.0472 | I8: -0.0346 | J8: -0.0645 | K8: -0.0574 | L8: -0.0802 | M8: -0.0453 | N8: -0.0328 | O8: -0.0581 | P8: -0.0469 | Q8: -0.0361 | R8: -0.0421 | S8: -0.0381 | T8: -0.0423 | U8: -0.0761 | V8: -0.0398 | W8: -0.039 | X8: -0.0347 | Y8: -0.033 | Z8: -0.0549
A9: 26146 | B9: 0.0329 | C9: 0.0438 | D9: 0.0281 | E9: 0.0456 | F9: 0.0565 | G9: 0.0408 | H9: 0.0707 | I9: 0.033 | J9: 0.0604 | K9: 0.0779 | L9: 0.0655 | M9: 0.0493 | N9: 0.0192 | O9: 0.075 | P9: 0.09 | Q9: 0.0689 | R9: 0.0433 | S9: 0.0215 | T9: 0.0348 | U9: 0.1056 | V9: 0.054 | W9: 0.0466 | X9: -0.0143 | Y9: 0.0197 | Z9: 0.1359
A10: 26177 | B10: 0.0121 | C10: 0.0209 | D10: -0.0012 | E10: -0.0063 | F10: -0.0238 | G10: 0.021 | H10: -0.0118 | I10: -0.021 | J10: -0.0166 | K10: -0.0283 | L10: 0.0113 | M10: 0.0031 | N10: -0.0068 | O10: -0.0133 | P10: -0.0298 | Q10: 0.0189 | R10: -0.0103 | S10: -0.0045 | T10: -0.0023 | U10: -0.0444 | V10: 0.0034 | W10: -0.0111 | X10: -0.0128 | Y10: -0.0145 | Z10: -0.0215
A11: 26207 | B11: -0.0786 | C11: -0.0678 | D11: -0.0709 | E11: -0.0445 | F11: -0.0727 | G11: -0.0596 | H11: -0.0532 | I11: -0.0306 | J11: -0.0435 | K11: -0.0666 | L11: -0.0799 | M11: -0.0632 | N11: -0.0318 | O11: -0.0469 | P11: -0.0525 | Q11: -0.0311 | R11: -0.034 | S11: -0.0227 | T11: -0.0554 | U11: -0.0587 | V11: -0.0349 | W11: -0.0523 | X11: -0.0363 | Y11: -0.0271 | Z11: -0.0402
A12: 26238 | B12: -0.0327 | C12: -0.0579 | D12: -0.0376 | E12: -0.0439 | F12: -0.056 | G12: -0.0189 | H12: -0.022 | I12: -0.0145 | J12: -0.0263 | K12: -0.0274 | L12: -0.0192 | M12: -0.0115 | N12: -0.0058 | O12: -0.0419 | P12: -0.0472 | Q12: 0.0029 | R12: -0.0177 | S12: -0.0272 | T12: 0.006 | U12: -0.0439 | V12: 0.011 | W12: 0.0105 | X12: -0.0013 | Y12: -0.0055 | Z12: 0.0028
A13: 26268 | B13: 0.1449 | C13: 0.1424 | D13: 0.1074 | E13: 0.1178 | F13: 0.1339 | G13: 0.1307 | H13: 0.1408 | I13: 0.1278 | J13: 0.1102 | K13: 0.1265 | L13: 0.1412 | M13: 0.095 | N13: 0.1017 | O13: 0.1193 | P13: 0.1238 | Q13: 0.1227 | R13: 0.0986 | S13: 0.0889 | T13: 0.0822 | U13: 0.1246 | V13: 0.0845 | W13: 0.0931 | X13: 0.0888 | Y13: 0.0693 | Z13: 0.0894
... A505: 41244 | B505: 0.012 | C505: 0.0309 | D505: 0.0422 | E505: 0.0427 | F505: 0.0458 | G505: 0.0329 | H505: 0.035 | I505: 0.04 | J505: 0.0341 | K505: 0.0461 | L505: 0.0242 | M505: 0.0434 | N505: 0.0123 | O505: 0.0391 | P505: 0.0426 | Q505: 0.0218 | R505: 0.0191 | S505: 0.0291 | T505: 0.0352 | U505: 0.0388 | V505: -0.0077 | W505: 0.0007 | X505: 0.013 | Y505: 0.0189 | Z505: 0.0643
