Workbook

Sheet Levels_real
A1: date | B1: credit | C1: trsry security | D1: =Levels!D1 -> net worth | E1: =Levels!V1 -> pvt safe | F1: GFCF | G1: cons | H1: hours | I1: =Levels!W1 -> LI_leverage | J1: =Levels!AD1 -> ma_equity_invcap_mean | K1: =Levels!AC1 -> ffr | L1: Real 10y r | M1: logQ | N1: ret | O1: ebp | P1: ExcR | Q1: infl | R1: JLN | S1: JLN_F | T1: GDP | U1: unc_m shock | V1: ip shock | W1: unc_f shock | X1: =Levels!AB1 -> vola_shock
A2: =Levels!A2 -> 1971Q1 | B2: =Levels!B2/Levels!$R2 -> 1146.9861 | C2: =Levels!C2/Levels!$R2 -> 216295.23 | D2: =Levels!D2/Levels!R2 -> 183563.37 | E2: =Levels!V2/Levels!R2 -> 1028622.9 | G2: =Levels!F2 -> 3107.2491 | H2: =Levels!G2 -> -2.1 | J2: =Levels!AD2 -> -0.011871578 | K2: =Levels!AC2 -> 3.8566667 | L2: =Levels!I2 -> -0.49996228 | M2: =Levels!J2 -> 1.9854295 | N2: =Levels!K2 -> -0.1529786 | P2: =Levels!M2 -> 0.14492942 | Q2: =Levels!N2 -> 0.16729428 | R2: =Levels!O2 -> 0.79096956 | S2: =Levels!P2 -> 0.97779341 | T2: =Levels!Q2 -> 5072.996 | U2: =Levels!S2 -> -4.2005676 | V2: =Levels!T2 -> 3.5197163 | W2: =Levels!U2 -> 0.04792851 | X2: =Levels!AB2 -> -0.99253557
A3: =Levels!A3 -> 1971Q2 | B3: =Levels!B3/Levels!$R3 -> 1181.7509 | C3: =Levels!C3/Levels!$R3 -> 215131.26 | D3: =Levels!D3/Levels!R3 -> 187801.6 | E3: =Levels!V3/Levels!R3 -> 1063192.1 | G3: =Levels!F3 -> 3132.4206 | H3: =Levels!G3 -> -0.5 | J3: =Levels!AD3 -> -0.011629499 | K3: =Levels!AC3 -> 4.5666667 | L3: =Levels!I3 -> -0.33476317 | M3: =Levels!J3 -> 2.0035371 | N3: =Levels!K3 -> -0.2530461 | P3: =Levels!M3 -> 0.010346773 | Q3: =Levels!N3 -> 0.49772333 | R3: =Levels!O3 -> 0.75466324 | S3: =Levels!P3 -> 0.93890474 | T3: =Levels!Q3 -> 5100.447 | U3: =Levels!S3 -> 1.0692357 | V3: =Levels!T3 -> -1.3260017 | W3: =Levels!U3 -> -0.20350855 | X3: =Levels!AB3 -> 0.11138773
A4: =Levels!A4 -> 1971Q3 | B4: =Levels!B4/Levels!$R4 -> 1208.3143 | C4: =Levels!C4/Levels!$R4 -> 212956.09 | D4: =Levels!D4/Levels!R4 -> 192946.56 | E4: =Levels!V4/Levels!R4 -> 1091281 | G4: =Levels!F4 -> 3148.7997 | H4: =Levels!G4 -> 0 | J4: =Levels!AD4 -> -0.0036406727 | K4: =Levels!AC4 -> 5.4766667 | L4: =Levels!I4 -> -0.17078911 | M4: =Levels!J4 -> 1.9910998 | N4: =Levels!K4 -> -0.37432899 | P4: =Levels!M4 -> -0.13164364 | Q4: =Levels!N4 -> 0.16400189 | R4: =Levels!O4 -> 0.76033864 | S4: =Levels!P4 -> 0.94071234 | T4: =Levels!Q4 -> 5142.422 | U4: =Levels!S4 -> -1.0795856 | V4: =Levels!T4 -> 0.29892608 | W4: =Levels!U4 -> 0.40864258 | X4: =Levels!AB4 -> 0.30780088
A5: =Levels!A5 -> 1971Q4 | B5: =Levels!B5/Levels!$R5 -> 1239.8683 | C5: =Levels!C5/Levels!$R5 -> 222961.2 | D5: =Levels!D5/Levels!R5 -> 200141.43 | E5: =Levels!V5/Levels!R5 -> 1136453.6 | G5: =Levels!F5 -> 3182.1609 | H5: =Levels!G5 -> 1.9 | J5: =Levels!AD5 -> 0.028613195 | K5: =Levels!AC5 -> 4.75 | L5: =Levels!I5 -> -0.82348626 | M5: =Levels!J5 -> 1.9819173 | N5: =Levels!K5 -> -0.35322285 | P5: =Levels!M5 -> -0.14608553 | Q5: =Levels!N5 -> 0.24469853 | R5: =Levels!O5 -> 0.75628188 | S5: =Levels!P5 -> 0.94820076 | T5: =Levels!Q5 -> 5154.547 | U5: =Levels!S5 -> 2.3988313 | V5: =Levels!T5 -> -0.26675265 | W5: =Levels!U5 -> 0.47947588 | X5: =Levels!AB5 -> -0.071932089
A6: =Levels!A6 -> 1972Q1 | B6: =Levels!B6/Levels!$R6 -> 1263.1117 | C6: =Levels!C6/Levels!$R6 -> 222285.3 | D6: =Levels!D6/Levels!R6 -> 208062.21 | E6: =Levels!V6/Levels!R6 -> 1165254.2 | F6: =Levels!E6 -> 908.537 | G6: =Levels!F6 -> 3226.2103 | H6: =Levels!G6 -> 2.6 | J6: =Levels!AD6 -> 0.0023036362 | K6: =Levels!AC6 -> 3.5466667 | L6: =Levels!I6 -> -0.74157349 | M6: =Levels!J6 -> 2.0227773 | N6: =Levels!K6 -> -0.73939461 | P6: =Levels!M6 -> -0.57402808 | Q6: =Levels!N6 -> 0.24291625 | R6: =Levels!O6 -> 0.74905767 | S6: =Levels!P6 -> 0.89377227 | T6: =Levels!Q6 -> 5249.337 | U6: =Levels!S6 -> 0.55881061 | V6: =Levels!T6 -> 2.908896 | W6: =Levels!U6 -> -3.6705217 | X6: =Levels!AB6 -> -0.50540096
A7: =Levels!A7 -> 1972Q2 | B7: =Levels!B7/Levels!$R7 -> 1308.5801 | C7: =Levels!C7/Levels!$R7 -> 221312.68 | D7: =Levels!D7/Levels!R7 -> 210594.23 | E7: =Levels!V7/Levels!R7 -> 1204986.1 | F7: =Levels!E7 -> 919.345 | G7: =Levels!F7 -> 3276.5467 | H7: =Levels!G7 -> 3 | J7: =Levels!AD7 -> -0.023576011 | K7: =Levels!AC7 -> 4.3 | L7: =Levels!I7 -> -0.69670607 | M7: =Levels!J7 -> 2.0331158 | N7: =Levels!K7 -> -0.84409953 | P7: =Levels!M7 -> -0.71528011 | Q7: =Levels!N7 -> 0.24096479 | R7: =Levels!O7 -> 0.72086478 | S7: =Levels!P7 -> 0.86197468 | T7: =Levels!Q7 -> 5368.485 | U7: =Levels!S7 -> -0.6140998 | V7: =Levels!T7 -> -1.344592 | W7: =Levels!U7 -> 0.18384939 | X7: =Levels!AB7 -> 0.013378271
A8: =Levels!A8 -> 1972Q3 | B8: =Levels!B8/Levels!$R8 -> 1340.3832 | C8: =Levels!C8/Levels!$R8 -> 218852.1 | D8: =Levels!D8/Levels!R8 -> 218072.48 | E8: =Levels!V8/Levels!R8 -> 1233553.4 | F8: =Levels!E8 -> 917.59 | G8: =Levels!F8 -> 3329.6378 | H8: =Levels!G8 -> 3.5 | J8: =Levels!AD8 -> -0.019333254 | K8: =Levels!AC8 -> 4.7433333 | L8: =Levels!I8 -> -0.61610667 | M8: =Levels!J8 -> 2.0413836 | N8: =Levels!K8 -> -0.81547068 | P8: =Levels!M8 -> -0.70840304 | Q8: =Levels!N8 -> 0.31879168 | R8: =Levels!O8 -> 0.7574092 | S8: =Levels!P8 -> 0.88100813 | T8: =Levels!Q8 -> 5419.184 | U8: =Levels!S8 -> 1.5322161 | V8: =Levels!T8 -> -0.045506628 | W8: =Levels!U8 -> -0.029725928 | X8: =Levels!AB8 -> -0.0076880759
A9: =Levels!A9 -> 1972Q4 | B9: =Levels!B9/Levels!$R9 -> 1387.2766 | C9: =Levels!C9/Levels!$R9 -> 228739.22 | D9: =Levels!D9/Levels!R9 -> 228956.69 | E9: =Levels!V9/Levels!R9 -> 1295029 | F9: =Levels!E9 -> 956.775 | G9: =Levels!F9 -> 3410.2999 | H9: =Levels!G9 -> 3.5 | J9: =Levels!AD9 -> -0.01032468 | K9: =Levels!AC9 -> 5.1466667 | L9: =Levels!I9 -> -0.59691595 | M9: =Levels!J9 -> 2.0655566 | N9: =Levels!K9 -> -0.47116967 | P9: =Levels!M9 -> -0.40034764 | Q9: =Levels!N9 -> 0.31577169 | R9: =Levels!O9 -> 0.78272069 | S9: =Levels!P9 -> 0.9260483 | T9: =Levels!Q9 -> 5509.926 | U9: =Levels!S9 -> 4.0139768 | V9: =Levels!T9 -> 0.10468662 | W9: =Levels!U9 -> -0.21161094 | X9: =Levels!AB9 -> -0.7985377
A10: =Levels!A10 -> 1973Q1 | B10: =Levels!B10/Levels!$R10 -> 1426.4019 | C10: =Levels!C10/Levels!$R10 -> 224997.99 | D10: =Levels!D10/Levels!R10 -> 237261.29 | E10: =Levels!V10/Levels!R10 -> 1327657.4 | F10: =Levels!E10 -> 996.161 | G10: =Levels!F10 -> 3488.2415 | H10: =Levels!G10 -> 3.9 | J10: =Levels!AD10 -> 0.033388641 | K10: =Levels!AC10 -> 6.5366667 | L10: =Levels!I10 -> -0.41931273 | M10: =Levels!J10 -> 2.0605947 | N10: =Levels!K10 -> -0.17466382 | O10: 0.0209 | P10: =Levels!M10 -> -0.15933788 | Q10: =Levels!N10 -> 0.62397347 | R10: =Levels!O10 -> 0.82162467 | S10: =Levels!P10 -> 1.0025217 | T10: =Levels!Q10 -> 5646.286 | U10: =Levels!S10 -> 1.6886504 | V10: =Levels!T10 -> 0.6921871 | W10: =Levels!U10 -> 0.30885107 | X10: =Levels!AB10 -> 1.491565
A11: =Levels!A11 -> 1973Q2 | B11: =Levels!B11/Levels!$R11 -> 1478.7258 | C11: =Levels!C11/Levels!$R11 -> 223233.27 | D11: =Levels!D11/Levels!R11 -> 242322.77 | E11: =Levels!V11/Levels!R11 -> 1375374.5 | F11: =Levels!E11 -> 996.956 | G11: =Levels!F11 -> 3529.2354 | H11: =Levels!G11 -> 4.2 | J11: =Levels!AD11 -> 0.021323124 | K11: =Levels!AC11 -> 7.8166667 | L11: =Levels!I11 -> -0.26696048 | M11: =Levels!J11 -> 2.0294043 | N11: =Levels!K11 -> 0.29158209 | O11: -0.0316 | P11: =Levels!M11 -> 0.27028401 | Q11: =Levels!N11 -> 0.68809511 | R11: =Levels!O11 -> 0.85461162 | S11: =Levels!P11 -> 1.0680409 | T11: =Levels!Q11 -> 5707.755 | U11: =Levels!S11 -> 1.8592563 | V11: =Levels!T11 -> -1.2523708 | W11: =Levels!U11 -> 1.3124441 | X11: =Levels!AB11 -> 0.95301059
A12: =Levels!A12 -> 1973Q3 | B12: =Levels!B12/Levels!$R12 -> 1522.4616 | C12: =Levels!C12/Levels!$R12 -> 219707.6 | D12: =Levels!D12/Levels!R12 -> 260305.56 | E12: =Levels!V12/Levels!R12 -> 1393249.7 | F12: =Levels!E12 -> 988.511 | G12: =Levels!F12 -> 3575.104 | H12: =Levels!G12 -> 4.3 | J12: =Levels!AD12 -> 0.025083577 | K12: =Levels!AC12 -> 10.56 | L12: =Levels!I12 -> 0.12014968 | M12: =Levels!J12 -> 2.0268212 | N12: =Levels!K12 -> 0.27369989 | O12: -0.3143 | P12: =Levels!M12 -> 0.21962252 | Q12: =Levels!N12 -> 0.75128097 | R12: =Levels!O12 -> 0.94089069 | S12: =Levels!P12 -> 1.1392991 | T12: =Levels!Q12 -> 5677.738 | U12: =Levels!S12 -> 3.5375632 | V12: =Levels!T12 -> 0.26813095 | W12: =Levels!U12 -> 1.2148524 | X12: =Levels!AB12 -> -0.52173465
A13: =Levels!A13 -> 1973Q4 | B13: =Levels!B13/Levels!$R13 -> 1560.4965 | C13: =Levels!C13/Levels!$R13 -> 228414.45 | D13: =Levels!D13/Levels!R13 -> 259035.18 | E13: =Levels!V13/Levels!R13 -> 1455277.6 | F13: =Levels!E13 -> 982.628 | G13: =Levels!F13 -> 3600.9919 | H13: =Levels!G13 -> 3.8 | J13: =Levels!AD13 -> -0.023258884 | K13: =Levels!AC13 -> 9.9966667 | L13: =Levels!I13 -> -0.34416786 | M13: =Levels!J13 -> 1.9926584 | N13: =Levels!K13 -> 0.48129295 | O13: 0.0523 | P13: =Levels!M13 -> 0.38189216 | Q13: =Levels!N13 -> 0.73214842 | R13: =Levels!O13 -> 0.94060057 | S13: =Levels!P13 -> 1.1964164 | T13: =Levels!Q13 -> 5731.632 | U13: =Levels!S13 -> 1.7073099 | V13: =Levels!T13 -> 0.11346682 | W13: =Levels!U13 -> -1.9173436 | X13: =Levels!AB13 -> 3.2358203
A14: =Levels!A14 -> 1974Q1 | B14: =Levels!B14/Levels!$R14 -> 1586.6712 | C14: =Levels!C14/Levels!$R14 -> 224963.49 | D14: =Levels!D14/Levels!R14 -> 267499.58 | E14: =Levels!V14/Levels!R14 -> 1476121.9 | F14: =Levels!E14 -> 973.878 | G14: =Levels!F14 -> 3630.8792 | H14: =Levels!G14 -> 1.8 | J14: =Levels!AD14 -> -0.0080833953 | K14: =Levels!AC14 -> 9.3233333 | L14: =Levels!I14 -> -0.038360527 | M14: =Levels!J14 -> 1.9806951 | N14: =Levels!K14 -> 0.57698054 | O14: -0.0035 | P14: =Levels!M14 -> 0.43001946 | Q14: =Levels!N14 -> 1.1415137 | R14: =Levels!O14 -> 0.92797056 | S14: =Levels!P14 -> 1.1147487 | T14: =Levels!Q14 -> 5682.353 | U14: =Levels!S14 -> -0.36504646 | V14: =Levels!T14 -> -0.73052763 | W14: =Levels!U14 -> -0.10677294 | X14: =Levels!AB14 -> -1.0169709
A15: =Levels!A15 -> 1974Q2 | B15: =Levels!B15/Levels!$R15 -> 1640.6855 | C15: =Levels!C15/Levels!$R15 -> 224409.84 | D15: =Levels!D15/Levels!R15 -> 272871.5 | E15: =Levels!V15/Levels!R15 -> 1520605 | F15: =Levels!E15 -> 970.429 | G15: =Levels!F15 -> 3692.3401 | H15: =Levels!G15 -> 1 | J15: =Levels!AD15 -> -0.010455564 | K15: =Levels!AC15 -> 11.25 | L15: =Levels!I15 -> 0.49468238 | M15: =Levels!J15 -> 1.9427892 | N15: =Levels!K15 -> 0.75252262 | O15: 0.2001 | P15: =Levels!M15 -> 0.55573823 | Q15: =Levels!N15 -> 0.8304851 | R15: =Levels!O15 -> 0.93079601 | S15: =Levels!P15 -> 1.1263069 | T15: =Levels!Q15 -> 5695.859 | U15: =Levels!S15 -> 1.4758472 | V15: =Levels!T15 -> 0.14781982 | W15: =Levels!U15 -> 1.8949369 | X15: =Levels!AB15 -> 2.7618788
A16: =Levels!A16 -> 1974Q3 | B16: =Levels!B16/Levels!$R16 -> 1679.8144 | C16: =Levels!C16/Levels!$R16 -> 222845.09 | D16: =Levels!D16/Levels!R16 -> 261082.14 | E16: =Levels!V16/Levels!R16 -> 1536096.3 | F16: =Levels!E16 -> 953.837 | G16: =Levels!F16 -> 3741.7166 | H16: =Levels!G16 -> 0 | J16: =Levels!AD16 -> -0.012828439 | K16: =Levels!AC16 -> 12.09 | L16: =Levels!I16 -> 0.98917161 | M16: =Levels!J16 -> 1.8519564 | N16: =Levels!K16 -> 1.4335446 | O16: 0.8057 | P16: =Levels!M16 -> 1.1790347 | Q16: =Levels!N16 -> 1.0769671 | R16: =Levels!O16 -> 0.95943359 | S16: =Levels!P16 -> 1.2085358 | T16: =Levels!Q16 -> 5642.025 | U16: =Levels!S16 -> 0.85070264 | V16: =Levels!T16 -> -0.83917508 | W16: =Levels!U16 -> 3.4635749 | X16: =Levels!AB16 -> 3.8256053
A17: =Levels!A17 -> 1974Q4 | B17: =Levels!B17/Levels!$R17 -> 1713.0008 | C17: =Levels!C17/Levels!$R17 -> 229078.15 | D17: =Levels!D17/Levels!R17 -> 273902.32 | E17: =Levels!V17/Levels!R17 -> 1568515.1 | F17: =Levels!E17 -> 911.379 | G17: =Levels!F17 -> 3699.7297 | H17: =Levels!G17 -> -2.1 | J17: =Levels!AD17 -> -0.0022248579 | K17: =Levels!AC17 -> 9.3466667 | L17: =Levels!I17 -> 0.80944859 | M17: =Levels!J17 -> 1.8411448 | N17: =Levels!K17 -> 1.5758592 | O17: 0.8332 | P17: =Levels!M17 -> 1.249375 | Q17: =Levels!N17 -> 0.84920673 | R17: =Levels!O17 -> 0.99742135 | S17: =Levels!P17 -> 1.255074 | T17: =Levels!Q17 -> 5620.126 | U17: =Levels!S17 -> -5.758001 | V17: =Levels!T17 -> -5.0263148 | W17: =Levels!U17 -> 3.9206876 | X17: =Levels!AB17 -> -1.56373
A18: =Levels!A18 -> 1975Q1 | B18: =Levels!B18/Levels!$R18 -> 1718.8821 | C18: =Levels!C18/Levels!$R18 -> 241849.13 | D18: =Levels!D18/Levels!R18 -> 287744.09 | E18: =Levels!V18/Levels!R18 -> 1592870.5 | F18: =Levels!E18 -> 876.76 | G18: =Levels!F18 -> 3709.2438 | H18: =Levels!G18 -> -4.7 | J18: =Levels!AD18 -> 0.0044844086 | K18: =Levels!AC18 -> 6.3033333 | L18: =Levels!I18 -> 0.82049095 | M18: =Levels!J18 -> 1.8958234 | N18: =Levels!K18 -> 1.4959458 | O18: 0.3778 | P18: =Levels!M18 -> 1.1326991 | Q18: =Levels!N18 -> 0.51135438 | R18: =Levels!O18 -> 0.95919584 | S18: =Levels!P18 -> 1.2120658 | T18: =Levels!Q18 -> 5551.713 | U18: =Levels!S18 -> -4.7871748 | V18: =Levels!T18 -> 1.5937692 | W18: =Levels!U18 -> -0.98702404 | X18: =Levels!AB18 -> -0.42944659
A19: =Levels!A19 -> 1975Q2 | B19: =Levels!B19/Levels!$R19 -> 1746.9322 | C19: =Levels!C19/Levels!$R19 -> 261148.69 | D19: =Levels!D19/Levels!R19 -> 300285.19 | E19: =Levels!V19/Levels!R19 -> 1635361 | F19: =Levels!E19 -> 856.806 | G19: =Levels!F19 -> 3722.0426 | H19: =Levels!G19 -> -5.9 | J19: =Levels!AD19 -> -0.0073048033 | K19: =Levels!AC19 -> 5.42 | L19: =Levels!I19 -> 1.4727936 | M19: =Levels!J19 -> 1.9536194 | N19: =Levels!K19 -> 1.2809491 | O19: 0.2218 | P19: =Levels!M19 -> 0.89383769 | Q19: =Levels!N19 -> 0.5661647 | R19: =Levels!O19 -> 0.89676815 | S19: =Levels!P19 -> 1.0760006 | T19: =Levels!Q19 -> 5591.382 | U19: =Levels!S19 -> 2.1712544 | V19: =Levels!T19 -> -1.2464274 | W19: =Levels!U19 -> -0.40670207 | X19: =Levels!AB19 -> -0.87082344
A20: =Levels!A20 -> 1975Q3 | B20: =Levels!B20/Levels!$R20 -> 1773.9547 | C20: =Levels!C20/Levels!$R20 -> 275088.41 | D20: =Levels!D20/Levels!R20 -> 293406.06 | E20: =Levels!V20/Levels!R20 -> 1650365.8 | F20: =Levels!E20 -> 887.954 | G20: =Levels!F20 -> 3760.3223 | H20: =Levels!G20 -> -4.7 | J20: =Levels!AD20 -> 0.0063287292 | K20: =Levels!AC20 -> 6.16 | L20: =Levels!I20 -> 1.8322875 | M20: =Levels!J20 -> 1.9360159 | N20: =Levels!K20 -> 1.4534452 | O20: 0.2827 | P20: =Levels!M20 -> 1.0226612 | Q20: =Levels!N20 -> 0.61879701 | R20: =Levels!O20 -> 0.84630793 | S20: =Levels!P20 -> 1.0188284 | T20: =Levels!Q20 -> 5687.087 | U20: =Levels!S20 -> 0.74547589 | V20: =Levels!T20 -> 2.9214341 | W20: =Levels!U20 -> -0.75612229 | X20: =Levels!AB20 -> 1.6185268
A21: =Levels!A21 -> 1975Q4 | B21: =Levels!B21/Levels!$R21 -> 1810.1814 | C21: =Levels!C21/Levels!$R21 -> 288631.6 | D21: =Levels!D21/Levels!R21 -> 303312.41 | E21: =Levels!V21/Levels!R21 -> 1703308.5 | F21: =Levels!E21 -> 909.903 | G21: =Levels!F21 -> 3792.3721 | H21: =Levels!G21 -> -1.5 | J21: =Levels!AD21 -> -0.0037410724 | K21: =Levels!AC21 -> 5.4133333 | L21: =Levels!I21 -> 1.6964956 | M21: =Levels!J21 -> 1.9512519 | N21: =Levels!K21 -> 1.5485802 | O21: 0.0925 | P21: =Levels!M21 -> 1.0886656 | Q21: =Levels!N21 -> 0.54657055 | R21: =Levels!O21 -> 0.79199991 | S21: =Levels!P21 -> 1.0004591 | T21: =Levels!Q21 -> 5763.665 | U21: =Levels!S21 -> 0.72190291 | V21: =Levels!T21 -> -0.28344698 | W21: =Levels!U21 -> 0.83826267 | X21: =Levels!AB21 -> -0.24768794
... A41: =Levels!A41 -> 1980Q4 | B41: =Levels!B41/Levels!$R41 -> 3144.0727 | C41: =Levels!C41/Levels!$R41 -> 430402.49 | D41: =Levels!D41/Levels!R41 -> 561927.07 | E41: =Levels!V41/Levels!R41 -> 2961520.7 | F41: =Levels!E41 -> 1184.951 | G41: =Levels!F41 -> 4568.3635 | H41: =Levels!G41 -> -1.2 | J41: =Levels!AD41 -> -0.016952831 | K41: =Levels!AC41 -> 15.853333 | L41: =Levels!I41 -> 7.5347326 | M41: =Levels!J41 -> 2.1290306 | N41: =Levels!K41 -> 2.109144 | O41: -0.063 | P41: =Levels!M41 -> 1.1554793 | Q41: =Levels!N41 -> 0.90450839 | R41: =Levels!O41 -> 1.0269331 | S41: =Levels!P41 -> 0.94474727 | T41: =Levels!Q41 -> 6817.903 | U41: =Levels!S41 -> 3.7112981 | V41: =Levels!T41 -> -0.66733789 | W41: =Levels!U41 -> -1.7492748 | X41: =Levels!AB41 -> 0.1402365
A42: =Levels!A42 -> 1981Q1 | B42: =Levels!B42/Levels!$R42 -> 3184.7012 | C42: =Levels!C42/Levels!$R42 -> 459365.68 | D42: =Levels!D42/Levels!R42 -> 576370.85 | E42: =Levels!V42/Levels!R42 -> 3039294 | F42: =Levels!E42 -> 1201.243 | G42: =Levels!F42 -> 4591.5242 | H42: =Levels!G42 -> -0.4 | I42: =Levels!Y42 -> 0.88892155 | J42: =Levels!AD42 -> 0.0030625663 | K42: =Levels!AC42 -> 16.57 | L42: =Levels!I42 -> 8.2256026 | M42: =Levels!J42 -> 2.1189736 | N42: =Levels!K42 -> 2.5209274 | O42: 0.1511 | P42: =Levels!M42 -> 1.561567 | Q42: =Levels!N42 -> 0.84273353 | R42: =Levels!O42 -> 1.0163667 | S42: =Levels!P42 -> 0.92260368 | T42: =Levels!Q42 -> 6951.495 | U42: =Levels!S42 -> -1.9293084 | V42: =Levels!T42 -> -0.22506821 | W42: =Levels!U42 -> -0.57680168 | X42: =Levels!AB42 -> -0.70313636
A43: =Levels!A43 -> 1981Q2 | B43: =Levels!B43/Levels!$R43 -> 3281.2144 | C43: =Levels!C43/Levels!$R43 -> 453082.9 | D43: =Levels!D43/Levels!R43 -> 586864.74 | E43: =Levels!V43/Levels!R43 -> 3115263.4 | F43: =Levels!E43 -> 1201.53 | G43: =Levels!F43 -> 4561.531 | H43: =Levels!G43 -> 1.5 | I43: =Levels!Y43 -> 1.7287282 | J43: =Levels!AD43 -> 0.00097319221 | K43: =Levels!AC43 -> 17.78 | L43: =Levels!I43 -> 9.1581014 | M43: =Levels!J43 -> 2.1201178 | N43: =Levels!K43 -> 2.662997 | O43: 0.3718 | P43: =Levels!M43 -> 1.7171343 | Q43: =Levels!N43 -> 0.78482294 | R43: =Levels!O43 -> 1.0094961 | S43: =Levels!P43 -> 0.91077231 | T43: =Levels!Q43 -> 6899.98 | U43: =Levels!S43 -> 1.6972631 | V43: =Levels!T43 -> -0.72447344 | W43: =Levels!U43 -> -1.2017454 | X43: =Levels!AB43 -> 0.046531181
A44: =Levels!A44 -> 1981Q3 | B44: =Levels!B44/Levels!$R44 -> 3362.1176 | C44: =Levels!C44/Levels!$R44 -> 471301.38 | D44: =Levels!D44/Levels!R44 -> 585290.31 | E44: =Levels!V44/Levels!R44 -> 3203015.5 | F44: =Levels!E44 -> 1197.764 | G44: =Levels!F44 -> 4554.6706 | H44: =Levels!G44 -> 1.9 | I44: =Levels!Y44 -> 2.0917108 | J44: =Levels!AD44 -> 0.00076998275 | K44: =Levels!AC44 -> 17.576667 | L44: =Levels!I44 -> 10.39121 | M44: =Levels!J44 -> 2.0880155 | N44: =Levels!K44 -> 2.9623774 | O44: 0.3037 | P44: =Levels!M44 -> 2.0265009 | Q44: =Levels!N44 -> 0.94767539 | R44: =Levels!O44 -> 1.00587 | S44: =Levels!P44 -> 0.95476983 | T44: =Levels!Q44 -> 6982.609 | U44: =Levels!S44 -> 0.40799323 | V44: =Levels!T44 -> -1.8674344 | W44: =Levels!U44 -> 0.35005574 | X44: =Levels!AB44 -> 1.3330723
A45: =Levels!A45 -> 1981Q4 | B45: =Levels!B45/Levels!$R45 -> 3429.2687 | C45: =Levels!C45/Levels!$R45 -> 504514.3 | D45: =Levels!D45/Levels!R45 -> 601647.47 | E45: =Levels!V45/Levels!R45 -> 3361692.7 | F45: =Levels!E45 -> 1200.996 | G45: =Levels!F45 -> 4495.4954 | H45: =Levels!G45 -> 0.2 | I45: =Levels!Y45 -> 2.0845536 | J45: =Levels!AD45 -> -0.0051487746 | K45: =Levels!AC45 -> 13.586667 | L45: =Levels!I45 -> 9.797838 | M45: =Levels!J45 -> 2.0911363 | N45: =Levels!K45 -> 2.987479 | O45: 0.3885 | P45: =Levels!M45 -> 2.0867719 | Q45: =Levels!N45 -> 0.28532073 | R45: =Levels!O45 -> 1.0118919 | S45: =Levels!P45 -> 0.93622252 | T45: =Levels!Q45 -> 6906.529 | U45: =Levels!S45 -> -3.025595 | V45: =Levels!T45 -> -2.2739214 | W45: =Levels!U45 -> -0.88778327 | X45: =Levels!AB45 -> 0.51262904
A46: =Levels!A46 -> 1982Q1 | B46: =Levels!B46/Levels!$R46 -> 3476.5974 | C46: =Levels!C46/Levels!$R46 -> 525973.22 | D46: =Levels!D46/Levels!R46 -> 607108.19 | E46: =Levels!V46/Levels!R46 -> 3415610 | F46: =Levels!E46 -> 1168.917 | G46: =Levels!F46 -> 4496.4744 | H46: =Levels!G46 -> -2.1 | I46: =Levels!Y46 -> 1.579708 | J46: =Levels!AD46 -> 0.00030904094 | K46: =Levels!AC46 -> 14.226667 | L46: =Levels!I46 -> 10.062422 | M46: =Levels!J46 -> 2.0575478 | N46: =Levels!K46 -> 3.2456478 | O46: 0.6552 | P46: =Levels!M46 -> 2.3810938 | Q46: =Levels!N46 -> 0.17719144 | R46: =Levels!O46 -> 1.018807 | S46: =Levels!P46 -> 0.91682962 | T46: =Levels!Q46 -> 6799.233 | U46: =Levels!S46 -> -0.47249076 | V46: =Levels!T46 -> 1.5338543 | W46: =Levels!U46 -> 0.12816432 | X46: =Levels!AB46 -> -1.1371215
A47: =Levels!A47 -> 1982Q2 | B47: =Levels!B47/Levels!$R47 -> 3552.9576 | C47: =Levels!C47/Levels!$R47 -> 526893.21 | D47: =Levels!D47/Levels!R47 -> 610851.85 | E47: =Levels!V47/Levels!R47 -> 3521202 | F47: =Levels!E47 -> 1143.141 | G47: =Levels!F47 -> 4473.3436 | H47: =Levels!G47 -> -1.7 | I47: =Levels!Y47 -> 2.2858784 | J47: =Levels!AD47 -> 0.01444605 | K47: =Levels!AC47 -> 14.513333 | L47: =Levels!I47 -> 9.8382992 | M47: =Levels!J47 -> 2.0526892 | N47: =Levels!K47 -> 3.3245311 | O47: 0.6189 | P47: =Levels!M47 -> 2.497899 | Q47: =Levels!N47 -> 0.87475224 | R47: =Levels!O47 -> 0.97206958 | S47: =Levels!P47 -> 0.94059797 | T47: =Levels!Q47 -> 6830.251 | U47: =Levels!S47 -> -1.4216617 | V47: =Levels!T47 -> -2.3032458 | W47: =Levels!U47 -> 1.6264403 | X47: =Levels!AB47 -> -0.54074285
A48: =Levels!A48 -> 1982Q3 | B48: =Levels!B48/Levels!$R48 -> 3595.9814 | C48: =Levels!C48/Levels!$R48 -> 575008.18 | D48: =Levels!D48/Levels!R48 -> 627192.77 | E48: =Levels!V48/Levels!R48 -> 3623175.7 | F48: =Levels!E48 -> 1121.696 | G48: =Levels!F48 -> 4500.0533 | H48: =Levels!G48 -> -2.4 | I48: =Levels!Y48 -> 2.1945323 | J48: =Levels!AD48 -> 0.012009587 | K48: =Levels!AC48 -> 11.006667 | L48: =Levels!I48 -> 9.0984286 | M48: =Levels!J48 -> 2.0836197 | N48: =Levels!K48 -> 3.2953811 | O48: 0.3034 | P48: =Levels!M48 -> 2.4906013 | Q48: =Levels!N48 -> 0.30843347 | R48: =Levels!O48 -> 0.94575345 | S48: =Levels!P48 -> 1.0068241 | T48: =Levels!Q48 -> 6804.139 | U48: =Levels!S48 -> -2.3746653 | V48: =Levels!T48 -> 1.1564377 | W48: =Levels!U48 -> 2.2141464 | X48: =Levels!AB48 -> 4.5193036
A49: =Levels!A49 -> 1982Q4 | B49: =Levels!B49/Levels!$R49 -> 3651.6043 | C49: =Levels!C49/Levels!$R49 -> 633731.81 | D49: =Levels!D49/Levels!R49 -> 674838.28 | E49: =Levels!V49/Levels!R49 -> 3717989.4 | F49: =Levels!E49 -> 1129.354 | G49: =Levels!F49 -> 4557.0992 | H49: =Levels!G49 -> -2.8 | I49: =Levels!Y49 -> 1.0426176 | J49: =Levels!AD49 -> -0.038358509 | K49: =Levels!AC49 -> 9.2866667 | L49: =Levels!I49 -> 6.7349724 | M49: =Levels!J49 -> 2.1422282 | N49: =Levels!K49 -> 2.8730823 | O49: 0.4288 | P49: =Levels!M49 -> 2.1098942 | Q49: =Levels!N49 -> -0.10179804 | R49: =Levels!O49 -> 0.91078784 | S49: =Levels!P49 -> 1.0069462 | T49: =Levels!Q49 -> 6806.857 | U49: =Levels!S49 -> -1.6930451 | V49: =Levels!T49 -> -2.6836457 | W49: =Levels!U49 -> -0.92759025 | X49: =Levels!AB49 -> -0.41807029
A50: =Levels!A50 -> 1983Q1 | B50: =Levels!B50/Levels!$R50 -> 3696.8308 | C50: =Levels!C50/Levels!$R50 -> 665170.57 | D50: =Levels!D50/Levels!R50 -> 686618.17 | E50: =Levels!V50/Levels!R50 -> 3774554.6 | F50: =Levels!E50 -> 1150.482 | G50: =Levels!F50 -> 4572.1045 | H50: =Levels!G50 -> -0.6 | I50: =Levels!Y50 -> 0.61462193 | J50: =Levels!AD50 -> -0.002479076 | K50: =Levels!AC50 -> 8.6533333 | L50: =Levels!I50 -> 6.7021344 | M50: =Levels!J50 -> 2.1691834 | N50: =Levels!K50 -> 2.7376199 | O50: 0.2724 | P50: =Levels!M50 -> 2.0222293 | Q50: =Levels!N50 -> 0.10238917 | R50: =Levels!O50 -> 0.87690196 | S50: =Levels!P50 -> 0.94020379 | T50: =Levels!Q50 -> 6896.561 | U50: =Levels!S50 -> 1.1467868 | V50: =Levels!T50 -> 2.6345384 | W50: =Levels!U50 -> -1.0335219 | X50: =Levels!AB50 -> -1.2808507
A51: =Levels!A51 -> 1983Q2 | B51: =Levels!B51/Levels!$R51 -> 3793.8824 | C51: =Levels!C51/Levels!$R51 -> 682287.43 | D51: =Levels!D51/Levels!R51 -> 687097.62 | E51: =Levels!V51/Levels!R51 -> 3877395.9 | F51: =Levels!E51 -> 1186.91 | G51: =Levels!F51 -> 4640.6962 | H51: =Levels!G51 -> 0.1 | I51: =Levels!Y51 -> 1.0273062 | J51: =Levels!AD51 -> -0.0014557321 | K51: =Levels!AC51 -> 8.8033333 | L51: =Levels!I51 -> 6.7680574 | M51: =Levels!J51 -> 2.2142025 | N51: =Levels!K51 -> 2.4897534 | O51: 0.0616 | P51: =Levels!M51 -> 1.7963711 | Q51: =Levels!N51 -> 0.54198465 | R51: =Levels!O51 -> 0.82073508 | S51: =Levels!P51 -> 0.90969026 | T51: =Levels!Q51 -> 7053.5 | U51: =Levels!S51 -> 0.97786839 | V51: =Levels!T51 -> 0.83570919 | W51: =Levels!U51 -> -1.465098 | X51: =Levels!AB51 -> 1.1767909
A52: =Levels!A52 -> 1983Q3 | B52: =Levels!B52/Levels!$R52 -> 3893.42 | C52: =Levels!C52/Levels!$R52 -> 724595.17 | D52: =Levels!D52/Levels!R52 -> 713233.82 | E52: =Levels!V52/Levels!R52 -> 3987111 | F52: =Levels!E52 -> 1248.512 | G52: =Levels!F52 -> 4725.0047 | H52: =Levels!G52 -> 2.8 | I52: =Levels!Y52 -> 1.0543238 | J52: =Levels!AD52 -> 0.012685368 | K52: =Levels!AC52 -> 9.46 | L52: =Levels!I52 -> 7.9169536 | M52: =Levels!J52 -> 2.2194518 | N52: =Levels!K52 -> 2.5606658 | O52: -0.1163 | P52: =Levels!M52 -> 1.8906298 | Q52: =Levels!N52 -> 0.40043745 | R52: =Levels!O52 -> 0.79068312 | S52: =Levels!P52 -> 0.8812983 | T52: =Levels!Q52 -> 7194.504 | U52: =Levels!S52 -> 2.4339858 | V52: =Levels!T52 -> 1.4932135 | W52: =Levels!U52 -> -1.7133386 | X52: =Levels!AB52 -> -0.97507169
A53: =Levels!A53 -> 1983Q4 | B53: =Levels!B53/Levels!$R53 -> 4017.78 | C53: =Levels!C53/Levels!$R53 -> 746249.57 | D53: =Levels!D53/Levels!R53 -> 707054.13 | E53: =Levels!V53/Levels!R53 -> 4099248.5 | F53: =Levels!E53 -> 1308.453 | G53: =Levels!F53 -> 4771.5155 | H53: =Levels!G53 -> 5.8 | I53: =Levels!Y53 -> 0.76761253 | J53: =Levels!AD53 -> 0.0024551115 | K53: =Levels!AC53 -> 9.43 | L53: =Levels!I53 -> 8.035801 | M53: =Levels!J53 -> 2.2169559 | N53: =Levels!K53 -> 2.5908383 | O53: 0.0063 | P53: =Levels!M53 -> 1.9543695 | Q53: =Levels!N53 -> 0.19824954 | R53: =Levels!O53 -> 0.76173376 | S53: =Levels!P53 -> 0.88130842 | T53: =Levels!Q53 -> 7344.597 | U53: =Levels!S53 -> -1.1921137 | V53: =Levels!T53 -> 0.44673632 | W53: =Levels!U53 -> -0.19527248 | X53: =Levels!AB53 -> -0.75730967
... A160: =Levels!A160 -> 2010Q3 | B160: =Levels!B160/Levels!$R160 -> 24040.903 | C160: =Levels!C160/Levels!$R160 -> 3976038.8 | D160: =Levels!D160/Levels!R160 -> 7426008.4 | E160: =Levels!V160/Levels!R160 -> 22326258 | F160: =Levels!E160 -> 2856.404 | G160: =Levels!F160 -> 10530.075 | H160: =Levels!G160 -> 1.4 | I160: =Levels!Y160 -> 0.72751029 | J160: =Levels!AD160 -> -0.0036807405 | K160: =Levels!AC160 -> 0.18666667 | L160: =Levels!I160 -> 1.1854427 | M160: =Levels!J160 -> 3.0517124 | N160: =Levels!K160 -> 2.9467248 | O160: -0.1864 | P160: =Levels!M160 -> 3.2427945 | Q160: =Levels!N160 -> 0.072448119 | R160: =Levels!O160 -> 0.75654172 | S160: =Levels!P160 -> 1.0855742 | T160: =Levels!Q160 -> 15726.282 | U160: =Levels!S160 -> 0.019147689 | V160: =Levels!T160 -> 0.60358029 | W160: =Levels!U160 -> -0.48659862 | X160: =Levels!AB160 -> -0.77002336
A161: =Levels!A161 -> 2010Q4 | B161: =Levels!B161/Levels!$R161 -> 23996.036 | C161: =Levels!C161/Levels!$R161 -> 4306839.1 | D161: =Levels!D161/Levels!R161 -> 7375944.2 | E161: =Levels!V161/Levels!R161 -> 22467318 | F161: =Levels!E161 -> 2892.01 | G161: =Levels!F161 -> 10625.467 | H161: =Levels!G161 -> 2 | I161: =Levels!Y161 -> 1.0023181 | J161: =Levels!AD161 -> 0.014428413 | K161: =Levels!AC161 -> 0.18666667 | L161: =Levels!I161 -> 1.2714216 | M161: =Levels!J161 -> 3.0863683 | N161: =Levels!K161 -> 2.8248676 | P161: =Levels!M161 -> 3.1181639 | Q161: =Levels!N161 -> 0.11280954 | R161: =Levels!O161 -> 0.74815231 | S161: =Levels!P161 -> 0.99033145 | T161: =Levels!Q161 -> 15807.995 | U161: =Levels!S161 -> 1.1490887 | V161: =Levels!T161 -> -2.1975647 | W161: =Levels!U161 -> -2.6184163 | X161: =Levels!AB161 -> -1.5888105
A162: =Levels!A162 -> 2011Q1 | B162: =Levels!B162/Levels!$R162 -> 23964.22 | C162: =Levels!C162/Levels!$R162 -> 4590181.4 | D162: =Levels!D162/Levels!R162 -> 7535270 | E162: =Levels!V162/Levels!R162 -> 22531430 | F162: =Levels!E162 -> 2875.086 | G162: =Levels!F162 -> 10726.621 | H162: =Levels!G162 -> 1.9 | I162: =Levels!Y162 -> 0.97475963 | J162: =Levels!AD162 -> 0.0008042664 | K162: =Levels!AC162 -> 0.15666667 | L162: =Levels!I162 -> 1.7934177 | M162: =Levels!J162 -> 3.114827 | N162: =Levels!K162 -> 2.8138993 | P162: =Levels!M162 -> 3.1058809 | Q162: =Levels!N162 -> 0.6481889 | R162: =Levels!O162 -> 0.75664864 | S162: =Levels!P162 -> 0.921221 | T162: =Levels!Q162 -> 15769.911 | U162: =Levels!S162 -> -1.0833278 | V162: =Levels!T162 -> 0.34972921 | W162: =Levels!U162 -> -1.0523799 | X162: =Levels!AB162 -> -0.93220479
A163: =Levels!A163 -> 2011Q2 | B163: =Levels!B163/Levels!$R163 -> 23939.17 | C163: =Levels!C163/Levels!$R163 -> 4654340 | D163: =Levels!D163/Levels!R163 -> 7591798.5 | E163: =Levels!V163/Levels!R163 -> 22830149 | F163: =Levels!E163 -> 2919.513 | G163: =Levels!F163 -> 10811.283 | H163: =Levels!G163 -> 2.2 | I163: =Levels!Y163 -> 1.824967 | J163: =Levels!AD163 -> 0.0010676411 | K163: =Levels!AC163 -> 0.093333333 | L163: =Levels!I163 -> 1.4730155 | M163: =Levels!J163 -> 3.1207139 | N163: =Levels!K163 -> 2.9863874 | P163: =Levels!M163 -> 3.2967793 | Q163: =Levels!N163 -> 0.335755 | R163: =Levels!O163 -> 0.75238606 | S163: =Levels!P163 -> 0.93018129 | T163: =Levels!Q163 -> 15876.839 | U163: =Levels!S163 -> 0.081994043 | V163: =Levels!T163 -> 0.39988548 | W163: =Levels!U163 -> 2.3896843 | X163: =Levels!AB163 -> 0.39393526
A164: =Levels!A164 -> 2011Q3 | B164: =Levels!B164/Levels!$R164 -> 23943.621 | C164: =Levels!C164/Levels!$R164 -> 5013792 | D164: =Levels!D164/Levels!R164 -> 7549132 | E164: =Levels!V164/Levels!R164 -> 22840229 | F164: =Levels!E164 -> 3008.949 | G164: =Levels!F164 -> 10853.601 | H164: =Levels!G164 -> 2.1 | I164: =Levels!Y164 -> 2.1817312 | J164: =Levels!AD164 -> 0.00080781882 | K164: =Levels!AC164 -> 0.083333333 | L164: =Levels!I164 -> 0.60908899 | M164: =Levels!J164 -> 3.0750807 | N164: =Levels!K164 -> 3.3299777 | P164: =Levels!M164 -> 3.6636525 | Q164: =Levels!N164 -> 0.17206989 | R164: =Levels!O164 -> 0.7598232 | S164: =Levels!P164 -> 1.0446978 | T164: =Levels!Q164 -> 15870.684 | U164: =Levels!S164 -> 0.6461623 | V164: =Levels!T164 -> 2.9440565 | W164: =Levels!U164 -> 3.3809634 | X164: =Levels!AB164 -> 4.8862021
A165: =Levels!A165 -> 2011Q4 | B165: =Levels!B165/Levels!$R165 -> 24026.773 | C165: =Levels!C165/Levels!$R165 -> 5341305.5 | D165: =Levels!D165/Levels!R165 -> 7671833.6 | E165: =Levels!V165/Levels!R165 -> 23076765 | F165: =Levels!E165 -> 3067.232 | G165: =Levels!F165 -> 10859.145 | H165: =Levels!G165 -> 2.4 | I165: =Levels!Y165 -> 1.5509293 | J165: =Levels!AD165 -> 0.0078188391 | K165: =Levels!AC165 -> 0.073333333 | L165: =Levels!I165 -> 0.15771512 | M165: =Levels!J165 -> 3.0916111 | N165: =Levels!K165 -> 3.335041 | P165: =Levels!M165 -> 3.7098175 | Q165: =Levels!N165 -> -0.17909201 | R165: =Levels!O165 -> 0.73770689 | S165: =Levels!P165 -> 1.0180619 | T165: =Levels!Q165 -> 16048.702 | U165: =Levels!S165 -> -0.60875249 | V165: =Levels!T165 -> 0.32447596 | W165: =Levels!U165 -> -4.6667844 | X165: =Levels!AB165 -> -2.1133242
...

Sheet Normalized_cleaned
A1: =Normalized!A1 -> date | B1: =Normalized!B1 -> credit | C1: =Normalized!C1 -> trsry security | D1: =Normalized!D1 -> net worth | E1: =Normalized!E1 -> GFCF | F1: =Normalized!F1 -> cons | G1: =Normalized!G1 -> hours | H1: =Normalized!H1 -> Real 3m r | ... T1: =Normalized!T1 -> unc_f shock
A2: =Levels!A2 -> 1971Q1 | B2: =Normalized!B2 -> 1.1469861 | C2: =Normalized!C2 -> 216.29523 | D2: =Normalized!D2 -> 21804.202 | F2: =Levels!F2/Levels!$Q2 -> 0.61250771 | G2: -2.1 | H2: -1.1999911 | I2: -0.49996228 | J2: 1.9854295 | K2: 0.19569739 | M2: 2.4406015 | N2: 5.00377 | O2: 0.79096956 | P2: 0.97779341 | Q2: 2.69724 | R2: -4.2005676 | S2: 3.5197163 | T2: 0.04792851
A3: =Levels!A3 -> 1971Q2 | B3: =Normalized!B3 -> 1.1817509 | C3: =Normalized!C3 -> 215.13126 | D3: =Normalized!D3 -> 21916.491 | F3: =Levels!F3/Levels!$Q3 -> 0.6141463 | G3: -0.5 | H3: -0.57537905 | I3: -0.33476317 | J3: 2.0035371 | K3: 0.17269642 | M3: 1.8972222 | N3: 5.01786 | O3: 0.75466324 | P3: 0.93890474 | Q3: 3.10661 | R3: 1.0692357 | S3: -1.3260017 | T3: -0.20350855
A4: =Levels!A4 -> 1971Q3 | B4: =Normalized!B4 -> 1.2083143 | C4: =Normalized!C4 -> 212.95609 | D4: =Normalized!D4 -> 22827.074 | F4: =Levels!F4/Levels!$Q4 -> 0.61231841 | G4: 0 | H4: 1.0299225 | I4: -0.17078911 | J4: 1.9910998 | K4: -0.082923813 | M4: 1.6608249 | N4: 4.83776 | O4: 0.76033864 | P4: 0.94071234 | Q4: 3.00589 | R4: -1.0795856 | S4: 0.29892608 | T4: 0.40864258
A5: =Levels!A5 -> 1971Q4 | B5: =Normalized!B5 -> 1.2398683 | C5: =Normalized!C5 -> 222.9612 | D5: =Normalized!D5 -> 23906.508 | F5: =Levels!F5/Levels!$Q5 -> 0.61735026 | G5: 1.9 | H5: 0.55639672 | I5: -0.82348626 | J5: 1.9819173 | K5: 0.090832648 | M5: 1.6553777 | N5: 3.97789 | O5: 0.75628188 | P5: 0.94820076 | Q5: 4.3672 | R5: 2.3988313 | S5: -0.26675265 | T5: 0.47947588
A6: =Levels!A6 -> 1972Q1 | B6: =Normalized!B6 -> 1.2631117 | C6: =Normalized!C6 -> 222.2853 | D6: =Normalized!D6 -> 23872.216 | E6: =Levels!E6/Levels!$Q6 -> 0.17307652 | F6: =Levels!F6/Levels!$Q6 -> 0.61459387 | G6: 2.6 | H6: 0.26047683 | I6: -0.74157349 | J6: 2.0227773 | K6: -0.89174984 | M6: 0.95439693 | N6: 3.6618 | O6: 0.74905767 | P6: 0.89377227 | Q6: 3.4760721 | R6: 0.55881061 | S6: 2.908896 | T6: -3.6705217
A7: =Levels!A7 -> 1972Q2 | B7: =Normalized!B7 -> 1.3085801 | C7: =Normalized!C7 -> 221.31268 | D7: =Normalized!D7 -> 23928.732 | E7: =Levels!E7/Levels!$Q7 -> 0.1712485 | F7: =Levels!F7/Levels!$Q7 -> 0.61032985 | G7: 3 | H7: 0.7805975 | I7: -0.69670607 | J7: 2.0331158 | K7: -0.035339052 | M7: 1.8877984 | N7: 3.18492 | O7: 0.72086478 | P7: 0.86197468 | Q7: 5.2551865 | R7: -0.6140998 | S7: -1.344592 | T7: 0.18384939
A8: =Levels!A8 -> 1972Q3 | B8: =Normalized!B8 -> 1.3403832 | C8: =Normalized!C8 -> 218.8521 | D8: =Normalized!D8 -> 24589.231 | E8: =Levels!E8/Levels!$Q8 -> 0.16932254 | F8: =Levels!F8/Levels!$Q8 -> 0.61441682 | G8: 3.5 | H8: 1.1635024 | I8: -0.61610667 | J8: 2.0413836 | K8: -0.55965761 | M8: 1.0524892 | N8: 2.99034 | O8: 0.7574092 | P8: 0.88100813 | Q8: 5.3819387 | R8: 1.5322161 | S8: -0.045506628 | T8: -0.029725928
A9: =Levels!A9 -> 1972Q4 | B9: =Normalized!B9 -> 1.3872766 | C9: =Normalized!C9 -> 228.73922 | D9: =Normalized!D9 -> 25220.009 | E9: =Levels!E9/Levels!$Q9 -> 0.17364571 | F9: =Levels!F9/Levels!$Q9 -> 0.61893751 | G9: 3.5 | H9: 2.0814833 | I9: -0.59691595 | J9: 2.0655566 | K9: -0.68146812 | M9: 1.3568742 | N9: 3.04745 | O9: 0.78272069 | P9: 0.9260483 | Q9: 6.8944759 | R9: 4.0139768 | S9: 0.10468662 | T9: -0.21161094
A10: =Levels!A10 -> 1973Q1 | B10: =Normalized!B10 -> 1.4264019 | C10: =Normalized!C10 -> 224.99799 | D10: =Normalized!D10 -> 26285.51 | E10: =Levels!E10/Levels!$Q10 -> 0.17642766 | F10: =Levels!F10/Levels!$Q10 -> 0.61779398 | G10: 3.9 | H10: 2.2260942 | I10: -0.41931273 | J10: 2.0605947 | K10: -0.038180953 | L10: 0.8896 | M10: 2.1151618 | N10: 2.78135 | O10: 0.82162467 | P10: 1.0025217 | Q10: 7.5618883 | R10: 1.6886504 | S10: 0.6921871 | T10: 0.30885107
A11: =Levels!A11 -> 1973Q2 | B11: =Normalized!B11 -> 1.4787258 | C11: =Normalized!C11 -> 223.23327 | D11: =Normalized!D11 -> 27740.003 | E11: =Levels!E11/Levels!$Q11 -> 0.17466692 | F11: =Levels!F11/Levels!$Q11 -> 0.61832286 | G11: 4.2 | H11: 2.5281508 | I11: -0.26696048 | J11: 2.0294043 | K11: 0.72880495 | L11: 0.8471 | M11: 3.0131481 | N11: 3.48068 | O11: 0.85461162 | P11: 1.0680409 | Q11: 6.31966 | R11: 1.8592563 | S11: -1.2523708 | T11: 1.3124441
A12: =Levels!A12 -> 1973Q3 | B12: =Normalized!B12 -> 1.5224616 | C12: =Normalized!C12 -> 219.7076 | D12: =Normalized!D12 -> 29927.057 | E12: =Levels!E12/Levels!$Q12 -> 0.17410296 | F12: =Levels!F12/Levels!$Q12 -> 0.62967048 | G12: 4.3 | H12: 3.4716694 | I12: 0.12014968 | J12: 2.0268212 | K12: 0.074922404 | L12: 0.6955 | M12: 2.0486348 | N12: 4.0755 | O12: 0.94089069 | P12: 1.1392991 | Q12: 4.7710873 | R12: 3.5375632 | S12: 0.26813095 | T12: 1.2148524
A13: =Levels!A13 -> 1973Q4 | B13: =Normalized!B13 -> 1.5604965 | C13: =Normalized!C13 -> 228.41445 | D13: =Normalized!D13 -> 30873.861 | E13: =Levels!E13/Levels!$Q13 -> 0.17143948 | F13: =Levels!F13/Levels!$Q13 -> 0.62826642 | G13: 3.8 | H13: 1.5712567 | I13: -0.34416786 | J13: 1.9926584 | K13: 1.0961419 | L13: 1.0661 | M13: 4.0151529 | N13: 4.86341 | O13: 0.94060057 | P13: 1.1964164 | Q13: 4.0237564 | R13: 1.7073099 | S13: 0.11346682 | T13: -1.9173436
A14: =Levels!A14 -> 1974Q1 | B14: =Normalized!B14 -> 1.5866712 | C14: =Normalized!C14 -> 224.96349 | D14: =Normalized!D14 -> 32325.49 | E14: =Levels!E14/Levels!$Q14 -> 0.1713864 | F14: =Levels!F14/Levels!$Q14 -> 0.6389746 | G14: 1.8 | H14: 0.54385197 | I14: -0.038360527 | J14: 1.9806951 | K14: 0.13757708 | L14: 0.9828 | M14: 2.7278288 | N14: 5.92591 | O14: 0.92797056 | P14: 1.1147487 | Q14: 0.63877388 | R14: -0.36504646 | S14: -0.73052763 | T14: -0.10677294
A15: =Levels!A15 -> 1974Q2 | B15: =Normalized!B15 -> 1.6406855 | C15: =Normalized!C15 -> 224.40984 | D15: =Normalized!D15 -> 34346.31 | E15: =Levels!E15/Levels!$Q15 -> 0.17037448 | F15: =Levels!F15/Levels!$Q15 -> 0.64824991 | G15: 1 | H15: -0.55646492 | I15: 0.49468238 | J15: 1.9427892 | K15: 1.1230131 | L15: 1.1519 | M15: 2.9483717 | N15: 7.10123 | O15: 0.93079601 | P15: 1.1263069 | Q15: -0.2084182 | R15: 1.4758472 | S15: 0.14781982 | T15: 1.8949369
A16: =Levels!A16 -> 1974Q3 | B16: =Normalized!B16 -> 1.6798144 | C16: =Normalized!C16 -> 222.84509 | D16: =Normalized!D16 -> 36061.85 | E16: =Levels!E16/Levels!$Q16 -> 0.16905934 | F16: =Levels!F16/Levels!$Q16 -> 0.66318682 | G16: 0 | H16: -1.6525712 | I16: 0.98917161 | J16: 1.8519564 | K16: 1.0579456 | L16: 1.9156 | M16: 2.8896119 | N16: 8.71583 | O16: 0.95943359 | P16: 1.2085358 | Q16: -0.62900049 | R16: 0.85070264 | S16: -0.83917508 | T16: 3.4635749
A17: =Levels!A17 -> 1974Q4 | B17: =Normalized!B17 -> 1.7130008 | C17: =Normalized!C17 -> 229.07815 | D17: =Normalized!D17 -> 38346.851 | E17: =Levels!E17/Levels!$Q17 -> 0.16216345 | F17: =Levels!F17/Levels!$Q17 -> 0.65830013 | G17: -2.1 | H17: -2.7436993 | I17: 0.80944859 | J17: 1.8411448 | K17: 0.63063489 | L17: 2.0764 | M17: 4.1781395 | N17: 9.84554 | O17: 0.99742135 | P17: 1.255074 | Q17: -1.9454494 | R17: -5.758001 | S17: -5.0263148 | T17: 3.9206876
A18: =Levels!A18 -> 1975Q1 | B18: =Normalized!B18 -> 1.7188821 | C18: =Normalized!C18 -> 241.84913 | D18: =Normalized!D18 -> 38222.127 | E18: =Levels!E18/Levels!$Q18 -> 0.15792603 | F18: =Levels!F18/Levels!$Q18 -> 0.668126 | G18: -4.7 | H18: -3.29118 | I18: 0.82049095 | J18: 1.8958234 | K18: -1.8346178 | L18: 1.415 | M18: 3.632642 | N18: 10.10206 | O18: 0.95919584 | P18: 1.2120658 | Q18: -2.2990476 | R18: -4.7871748 | S18: 1.5937692 | T18: -0.98702404
A19: =Levels!A19 -> 1975Q2 | B19: =Normalized!B19 -> 1.7469322 | C19: =Normalized!C19 -> 261.14869 | D19: =Normalized!D19 -> 37696.126 | E19: =Levels!E19/Levels!$Q19 -> 0.15323689 | F19: =Levels!F19/Levels!$Q19 -> 0.66567488 | G19: -5.9 | H19: -2.231465 | I19: 1.4727936 | J19: 1.9536194 | K19: 0.18272604 | L19: 1.2315 | M19: 3.40276 | N19: 9.06618 | O19: 0.89676815 | P19: 1.0760006 | Q19: -1.8342624 | R19: 2.1712544 | S19: -1.2464274 | T19: -0.40670207
A20: =Levels!A20 -> 1975Q3 | B20: =Normalized!B20 -> 1.7739547 | C20: =Normalized!C20 -> 275.08841 | D20: =Normalized!D20 -> 37539.739 | E20: =Levels!E20/Levels!$Q20 -> 0.15613512 | F20: =Levels!F20/Levels!$Q20 -> 0.66120358 | G20: -4.7 | H20: -0.4431025 | I20: 1.8322875 | J20: 1.9360159 | K20: 0.77819691 | L20: 1.1963 | M20: 4.7881683 | N20: 7.62834 | O20: 0.84630793 | P20: 1.0188284 | Q20: 0.79868487 | R20: 0.74547589 | S20: 2.9214341 | T20: -0.75612229
A21: =Levels!A21 -> 1975Q4 | B21: =Normalized!B21 -> 1.8101814 | C21: =Normalized!C21 -> 288.6316 | D21: =Normalized!D21 -> 38279.545 | E21: =Levels!E21/Levels!$Q21 -> 0.15786882 | F21: =Levels!F21/Levels!$Q21 -> 0.65797927 | G21: -1.5 | H21: -0.67907902 | I21: 1.6964956 | J21: 1.9512519 | K21: 0.17695831 | L21: 1.0724 | M21: 5.9981157 | N21: 6.77154 | O21: 0.79199991 | P21: 1.0004591 | Q21: 2.5540175 | R21: 0.72190291 | S21: -0.28344698 | T21: 0.83826267
... A160: =Levels!A160 -> 2010Q3 | B160: =Normalized!B160 -> 24.040903 | C160: =Normalized!C160 -> 3976.0388 | D160: =Normalized!D160 -> 350068.15 | E160: =Levels!E160/Levels!$Q160 -> 0.18163251 | F160: =Levels!F160/Levels!$Q160 -> 0.66958452 | G160: 1.4 | H160: -0.93048625 | I160: 1.1854427 | J160: 3.0517124 | K160: -0.71723057 | L160: 2.5012 | M160: -2.1674698 | N160: 1.39508 | O160: 0.75654172 | P160: 1.0855742 | Q160: 3.3491938 | R160: 0.019147689 | S160: 0.60358029 | T160: -0.48659862
A161: =Levels!A161 -> 2010Q4 | B161: =Normalized!B161 -> 23.996036 | C161: =Normalized!C161 -> 4306.8391 | D161: =Normalized!D161 -> 335925.19 | E161: =Levels!E161/Levels!$Q161 -> 0.18294603 | F161: =Levels!F161/Levels!$Q161 -> 0.67215782 | G161: 2 | H161: -1.0445739 | I161: 1.2714216 | J161: 3.0863683 | K161: -0.35392615 | M161: -2.4165292 | N161: 1.08533 | O161: 0.74815231 | P161: 0.99033145 | Q161: 2.7884497 | R161: 1.1490887 | S161: -2.1975647 | T161: -2.6184163
A162: =Levels!A162 -> 2011Q1 | B162: =Normalized!B162 -> 23.96422 | C162: =Normalized!C162 -> 4590.1814 | D162: =Normalized!D162 -> 333646.65 | E162: =Levels!E162/Levels!$Q162 -> 0.18231466 | F162: =Levels!F162/Levels!$Q162 -> 0.68019544 | G162: 1.9 | H162: -1.3748058 | I162: 1.7934177 | J162: 3.114827 | K162: -0.33205916 | M162: -3.9249336 | N162: 1.18409 | O162: 0.75664864 | P162: 0.921221 | Q162: 2.0306082 | R162: -1.0833278 | S162: 0.34972921 | T162: -1.0523799
A163: =Levels!A163 -> 2011Q2 | B163: =Normalized!B163 -> 23.93917 | C163: =Normalized!C163 -> 4654.34 | D163: =Normalized!D163 -> 334718.07 | E163: =Levels!E163/Levels!$Q163 -> 0.18388503 | F163: =Levels!F163/Levels!$Q163 -> 0.6809468 | G163: 2.2 | H163: -1.7628519 | I163: 1.4730155 | J163: 3.1207139 | K163: 0.23406256 | M163: -3.2850058 | N163: 1.50158 | O163: 0.75238606 | P163: 0.93018129 | Q163: 1.7379051 | R163: 0.081994043 | S163: 0.39988548 | T163: 2.3896843
A164: =Levels!A164 -> 2011Q3 | B164: =Normalized!B164 -> 23.943621 | C164: =Normalized!C164 -> 5013.792 | D164: =Normalized!D164 -> 348669.66 | E164: =Levels!E164/Levels!$Q164 -> 0.18959164 | F164: =Levels!F164/Levels!$Q164 -> 0.68387733 | G164: 2.1 | H164: -1.82447 | I164: 0.60908899 | J164: 3.0750807 | K164: 0.59824903 | M164: -1.1341993 | N164: 1.80809 | O164: 0.7598232 | P164: 1.0446978 | Q164: 0.91822085 | R164: 0.6461623 | S164: 2.9440565 | T164: 3.3809634
A165: =Levels!A165 -> 2011Q4 | B165: =Normalized!B165 -> 24.026773 | C165: =Normalized!C165 -> 5341.3055 | D165: =Normalized!D165 -> 348677.59 | E165: =Levels!E165/Levels!$Q165 -> 0.19112025 | F165: =Levels!F165/Levels!$Q165 -> 0.67663695 | G165: 2.4 | H165: -2.0284459 | I165: 0.15771512 | J165: 3.0916111 | K165: 0.15617172 | M165: -0.020767631 | N165: 1.84947 | O165: 0.73770689 | P165: 1.0180619 | Q165: 1.5226915 | R165: -0.60875249 | S165: 0.32447596 | T165: -4.6667844
A166: =Levels!A166 -> 2012Q1 | B166: =Normalized!B166 -> 24.068553 | C166: =Normalized!C166 -> 5735.451 | D166: =Normalized!D166 -> 369777.53 | E166: =Levels!E166/Levels!$Q166 -> 0.19344599 | F166: =Levels!F166/Levels!$Q166 -> 0.67733756 | G166: 3.1 | H166: -1.7991348 | I166: 0.076403333 | J166: 3.1293495 | K166: -0.3479205 | M166: -0.39181073 | N166: 2.0432 | O166: 0.71559723 | P166: 0.91206994 | Q166: 2.6002493 | R166: -0.83450165 | S166: 0.10112817 | T166: -0.32687477
A167: =Levels!A167 -> 2012Q2 | B167: =Normalized!B167 -> 24.13318 | C167: =Normalized!C167 -> 5789.2431 | D167: =Normalized!D167 -> 374552.94 | E167: =Levels!E167/Levels!$Q167 -> 0.19547629 | F167: =Levels!F167/Levels!$Q167 -> 0.67392733 | G167: 2.2 | H167: -1.6122087 | I167: -0.20694732 | J167: 3.13115 | K167: 0.26124486 | M167: 0.37744621 | N167: 1.86978 | O167: 0.70555585 | P167: 0.88215008 | Q167: 2.3738163 | R167: -0.21761944 | S167: -0.17054583 | T167: -0.90206171
A168: =Levels!A168 -> 2012Q3 | B168: =Normalized!B168 -> 24.322303 | C168: =Normalized!C168 -> 5910.0063 | D168: =Normalized!D168 -> 368955.65 | E168: =Levels!E168/Levels!$Q168 -> 0.19474982 | F168: =Levels!F168/Levels!$Q168 -> 0.6732103 | G168: 2.4 | H168: -1.6856227 | I168: -0.46215587 | J168: 3.1547647 | K168: -0.086295486 | M168: 0.023707249 | N168: 1.70049 | O168: 0.71137391 | P168: 0.82532662 | Q168: 2.592623 | R168: -0.73819541 | S168: -1.1738945 | T168: -1.1164353
A169: =Levels!A169 -> 2012Q4 | B169: =Normalized!B169 -> 24.514114 | C169: =Normalized!C169 -> 5977.2402 | D169: =Normalized!D169 -> 375241.91 | E169: =Levels!E169/Levels!$Q169 -> 0.19682031 | F169: =Levels!F169/Levels!$Q169 -> 0.6759153 | G169: 2.1 | H169: -1.4654279 | I169: -0.4666082 | J169: 3.1487049 | K169: 0.44689915 | M169: 0.91764785 | N169: 1.78721 | O169: 0.71528796 | P169: 0.80250874 | Q169: 1.5660643 | R169: 1.2729781 | S169: -0.80718583 | T169: -0.16894063
A170: =Levels!A170 -> 2013Q1 | B170: =Normalized!B170 -> 24.509098 | C170: =Normalized!C170 -> 6103.3672 | D170: =Normalized!D170 -> 370346.21 | E170: =Levels!E170/Levels!$Q170 -> 0.1970156 | F170: =Levels!F170/Levels!$Q170 -> 0.67347935 | G170: 1.7 | H170: -1.3592067 | I170: -0.2850469 | J170: 3.1801947 | K170: -0.47401299 | M170: 0.17898354 | N170: 1.5551 | O170: 0.71595232 | P170: 0.80977213 | Q170: 1.6163011 | R170: -1.1628731 | S170: 1.9258847 | T170: -0.22683252
A171: =Levels!A171 -> 2013Q2 | B171: =Normalized!B171 -> 24.671406 | C171: =Normalized!C171 -> 5903.3896 | D171: =Normalized!D171 -> 347447.83 | E171: =Levels!E171/Levels!$Q171 -> 0.1978664 | F171: =Levels!F171/Levels!$Q171 -> 0.67162912 | G171: 2 | H171: -1.4936675 | I171: -0.26640537 | J171: 3.2106132 | K171: -0.23323791 | M171: 0.37915556 | N171: 1.44554 | O171: 0.68643445 | P171: 0.81741085 | Q171: 1.2961705 | R171: -2.6163394 | S171: 1.3218152 | T171: 0.76916278
A172: =Levels!A172 -> 2013Q3 | B172: =Normalized!B172 -> 24.925901 | C172: =Normalized!C172 -> 5901.0628 | D172: =Normalized!D172 -> 349835.91 | E172: =Levels!E172/Levels!$Q172 -> 0.19921014 | F172: =Levels!F172/Levels!$Q172 -> 0.66897683 | G172: 2 | H172: -1.5602625 | I172: 0.43372925 | J172: 3.2284782 | K172: -0.24630715 | M172: -0.50150809 | N172: 1.54523 | O172: 0.67632809 | P172: 0.84172166 | Q172: 1.9198446 | R172: -0.70887009 | S172: 1.1835532 | T172: 0.030942278
... A193: =Levels!A193 -> 2018Q4 | B193: =Normalized!B193 -> 30.912642 | C193: =Normalized!C193 -> 8880.7328 | D193: =Normalized!D193 -> 370797.01 | E193: =Levels!E193/Levels!$Q193 -> 0.21325367 | F193: =Levels!F193/Levels!$Q193 -> 0.67430656 | G193: 2.6 | H193: -1.2008087 | I193: -0.256725 | J193: 3.3222287 | K193: -0.53872108 | M193: -3.982447 | N193: 1.30435 | O193: 0.78124467 | P193: 0.84736693 | Q193: 3.0398547 | R193: -0.3910144 | S193: 0.5303932 | T193: 0.12045721

Sheet Normalized
A1: =Levels!A1 -> date | B1: =Levels!B1 -> credit | C1: =Levels!C1 -> trsry security | D1: =Levels!D1 -> net worth | E1: =Levels!E1 -> GFCF | F1: =Levels!F1 -> cons | G1: =Levels!G1 -> hours | H1: =Levels!H1 -> Real 3m r | ... Q1: =Levels!Q1 -> GDP | R1: unc_m shock | S1: ip shock | T1: unc_f shock
A2: 1971Q1 | B2: =Levels!B2/(Levels!$R2*1000) -> 1.1469861 | C2: =Levels!C2/(Levels!$R2*1000) -> 216.29523 | D2: =Levels!D2/EXP(Levels!$J2) -> 21804.202 | F2: =Levels!F2/Levels!$Q2 -> 0.61250771 | G2: -2.1 | H2: -1.1999911 | I2: -0.49996228 | J2: 1.9854295 | K2: 0.19569739 | M2: 2.4406015 | N2: 5.00377 | O2: 0.79096956 | P2: 0.97779341 | Q2: 5072.996 | R2: -4.2005676 | S2: 3.5197163 | T2: 0.04792851
A3: 1971Q2 | B3: =Levels!B3/(Levels!$R3*1000) -> 1.1817509 | C3: =Levels!C3/(Levels!$R3*1000) -> 215.13126 | D3: =Levels!D3/EXP(Levels!$J3) -> 21916.491 | F3: =Levels!F3/Levels!$Q3 -> 0.6141463 | G3: -0.5 | H3: -0.57537905 | I3: -0.33476317 | J3: 2.0035371 | K3: 0.17269642 | M3: 1.8972222 | N3: 5.01786 | O3: 0.75466324 | P3: 0.93890474 | Q3: 5100.447 | R3: 1.0692357 | S3: -1.3260017 | T3: -0.20350855
A4: 1971Q3 | B4: =Levels!B4/(Levels!$R4*1000) -> 1.2083143 | C4: =Levels!C4/(Levels!$R4*1000) -> 212.95609 | D4: =Levels!D4/EXP(Levels!$J4) -> 22827.074 | F4: =Levels!F4/Levels!$Q4 -> 0.61231841 | G4: 0 | H4: 1.0299225 | I4: -0.17078911 | J4: 1.9910998 | K4: -0.082923813 | M4: 1.6608249 | N4: 4.83776 | O4: 0.76033864 | P4: 0.94071234 | Q4: 5142.422 | R4: -1.0795856 | S4: 0.29892608 | T4: 0.40864258
A5: 1971Q4 | B5: =Levels!B5/(Levels!$R5*1000) -> 1.2398683 | C5: =Levels!C5/(Levels!$R5*1000) -> 222.9612 | D5: =Levels!D5/EXP(Levels!$J5) -> 23906.508 | F5: =Levels!F5/Levels!$Q5 -> 0.61735026 | G5: 1.9 | H5: 0.55639672 | I5: -0.82348626 | J5: 1.9819173 | K5: 0.090832648 | M5: 1.6553777 | N5: 3.97789 | O5: 0.75628188 | P5: 0.94820076 | Q5: 5154.547 | R5: 2.3988313 | S5: -0.26675265 | T5: 0.47947588
A6: 1972Q1 | B6: =Levels!B6/(Levels!$R6*1000) -> 1.2631117 | C6: =Levels!C6/(Levels!$R6*1000) -> 222.2853 | D6: =Levels!D6/EXP(Levels!$J6) -> 23872.216 | E6: =Levels!E6/Levels!$Q6 -> 0.17307652 | F6: =Levels!F6/Levels!$Q6 -> 0.61459387 | G6: 2.6 | H6: 0.26047683 | I6: -0.74157349 | J6: 2.0227773 | K6: -0.89174984 | M6: 0.95439693 | N6: 3.6618 | O6: 0.74905767 | P6: 0.89377227 | Q6: 5249.337 | R6: 0.55881061 | S6: 2.908896 | T6: -3.6705217
A7: 1972Q2 | B7: =Levels!B7/(Levels!$R7*1000) -> 1.3085801 | C7: =Levels!C7/(Levels!$R7*1000) -> 221.31268 | D7: =Levels!D7/EXP(Levels!$J7) -> 23928.732 | E7: =Levels!E7/Levels!$Q7 -> 0.1712485 | F7: =Levels!F7/Levels!$Q7 -> 0.61032985 | G7: 3 | H7: 0.7805975 | I7: -0.69670607 | J7: 2.0331158 | K7: -0.035339052 | M7: 1.8877984 | N7: 3.18492 | O7: 0.72086478 | P7: 0.86197468 | Q7: 5368.485 | R7: -0.6140998 | S7: -1.344592 | T7: 0.18384939
A8: 1972Q3 | B8: =Levels!B8/(Levels!$R8*1000) -> 1.3403832 | C8: =Levels!C8/(Levels!$R8*1000) -> 218.8521 | D8: =Levels!D8/EXP(Levels!$J8) -> 24589.231 | E8: =Levels!E8/Levels!$Q8 -> 0.16932254 | F8: =Levels!F8/Levels!$Q8 -> 0.61441682 | G8: 3.5 | H8: 1.1635024 | I8: -0.61610667 | J8: 2.0413836 | K8: -0.55965761 | M8: 1.0524892 | N8: 2.99034 | O8: 0.7574092 | P8: 0.88100813 | Q8: 5419.184 | R8: 1.5322161 | S8: -0.045506628 | T8: -0.029725928
A9: 1972Q4 | B9: =Levels!B9/(Levels!$R9*1000) -> 1.3872766 | C9: =Levels!C9/(Levels!$R9*1000) -> 228.73922 | D9: =Levels!D9/EXP(Levels!$J9) -> 25220.009 | E9: =Levels!E9/Levels!$Q9 -> 0.17364571 | F9: =Levels!F9/Levels!$Q9 -> 0.61893751 | G9: 3.5 | H9: 2.0814833 | I9: -0.59691595 | J9: 2.0655566 | K9: -0.68146812 | M9: 1.3568742 | N9: 3.04745 | O9: 0.78272069 | P9: 0.9260483 | Q9: 5509.926 | R9: 4.0139768 | S9: 0.10468662 | T9: -0.21161094
A10: 1973Q1 | B10: =Levels!B10/(Levels!$R10*1000) -> 1.4264019 | C10: =Levels!C10/(Levels!$R10*1000) -> 224.99799 | D10: =Levels!D10/EXP(Levels!$J10) -> 26285.51 | E10: =Levels!E10/Levels!$Q10 -> 0.17642766 | F10: =Levels!F10/Levels!$Q10 -> 0.61779398 | G10: 3.9 | H10: 2.2260942 | I10: -0.41931273 | J10: 2.0605947 | K10: -0.038180953 | L10: 0.8896 | M10: 2.1151618 | N10: 2.78135 | O10: 0.82162467 | P10: 1.0025217 | Q10: 5646.286 | R10: 1.6886504 | S10: 0.6921871 | T10: 0.30885107
A11: 1973Q2 | B11: =Levels!B11/(Levels!$R11*1000) -> 1.4787258 | C11: =Levels!C11/(Levels!$R11*1000) -> 223.23327 | D11: =Levels!D11/EXP(Levels!$J11) -> 27740.003 | E11: =Levels!E11/Levels!$Q11 -> 0.17466692 | F11: =Levels!F11/Levels!$Q11 -> 0.61832286 | G11: 4.2 | H11: 2.5281508 | I11: -0.26696048 | J11: 2.0294043 | K11: 0.72880495 | L11: 0.8471 | M11: 3.0131481 | N11: 3.48068 | O11: 0.85461162 | P11: 1.0680409 | Q11: 5707.755 | R11: 1.8592563 | S11: -1.2523708 | T11: 1.3124441
A12: 1973Q3 | B12: =Levels!B12/(Levels!$R12*1000) -> 1.5224616 | C12: =Levels!C12/(Levels!$R12*1000) -> 219.7076 | D12: =Levels!D12/EXP(Levels!$J12) -> 29927.057 | E12: =Levels!E12/Levels!$Q12 -> 0.17410296 | F12: =Levels!F12/Levels!$Q12 -> 0.62967048 | G12: 4.3 | H12: 3.4716694 | I12: 0.12014968 | J12: 2.0268212 | K12: 0.074922404 | L12: 0.6955 | M12: 2.0486348 | N12: 4.0755 | O12: 0.94089069 | P12: 1.1392991 | Q12: 5677.738 | R12: 3.5375632 | S12: 0.26813095 | T12: 1.2148524
A13: 1973Q4 | B13: =Levels!B13/(Levels!$R13*1000) -> 1.5604965 | C13: =Levels!C13/(Levels!$R13*1000) -> 228.41445 | D13: =Levels!D13/EXP(Levels!$J13) -> 30873.861 | E13: =Levels!E13/Levels!$Q13 -> 0.17143948 | F13: =Levels!F13/Levels!$Q13 -> 0.62826642 | G13: 3.8 | H13: 1.5712567 | I13: -0.34416786 | J13: 1.9926584 | K13: 1.0961419 | L13: 1.0661 | M13: 4.0151529 | N13: 4.86341 | O13: 0.94060057 | P13: 1.1964164 | Q13: 5731.632 | R13: 1.7073099 | S13: 0.11346682 | T13: -1.9173436
A14: 1974Q1 | B14: =Levels!B14/(Levels!$R14*1000) -> 1.5866712 | C14: =Levels!C14/(Levels!$R14*1000) -> 224.96349 | D14: =Levels!D14/EXP(Levels!$J14) -> 32325.49 | E14: =Levels!E14/Levels!$Q14 -> 0.1713864 | F14: =Levels!F14/Levels!$Q14 -> 0.6389746 | G14: 1.8 | H14: 0.54385197 | I14: -0.038360527 | J14: 1.9806951 | K14: 0.13757708 | L14: 0.9828 | M14: 2.7278288 | N14: 5.92591 | O14: 0.92797056 | P14: 1.1147487 | Q14: 5682.353 | R14: -0.36504646 | S14: -0.73052763 | T14: -0.10677294
A15: 1974Q2 | B15: =Levels!B15/(Levels!$R15*1000) -> 1.6406855 | C15: =Levels!C15/(Levels!$R15*1000) -> 224.40984 | D15: =Levels!D15/EXP(Levels!$J15) -> 34346.31 | E15: =Levels!E15/Levels!$Q15 -> 0.17037448 | F15: =Levels!F15/Levels!$Q15 -> 0.64824991 | G15: 1 | H15: -0.55646492 | I15: 0.49468238 | J15: 1.9427892 | K15: 1.1230131 | L15: 1.1519 | M15: 2.9483717 | N15: 7.10123 | O15: 0.93079601 | P15: 1.1263069 | Q15: 5695.859 | R15: 1.4758472 | S15: 0.14781982 | T15: 1.8949369
A16: 1974Q3 | B16: =Levels!B16/(Levels!$R16*1000) -> 1.6798144 | C16: =Levels!C16/(Levels!$R16*1000) -> 222.84509 | D16: =Levels!D16/EXP(Levels!$J16) -> 36061.85 | E16: =Levels!E16/Levels!$Q16 -> 0.16905934 | F16: =Levels!F16/Levels!$Q16 -> 0.66318682 | G16: 0 | H16: -1.6525712 | I16: 0.98917161 | J16: 1.8519564 | K16: 1.0579456 | L16: 1.9156 | M16: 2.8896119 | N16: 8.71583 | O16: 0.95943359 | P16: 1.2085358 | Q16: 5642.025 | R16: 0.85070264 | S16: -0.83917508 | T16: 3.4635749
A17: 1974Q4 | B17: =Levels!B17/(Levels!$R17*1000) -> 1.7130008 | C17: =Levels!C17/(Levels!$R17*1000) -> 229.07815 | D17: =Levels!D17/EXP(Levels!$J17) -> 38346.851 | E17: =Levels!E17/Levels!$Q17 -> 0.16216345 | F17: =Levels!F17/Levels!$Q17 -> 0.65830013 | G17: -2.1 | H17: -2.7436993 | I17: 0.80944859 | J17: 1.8411448 | K17: 0.63063489 | L17: 2.0764 | M17: 4.1781395 | N17: 9.84554 | O17: 0.99742135 | P17: 1.255074 | Q17: 5620.126 | R17: -5.758001 | S17: -5.0263148 | T17: 3.9206876
A18: 1975Q1 | B18: =Levels!B18/(Levels!$R18*1000) -> 1.7188821 | C18: =Levels!C18/(Levels!$R18*1000) -> 241.84913 | D18: =Levels!D18/EXP(Levels!$J18) -> 38222.127 | E18: =Levels!E18/Levels!$Q18 -> 0.15792603 | F18: =Levels!F18/Levels!$Q18 -> 0.668126 | G18: -4.7 | H18: -3.29118 | I18: 0.82049095 | J18: 1.8958234 | K18: -1.8346178 | L18: 1.415 | M18: 3.632642 | N18: 10.10206 | O18: 0.95919584 | P18: 1.2120658 | Q18: 5551.713 | R18: -4.7871748 | S18: 1.5937692 | T18: -0.98702404
A19: 1975Q2 | B19: =Levels!B19/(Levels!$R19*1000) -> 1.7469322 | C19: =Levels!C19/(Levels!$R19*1000) -> 261.14869 | D19: =Levels!D19/EXP(Levels!$J19) -> 37696.126 | E19: =Levels!E19/Levels!$Q19 -> 0.15323689 | F19: =Levels!F19/Levels!$Q19 -> 0.66567488 | G19: -5.9 | H19: -2.231465 | I19: 1.4727936 | J19: 1.9536194 | K19: 0.18272604 | L19: 1.2315 | M19: 3.40276 | N19: 9.06618 | O19: 0.89676815 | P19: 1.0760006 | Q19: 5591.382 | R19: 2.1712544 | S19: -1.2464274 | T19: -0.40670207
A20: 1975Q3 | B20: =Levels!B20/(Levels!$R20*1000) -> 1.7739547 | C20: =Levels!C20/(Levels!$R20*1000) -> 275.08841 | D20: =Levels!D20/EXP(Levels!$J20) -> 37539.739 | E20: =Levels!E20/Levels!$Q20 -> 0.15613512 | F20: =Levels!F20/Levels!$Q20 -> 0.66120358 | G20: -4.7 | H20: -0.4431025 | I20: 1.8322875 | J20: 1.9360159 | K20: 0.77819691 | L20: 1.1963 | M20: 4.7881683 | N20: 7.62834 | O20: 0.84630793 | P20: 1.0188284 | Q20: 5687.087 | R20: 0.74547589 | S20: 2.9214341 | T20: -0.75612229
A21: 1975Q4 | B21: =Levels!B21/(Levels!$R21*1000) -> 1.8101814 | C21: =Levels!C21/(Levels!$R21*1000) -> 288.6316 | D21: =Levels!D21/EXP(Levels!$J21) -> 38279.545 | E21: =Levels!E21/Levels!$Q21 -> 0.15786882 | F21: =Levels!F21/Levels!$Q21 -> 0.65797927 | G21: -1.5 | H21: -0.67907902 | I21: 1.6964956 | J21: 1.9512519 | K21: 0.17695831 | L21: 1.0724 | M21: 5.9981157 | N21: 6.77154 | O21: 0.79199991 | P21: 1.0004591 | Q21: 5763.665 | R21: 0.72190291 | S21: -0.28344698 | T21: 0.83826267
... A160: 2010Q3 | B160: =Levels!B160/(Levels!$R160*1000) -> 24.040903 | C160: =Levels!C160/(Levels!$R160*1000) -> 3976.0388 | D160: =Levels!D160/EXP(Levels!$J160) -> 350068.15 | E160: =Levels!E160/Levels!$Q160 -> 0.18163251 | F160: =Levels!F160/Levels!$Q160 -> 0.66958452 | G160: 1.4 | H160: -0.93048625 | I160: 1.1854427 | J160: 3.0517124 | K160: -0.71723057 | L160: 2.5012 | M160: -2.1674698 | N160: 1.39508 | O160: 0.75654172 | P160: 1.0855742 | Q160: 15726.282 | R160: 0.019147689 | S160: 0.60358029 | T160: -0.48659862
A161: 2010Q4 | B161: =Levels!B161/(Levels!$R161*1000) -> 23.996036 | C161: =Levels!C161/(Levels!$R161*1000) -> 4306.8391 | D161: =Levels!D161/EXP(Levels!$J161) -> 335925.19 | E161: =Levels!E161/Levels!$Q161 -> 0.18294603 | F161: =Levels!F161/Levels!$Q161 -> 0.67215782 | G161: 2 | H161: -1.0445739 | I161: 1.2714216 | J161: 3.0863683 | K161: -0.35392615 | M161: -2.4165292 | N161: 1.08533 | O161: 0.74815231 | P161: 0.99033145 | Q161: 15807.995 | R161: 1.1490887 | S161: -2.1975647 | T161: -2.6184163
A162: 2011Q1 | B162: =Levels!B162/(Levels!$R162*1000) -> 23.96422 | C162: =Levels!C162/(Levels!$R162*1000) -> 4590.1814 | D162: =Levels!D162/EXP(Levels!$J162) -> 333646.65 | E162: =Levels!E162/Levels!$Q162 -> 0.18231466 | F162: =Levels!F162/Levels!$Q162 -> 0.68019544 | G162: 1.9 | H162: -1.3748058 | I162: 1.7934177 | J162: 3.114827 | K162: -0.33205916 | M162: -3.9249336 | N162: 1.18409 | O162: 0.75664864 | P162: 0.921221 | Q162: 15769.911 | R162: -1.0833278 | S162: 0.34972921 | T162: -1.0523799
A163: 2011Q2 | B163: =Levels!B163/(Levels!$R163*1000) -> 23.93917 | C163: =Levels!C163/(Levels!$R163*1000) -> 4654.34 | D163: =Levels!D163/EXP(Levels!$J163) -> 334718.07 | E163: =Levels!E163/Levels!$Q163 -> 0.18388503 | F163: =Levels!F163/Levels!$Q163 -> 0.6809468 | G163: 2.2 | H163: -1.7628519 | I163: 1.4730155 | J163: 3.1207139 | K163: 0.23406256 | M163: -3.2850058 | N163: 1.50158 | O163: 0.75238606 | P163: 0.93018129 | Q163: 15876.839 | R163: 0.081994043 | S163: 0.39988548 | T163: 2.3896843
A164: 2011Q3 | B164: =Levels!B164/(Levels!$R164*1000) -> 23.943621 | C164: =Levels!C164/(Levels!$R164*1000) -> 5013.792 | D164: =Levels!D164/EXP(Levels!$J164) -> 348669.66 | E164: =Levels!E164/Levels!$Q164 -> 0.18959164 | F164: =Levels!F164/Levels!$Q164 -> 0.68387733 | G164: 2.1 | H164: -1.82447 | I164: 0.60908899 | J164: 3.0750807 | K164: 0.59824903 | M164: -1.1341993 | N164: 1.80809 | O164: 0.7598232 | P164: 1.0446978 | Q164: 15870.684 | R164: 0.6461623 | S164: 2.9440565 | T164: 3.3809634
A165: 2011Q4 | B165: =Levels!B165/(Levels!$R165*1000) -> 24.026773 | C165: =Levels!C165/(Levels!$R165*1000) -> 5341.3055 | D165: =Levels!D165/EXP(Levels!$J165) -> 348677.59 | E165: =Levels!E165/Levels!$Q165 -> 0.19112025 | F165: =Levels!F165/Levels!$Q165 -> 0.67663695 | G165: 2.4 | H165: -2.0284459 | I165: 0.15771512 | J165: 3.0916111 | K165: 0.15617172 | M165: -0.020767631 | N165: 1.84947 | O165: 0.73770689 | P165: 1.0180619 | Q165: 16048.702 | R165: -0.60875249 | S165: 0.32447596 | T165: -4.6667844
A166: 2012Q1 | B166: =Levels!B166/(Levels!$R166*1000) -> 24.068553 | C166: =Levels!C166/(Levels!$R166*1000) -> 5735.451 | D166: =Levels!D166/EXP(Levels!$J166) -> 369777.53 | E166: =Levels!E166/Levels!$Q166 -> 0.19344599 | F166: =Levels!F166/Levels!$Q166 -> 0.67733756 | G166: 3.1 | H166: -1.7991348 | I166: 0.076403333 | J166: 3.1293495 | K166: -0.3479205 | M166: -0.39181073 | N166: 2.0432 | O166: 0.71559723 | P166: 0.91206994 | Q166: 16179.968 | R166: -0.83450165 | S166: 0.10112817 | T166: -0.32687477
A167: 2012Q2 | B167: =Levels!B167/(Levels!$R167*1000) -> 24.13318 | C167: =Levels!C167/(Levels!$R167*1000) -> 5789.2431 | D167: =Levels!D167/EXP(Levels!$J167) -> 374552.94 | E167: =Levels!E167/Levels!$Q167 -> 0.19547629 | F167: =Levels!F167/Levels!$Q167 -> 0.67392733 | G167: 2.2 | H167: -1.6122087 | I167: -0.20694732 | J167: 3.13115 | K167: 0.26124486 | M167: 0.37744621 | N167: 1.86978 | O167: 0.70555585 | P167: 0.88215008 | Q167: 16253.726 | R167: -0.21761944 | S167: -0.17054583 | T167: -0.90206171
