Workbook

Sheet 25_Portfolios_5x5
A1: This file was created by CMPT_ME_BEME_OP_INV_RETS using the 202403 CRSP database.
A2: It contains value- and equal-weighted returns for portfolios formed on ME and BEME.
A4: The portfolios are constructed at the end of June. BEME is book value at the last fiscal year end of the prior calendar year
A5: divided by ME at the end of December of the prior year.
A6: Annual returns are from January to December.
A8: Missing data are indicated by -99.99 or -999.
A10: The break points include utilities and include financials.
A12: The portfolios include utilities and include financials.
A15: Average Value Weighted Returns -- Monthly
B16: SMALL LoBM | C16: ME1 BM2 | D16: ME1 BM3 | E16: ME1 BM4 | F16: SMALL HiBM | G16: ME2 BM1 | H16: ME2 BM2 | I16: ME2 BM3 | J16: ME2 BM4 | K16: ME2 BM5 | L16: ME3 BM1 | M16: ME3 BM2 | N16: ME3 BM3 | O16: ME3 BM4 | P16: ME3 BM5 | Q16: ME4 BM1 | R16: ME4 BM2 | S16: ME4 BM3 | T16: ME4 BM4 | U16: ME4 BM5 | V16: BIG LoBM | W16: ME5 BM2 | X16: ME5 BM3 | Y16: ME5 BM4 | Z16: BIG HiBM
A17: 192607 | B17: 5.8248 | C17: -1.7006 | D17: 0.4875 | E17: -1.458 | F17: 2.0534 | G17: 1.2077 | H17: 2.4192 | I17: 0.4926 | J17: -2.6049 | K17: -0.3344 | L17: 1.9116 | M17: 2.4336 | N17: -0.4347 | O17: 3.7288 | P17: -1.2629 | Q17: 1.5893 | R17: 1.5278 | S17: 1.2978 | T17: 0.2727 | U17: 2.4678 | V17: 3.4539 | W17: 6.0902 | X17: 2.0266 | Y17: 3.1111 | Z17: 0.5623
A18: 192608 | B18: -2.0206 | C18: -8.0282 | D18: 1.3796 | E18: 1.4606 | F18: 8.3968 | G18: 2.3618 | H18: -1.1849 | I18: 4.0084 | J18: 0.5038 | K18: 6.1675 | L18: -0.939 | M18: 2.3886 | N18: 1.9912 | O18: 4.298 | P18: 8.1169 | Q18: 1.3336 | R18: 3.873 | S18: 2.0021 | T18: 2.1706 | U18: 5.3422 | V18: 1.0124 | W18: 4.1903 | X18: 2.0131 | Y18: 5.4849 | Z18: 7.7576
A19: 192609 | B19: -4.8291 | C19: -2.6154 | D19: -4.3417 | E19: -3.2729 | F19: 0.8649 | G19: -2.654 | H19: -1.2618 | I19: 1.0829 | J19: -3.548 | K19: -0.9401 | L19: -0.3898 | M19: 0.169 | N19: -1.9328 | O19: 2.6946 | P19: -3.6215 | Q19: 1.0923 | R19: -0.525 | S19: -1.7636 | T19: 1.4646 | U19: 0.873 | V19: -1.2906 | W19: 3.6538 | X19: 0.095 | Y19: -0.7487 | Z19: -2.4284
A20: 192610 | B20: -9.3729 | C20: -3.5519 | D20: -3.4948 | E20: 3.4413 | F20: -2.5476 | G20: -2.8069 | H20: -3.2663 | I20: -5.0745 | J20: -8.0191 | K20: -1.3213 | L20: -5.1161 | M20: -2.5583 | N20: 0.4293 | O20: -2.1819 | P20: -3.1373 | Q20: -3.3361 | R20: -2.6559 | S20: -2.107 | T20: -3.1051 | U20: -5.3525 | V20: -2.7413 | W20: -3.0071 | X20: -2.2437 | Y20: -4.6719 | Z20: -5.8129
A21: 192611 | B21: 5.5888 | C21: 4.1877 | D21: 2.4623 | E21: -4.4494 | F21: 0.5362 | G21: 3.1033 | H21: -2.369 | I21: 3.0078 | J21: 5.1546 | K21: 2.7292 | L21: 1.9107 | M21: 4.5467 | N21: 0.4771 | O21: 4.943 | P21: 3.7333 | Q21: 3.4448 | R21: 2.3887 | S21: 3.7335 | T21: 4.932 | U21: 1.8213 | V21: 4.2946 | W21: 2.5326 | X21: 1.5204 | Y21: 3.6619 | Z21: 2.5636
A22: 192612 | B22: 14.9644 | C22: -1.3814 | D22: 0.1503 | E22: 3.4171 | F22: 0.8556 | G22: 3.1108 | H22: 4.7507 | I22: 1.2089 | J22: 2.134 | K22: 5.198 | L22: -1.3186 | M22: 2.3963 | N22: -1.0707 | O22: 3.0242 | P22: 1.5349 | Q22: 3.4702 | R22: 2.6069 | S22: 1.7698 | T22: 3.0306 | U22: 0.1578 | V22: 1.4887 | W22: 3.4585 | X22: 1.9777 | Y22: 6.2357 | Z22: 2.4024
A23: 192701 | B23: 1.0943 | C23: -8.1352 | D23: -5.2057 | E23: 3.0498 | F23: 2.0166 | G23: 2.9853 | H23: -4.2365 | I23: -0.064 | J23: -0.3004 | K23: 11.057 | L23: -0.6319 | M23: -0.22 | N23: -0.6412 | O23: 2.3361 | P23: 2.5541 | Q23: 2.3758 | R23: 1.4701 | S23: -0.5134 | T23: 0.2313 | U23: 7.3063 | V23: -0.7756 | W23: 0.3281 | X23: -0.4374 | Y23: 0.5498 | Z23: 4.2141
A24: 192702 | B24: 2.8672 | C24: -0.4922 | D24: 8.9123 | E24: 5.3216 | F24: 10.2076 | G24: 1.5108 | H24: 8.6948 | I24: 7.8557 | J24: 4.0122 | K24: 7.5867 | L24: 6.1214 | M24: 5.5311 | N24: 4.3764 | O24: 6.5566 | P24: 13.2797 | Q24: 5.2914 | R24: 4.2655 | S24: 2.3492 | T24: 6.7788 | U24: 11.4693 | V24: 3.4545 | W24: 5.0906 | X24: 3.4173 | Y24: 5.1264 | Z24: 6.2731
A25: 192703 | B25: 5.8224 | C25: -0.1275 | D25: -5.8769 | E25: -3.901 | F25: -3.5735 | G25: -2.4897 | H25: -0.5186 | I25: -2.0169 | J25: -0.7107 | K25: -0.5481 | L25: 0.5222 | M25: -3.5673 | N25: -0.6866 | O25: -2.0763 | P25: -5.9028 | Q25: -2.2017 | R25: 0.1638 | S25: -1.3431 | T25: -1.3877 | U25: 3.889 | V25: 0.5845 | W25: 1.9822 | X25: -0.1206 | Y25: 0.4765 | Z25: -3.8361
A26: 192704 | B26: 7.8219 | C26: 4.788 | D26: 4.3888 | E26: 3.3905 | F26: 6.4218 | G26: -2.9654 | H26: -5.6544 | I26: -0.2997 | J26: -0.3946 | K26: 4.4712 | L26: -2.2887 | M26: 1.3977 | N26: -0.5106 | O26: 2.2022 | P26: 1.7466 | Q26: -0.2637 | R26: 1.8622 | S26: -1.2139 | T26: 0.0794 | U26: 5.753 | V26: 2.6984 | W26: 0.8929 | X26: -0.2989 | Y26: -0.4236 | Z26: -3.5345
A27: 192705 | B27: 10.2463 | C27: 7.2563 | D27: 2.5823 | E27: 14.6735 | F27: 10.0697 | G27: 7.2964 | H27: 2.5196 | I27: 5.4286 | J27: 8.9854 | K27: 13.453 | L27: 3.0289 | M27: 6.6737 | N27: 6.1437 | O27: 7.1049 | P27: 12.9147 | Q27: 4.8501 | R27: 6.1769 | S27: 3.7701 | T27: 7.1732 | U27: 7.7199 | V27: 5.6929 | W27: 4.6786 | X27: 5.5318 | Y27: 5.4185 | Z27: 4.7762
A28: 192706 | B28: -3.4332 | C28: 10.6227 | D28: -3.0588 | E28: -4.2885 | F28: -4.4903 | G28: 3.2711 | H28: 3.2146 | I28: 4.566 | J28: -0.9188 | K28: -6.3846 | L28: -0.6943 | M28: -3.6414 | N28: -0.7963 | O28: 0.1135 | P28: 1.7373 | Q28: 1.0302 | R28: -3.2201 | S28: -3.6411 | T28: -2.2869 | U28: 1.9683 | V28: -0.0607 | W28: -3.1371 | X28: -2.7494 | Y28: -3.0453 | Z28: -5.3613
... A352: 195406 | B352: -4.2572 | C352: 0.4208 | D352: 0.9297 | E352: 0.8265 | F352: 2.1939 | G352: 1.1903 | H352: -0.6286 | I352: 2.8189 | J352: 1.201 | K352: 2.6078 | L352: 1.6295 | M352: 1.2072 | N352: 2.1208 | O352: 2.2261 | P352: 1.4817 | Q352: 0.8875 | R352: 2.6006 | S352: 2.9755 | T352: 1.7225 | U352: -0.1628 | V352: 3.1816 | W352: -1.1349 | X352: -1.7169 | Y352: 0.9093 | Z352: -0.7484
A353: 195407 | B353: 2.3029 | C353: 7.4812 | D353: 4.0861 | E353: 9.3881 | F353: 14.5988 | G353: 3.5607 | H353: 6.7852 | I353: 7.0835 | J353: 7.1611 | K353: 8.2942 | L353: 5.3204 | M353: 6.8734 | N353: 6.6749 | O353: 6.7767 | P353: 6.9073 | Q353: 5.6761 | R353: 6.6557 | S353: 7.4457 | T353: 5.1106 | U353: 8.5415 | V353: 3.7804 | W353: 4.9967 | X353: 4.8849 | Y353: 7.2455 | Z353: 8.7895 | AA353: 0.05 | AB353: 26.86
A354: 195408 | B354: 2.8606 | C354: -2.4977 | D354: -0.2268 | E354: -0.29 | F354: 0.0918 | G354: -1.8541 | H354: 1.5806 | I354: 1.2451 | J354: 0.7609 | K354: -0.9046 | L354: 0.4118 | M354: -1.7985 | N354: -1.1466 | O354: -1.4608 | P354: -1.4495 | Q354: -1.7835 | R354: -1.2545 | S354: -0.9756 | T354: -0.8716 | U354: -3.1043 | V354: -3.4477 | W354: -1.2138 | X354: -1.4163 | Y354: -4.5527 | Z354: -5.0369 | AA354: 0.05 | AB354: 26.85 | AC354: =((1+B354/100)*$AB353/$AB354-1)*100 -> 2.8989093 | AD354: =((1+C354/100)*$AB353/$AB354-1)*100 -> -2.4613863 | AE354: =((1+D354/100)*$AB353/$AB354-1)*100 -> -0.18964052 | AF354: =((1+E354/100)*$AB353/$AB354-1)*100 -> -0.25286406 | AG354: =((1+F354/100)*$AB353/$AB354-1)*100 -> 0.12907814 | AH354: =((1+G354/100)*$AB353/$AB354-1)*100 -> -1.8175466 | AI354: =((1+H354/100)*$AB353/$AB354-1)*100 -> 1.6184326 | AJ354: =((1+I354/100)*$AB353/$AB354-1)*100 -> 1.2828077 | ... BB354: =((1+AA354/100)*$AB353/$AB354-1)*100 -> 0.08726257
A355: 195409 | B355: 0.2453 | C355: 4.9652 | D355: 2.9753 | E355: 4.6303 | F355: 3.6619 | G355: 4.5933 | H355: 4.0061 | I355: 4.5876 | J355: 4.5519 | K355: 4.8799 | L355: 1.4282 | M355: 2.7286 | N355: 6.4282 | O355: 4.6483 | P355: 4.5681 | Q355: 4.0323 | R355: 4.6277 | S355: 6.6278 | T355: 6.1802 | U355: 4.109 | V355: 7.4894 | W355: 6.1434 | X355: 9.3895 | Y355: 7.2195 | Z355: 3.4924 | AA355: 0.09 | AB355: 26.81 | AC355: =((1+B355/100)*$AB354/$AB355-1)*100 -> 0.39486404 | AD355: =((1+C355/100)*$AB354/$AB355-1)*100 -> 5.121806 | AE355: =((1+D355/100)*$AB354/$AB355-1)*100 -> 3.1289372 | AF355: =((1+E355/100)*$AB354/$AB355-1)*100 -> 4.7864064 | AG355: =((1+F355/100)*$AB354/$AB355-1)*100 -> 3.8165615 | AH355: =((1+G355/100)*$AB354/$AB355-1)*100 -> 4.7493512 | AI355: =((1+H355/100)*$AB354/$AB355-1)*100 -> 4.1612751 | AJ355: =((1+I355/100)*$AB354/$AB355-1)*100 -> 4.7436427 | ... BB355: =((1+AA355/100)*$AB354/$AB355-1)*100 -> 0.23933234
A356: 195410 | B356: -1.709 | C356: -2.8333 | D356: -0.0752 | E356: 0.0276 | F356: 0.5043 | G356: -3.6842 | H356: -0.2498 | I356: -0.0805 | J356: -0.3593 | K356: -2.949 | L356: 2.095 | M356: -0.221 | N356: -0.574 | O356: -0.6639 | P356: -1.6901 | Q356: -1.1377 | R356: -1.1628 | S356: 1.538 | T356: -1.4541 | U356: 1.321 | V356: -2.4196 | W356: -1.6617 | X356: -1.9172 | Y356: 0.2787 | Z356: 0.4665 | AA356: 0.07 | AB356: 26.72 | AC356: =((1+B356/100)*$AB355/$AB356-1)*100 -> -1.37793 | AD356: =((1+C356/100)*$AB355/$AB356-1)*100 -> -2.506017 | AE356: =((1+D356/100)*$AB355/$AB356-1)*100 -> 0.26137305 | AF356: =((1+E356/100)*$AB355/$AB356-1)*100 -> 0.36451931 | AG356: =((1+F356/100)*$AB355/$AB356-1)*100 -> 0.84282496 | AH356: =((1+G356/100)*$AB355/$AB356-1)*100 -> -3.359783 | AI356: =((1+H356/100)*$AB355/$AB356-1)*100 -> 0.086184955 | AJ356: =((1+I356/100)*$AB355/$AB356-1)*100 -> 0.2560552 | ... BB356: =((1+AA356/100)*$AB355/$AB356-1)*100 -> 0.40706213
A357: 195411 | B357: 3.8145 | C357: 9.8668 | D357: 8.9207 | E357: 7.7012 | F357: 7.4968 | G357: 9.1866 | H357: 5.3027 | I357: 7.4082 | J357: 10.31 | K357: 9.212 | L357: 7.653 | M357: 9.2762 | N357: 9.2562 | O357: 13.7976 | P357: 9.7288 | Q357: 7.1987 | R357: 9.4869 | S357: 12.1489 | T357: 12.0591 | U357: 13.3463 | V357: 10.3379 | W357: 7.1797 | X357: 8.6736 | Y357: 13.5541 | Z357: 15.5168 | AA357: 0.06 | AB357: 26.78 | AC357: =((1+B357/100)*$AB356/$AB357-1)*100 -> 3.5819059 | AD357: =((1+C357/100)*$AB356/$AB357-1)*100 -> 9.6206459 | AE357: =((1+D357/100)*$AB356/$AB357-1)*100 -> 8.6766656 | AF357: =((1+E357/100)*$AB356/$AB357-1)*100 -> 7.4598978 | AG357: =((1+F357/100)*$AB356/$AB357-1)*100 -> 7.2559558 | AH357: =((1+G357/100)*$AB356/$AB357-1)*100 -> 8.9419698 | AI357: =((1+H357/100)*$AB356/$AB357-1)*100 -> 5.0667716 | AJ357: =((1+I357/100)*$AB356/$AB357-1)*100 -> 7.1675543 | ... BB357: =((1+AA357/100)*$AB356/$AB357-1)*100 -> -0.16418223
A358: 195412 | B358: 13.723 | C358: 10.024 | D358: 8.3487 | E358: 12.8254 | F358: 12.7618 | G358: 7.7347 | H358: 10.9942 | I358: 9.6084 | J358: 8.567 | K358: 11.2543 | L358: 4.3568 | M358: 7.2021 | N358: 7.9514 | O358: 10.514 | P358: 13.391 | Q358: 4.5234 | R358: 4.4476 | S358: 5.3487 | T358: 8.6519 | U358: 14.1489 | V358: 3.9345 | W358: 4.3946 | X358: 7.9701 | Y358: 9.6953 | Z358: 15.5735 | AA358: 0.08 | AB358: 26.77 | AC358: =((1+B358/100)*$AB357/$AB358-1)*100 -> 13.765482 | AD358: =((1+C358/100)*$AB357/$AB358-1)*100 -> 10.0651 | AE358: =((1+D358/100)*$AB357/$AB358-1)*100 -> 8.3891739 | AF358: =((1+E358/100)*$AB357/$AB358-1)*100 -> 12.867546 | AG358: =((1+F358/100)*$AB357/$AB358-1)*100 -> 12.803922 | AH358: =((1+G358/100)*$AB357/$AB358-1)*100 -> 7.7749446 | AI358: =((1+H358/100)*$AB357/$AB358-1)*100 -> 11.035662 | AJ358: =((1+I358/100)*$AB357/$AB358-1)*100 -> 9.6493445 | ... BB358: =((1+AA358/100)*$AB357/$AB358-1)*100 -> 0.11738513
A359: 195501 | B359: -4.9754 | C359: 4.6488 | D359: 2.4768 | E359: 3.8723 | F359: 4.6834 | G359: -2.4464 | H359: 1.5758 | I359: 0.9075 | J359: 1.3162 | K359: 1.7378 | L359: 3.0539 | M359: 1.3808 | N359: 3.6262 | O359: 2.0023 | P359: 2.1593 | Q359: -0.1188 | R359: 1.5232 | S359: 1.0808 | T359: 0.159 | U359: 0.3713 | V359: -0.1705 | W359: 1.5231 | X359: -1.5318 | Y359: 2.8155 | Z359: 1.8377 | AA359: 0.08 | AB359: 26.77 | AC359: =((1+B359/100)*$AB358/$AB359-1)*100 -> -4.9754 | AD359: =((1+C359/100)*$AB358/$AB359-1)*100 -> 4.6488 | AE359: =((1+D359/100)*$AB358/$AB359-1)*100 -> 2.4768 | AF359: =((1+E359/100)*$AB358/$AB359-1)*100 -> 3.8723 | AG359: =((1+F359/100)*$AB358/$AB359-1)*100 -> 4.6834 | AH359: =((1+G359/100)*$AB358/$AB359-1)*100 -> -2.4464 | AI359: =((1+H359/100)*$AB358/$AB359-1)*100 -> 1.5758 | AJ359: =((1+I359/100)*$AB358/$AB359-1)*100 -> 0.9075 | ... BB359: =((1+AA359/100)*$AB358/$AB359-1)*100 -> 0.08
A360: 195502 | B360: 2.415 | C360: 9.1504 | D360: 5.0501 | E360: 5.6338 | F360: 5.8932 | G360: 3.395 | H360: 3.9965 | I360: 3.6339 | J360: 3.5969 | K360: 4.9792 | L360: 5.3374 | M360: 5.103 | N360: 5.0023 | O360: 5.4004 | P360: 4.8486 | Q360: 3.5235 | R360: 3.757 | S360: 4.2454 | T360: 4.0042 | U360: 3.2239 | V360: 2.8857 | W360: 2.5139 | X360: 2.8822 | Y360: 2.4677 | Z360: 5.1598 | AA360: 0.09 | AB360: 26.82 | AC360: =((1+B360/100)*$AB359/$AB360-1)*100 -> 2.2240697 | AD360: =((1+C360/100)*$AB359/$AB360-1)*100 -> 8.946913 | AE360: =((1+D360/100)*$AB359/$AB360-1)*100 -> 4.8542572 | AF360: =((1+E360/100)*$AB359/$AB360-1)*100 -> 5.436869 | AG360: =((1+F360/100)*$AB359/$AB360-1)*100 -> 5.6957854 | AH360: =((1+G360/100)*$AB359/$AB360-1)*100 -> 3.2022427 | AI360: =((1+H360/100)*$AB359/$AB360-1)*100 -> 3.8026214 | AJ360: =((1+I360/100)*$AB359/$AB360-1)*100 -> 3.4406974 | ... BB360: =((1+AA360/100)*$AB359/$AB360-1)*100 -> -0.096595824
A361: 195503 | B361: -1.7029 | C361: -0.9848 | D361: -0.2855 | E361: -0.9498 | F361: -0.3482 | G361: -0.333 | H361: 0.1087 | I361: -0.777 | J361: 0.2299 | K361: 2.0357 | L361: -2.9516 | M361: -1.2571 | N361: -0.5001 | O361: 3.4631 | P361: 2.5037 | Q361: -0.3456 | R361: -0.6846 | S361: -1.7701 | T361: -1.5475 | U361: 1.6718 | V361: -0.0587 | W361: -0.4471 | X361: 0.1453 | Y361: 1.503 | Z361: 0.6816 | AA361: 0.1 | AB361: 26.79 | AC361: =((1+B361/100)*$AB360/$AB361-1)*100 -> -1.5928249 | AD361: =((1+C361/100)*$AB360/$AB361-1)*100 -> -0.87392072 | AE361: =((1+D361/100)*$AB360/$AB361-1)*100 -> -0.17383763 | AF361: =((1+E361/100)*$AB360/$AB361-1)*100 -> -0.83888152 | AG361: =((1+F361/100)*$AB360/$AB361-1)*100 -> -0.23660784 | AH361: =((1+G361/100)*$AB360/$AB361-1)*100 -> -0.22139082 | AI361: =((1+H361/100)*$AB360/$AB361-1)*100 -> 0.22080381 | AJ361: =((1+I361/100)*$AB360/$AB361-1)*100 -> -0.66588802 | ... BB361: =((1+AA361/100)*$AB360/$AB361-1)*100 -> 0.21209406
A362: 195504 | B362: 5.1572 | C362: -1.2958 | D362: 2.5717 | E362: 2.7817 | F362: 1.2704 | G362: 0.6716 | H362: 1.4733 | I362: 1.4646 | J362: 2.5452 | K362: 2.9014 | L362: 2.9745 | M362: 3.2446 | N362: 2.2302 | O362: 0.9952 | P362: 0.9696 | Q362: 3.7281 | R362: 1.7002 | S362: 2.6482 | T362: 1.1383 | U362: 1.1067 | V362: 4.6945 | W362: 1.8924 | X362: 2.1702 | Y362: 5.5401 | Z362: 4.6863 | AA362: 0.1 | AB362: 26.79 | AC362: =((1+B362/100)*$AB361/$AB362-1)*100 -> 5.1572 | AD362: =((1+C362/100)*$AB361/$AB362-1)*100 -> -1.2958 | AE362: =((1+D362/100)*$AB361/$AB362-1)*100 -> 2.5717 | AF362: =((1+E362/100)*$AB361/$AB362-1)*100 -> 2.7817 | AG362: =((1+F362/100)*$AB361/$AB362-1)*100 -> 1.2704 | AH362: =((1+G362/100)*$AB361/$AB362-1)*100 -> 0.6716 | AI362: =((1+H362/100)*$AB361/$AB362-1)*100 -> 1.4733 | AJ362: =((1+I362/100)*$AB361/$AB362-1)*100 -> 1.4646 | ... BB362: =((1+AA362/100)*$AB361/$AB362-1)*100 -> 0.1
A363: 195505 | B363: -1.2429 | C363: 1.3889 | D363: -0.2499 | E363: 1.0599 | F363: 0.7989 | G363: -1.1491 | H363: 2.0955 | I363: -0.2235 | J363: -0.6887 | K363: 0.4978 | L363: 1.2547 | M363: -0.2754 | N363: 0.8788 | O363: 0.6916 | P363: 0.6143 | Q363: 1.2371 | R363: 1.6557 | S363: 0.6807 | T363: 2.4783 | U363: 0.3284 | V363: 2.4802 | W363: -0.1137 | X363: 0.4777 | Y363: -0.8562 | Z363: 1.4179 | AA363: 0.14 | AB363: 26.77 | AC363: =((1+B363/100)*$AB362/$AB363-1)*100 -> -1.1691181 | AD363: =((1+C363/100)*$AB362/$AB363-1)*100 -> 1.4646482 | AE363: =((1+D363/100)*$AB362/$AB363-1)*100 -> -0.1753762 | AF363: =((1+E363/100)*$AB362/$AB363-1)*100 -> 1.1354024 | AG363: =((1+F363/100)*$AB362/$AB363-1)*100 -> 0.87420736 | AH363: =((1+G363/100)*$AB362/$AB363-1)*100 -> -1.075248 | AI363: =((1+H363/100)*$AB362/$AB363-1)*100 -> 2.1717761 | AJ363: =((1+I363/100)*$AB362/$AB363-1)*100 -> -0.14895648 | ... BB363: =((1+AA363/100)*$AB362/$AB363-1)*100 -> 0.21481509
A364: 195506 | B364: 5.4825 | C364: 3.692 | D364: 1.8135 | E364: 4.8018 | F364: 4.4007 | G364: 1.9272 | H364: 1.379 | I364: 3.4026 | J364: 4.0573 | K364: 2.1487 | L364: 2.8794 | M364: 1.3333 | N364: 3.1726 | O364: 4.0574 | P364: 1.4266 | Q364: 3.409 | R364: 7.1208 | S364: 5.5131 | T364: 5.5784 | U364: 0.8677 | V364: 7.4772 | W364: 5.8049 | X364: 11.1086 | Y364: 11.6495 | Z364: 5.0158 | AA364: 0.1 | AB364: 26.71 | AC364: =((1+B364/100)*$AB363/$AB364-1)*100 -> 5.7194506 | AD364: =((1+C364/100)*$AB363/$AB364-1)*100 -> 3.9249285 | AE364: =((1+D364/100)*$AB363/$AB364-1)*100 -> 2.0422087 | AF364: =((1+E364/100)*$AB363/$AB364-1)*100 -> 5.0372215 | AG364: =((1+F364/100)*$AB363/$AB364-1)*100 -> 4.6352205 | AH364: =((1+G364/100)*$AB363/$AB364-1)*100 -> 2.1561641 | AI364: =((1+H364/100)*$AB363/$AB364-1)*100 -> 1.6067327 | AJ364: =((1+I364/100)*$AB363/$AB364-1)*100 -> 3.6348784 | ... BB364: =((1+AA364/100)*$AB363/$AB364-1)*100 -> 0.3248596
A365: 195507 | B365: 9.3525 | C365: 3.324 | D365: 0.3889 | E365: 1.8187 | F365: 0.5586 | G365: -4.3425 | H365: 0.3758 | I365: 1.8715 | J365: 1.0719 | K365: 2.0628 | L365: 0.7446 | M365: -0.1029 | N365: -0.5811 | O365: 0.5 | P365: 1.0013 | Q365: -0.3096 | R365: 0.5765 | S365: 0.1652 | T365: 0.5393 | U365: 1.5842 | V365: 2.353 | W365: 4.2972 | X365: 1.6411 | Y365: -0.5928 | Z365: 0.2073 | AA365: 0.1 | AB365: 26.76 | AC365: =((1+B365/100)*$AB364/$AB365-1)*100 -> 9.1481792 | AD365: =((1+C365/100)*$AB364/$AB365-1)*100 -> 3.1309432 | AE365: =((1+D365/100)*$AB364/$AB365-1)*100 -> 0.20132732 | AF365: =((1+E365/100)*$AB364/$AB365-1)*100 -> 1.6284558 | AG365: =((1+F365/100)*$AB364/$AB365-1)*100 -> 0.37071024 | AH365: =((1+G365/100)*$AB364/$AB365-1)*100 -> -4.5212322 | AI365: =((1+H365/100)*$AB364/$AB365-1)*100 -> 0.18825179 | AJ365: =((1+I365/100)*$AB364/$AB365-1)*100 -> 1.6811571 | ... BB365: =((1+AA365/100)*$AB364/$AB365-1)*100 -> -0.087032885
... A1186: 202312 | B1186: 15.2866 | C1186: 16.045 | D1186: 14.8609 | E1186: 16.4605 | F1186: 14.9009 | G1186: 12.0839 | H1186: 14.3359 | I1186: 11.2742 | J1186: 13.4411 | K1186: 15.8698 | L1186: 10.3294 | M1186: 10.8237 | N1186: 10.0157 | O1186: 12.148 | P1186: 17.0064 | Q1186: 8.6568 | R1186: 7.7652 | S1186: 9.1821 | T1186: 9.0094 | U1186: 11.721 | V1186: 3.7289 | W1186: 4.7129 | X1186: 5.0839 | Y1186: 4.6592 | Z1186: 11.6076 | AA1186: 0.43 | AB1186: 308.742 | AC1186: =((1+B1186/100)*$AB1185/$AB1186-1)*100 -> 15.018493 | AD1186: =((1+C1186/100)*$AB1185/$AB1186-1)*100 -> 15.77513 | AE1186: =((1+D1186/100)*$AB1185/$AB1186-1)*100 -> 14.593783 | AF1186: =((1+E1186/100)*$AB1185/$AB1186-1)*100 -> 16.189663 | AG1186: =((1+F1186/100)*$AB1185/$AB1186-1)*100 -> 14.63369 | AH1186: =((1+G1186/100)*$AB1185/$AB1186-1)*100 -> 11.823241 | AI1186: =((1+H1186/100)*$AB1185/$AB1186-1)*100 -> 14.070004 | AJ1186: =((1+I1186/100)*$AB1185/$AB1186-1)*100 -> 11.015424 | ... BB1186: =((1+AA1186/100)*$AB1185/$AB1186-1)*100 -> 0.19644337
A1187: 202401 | B1187: 0.3757 | C1187: -3.4981 | D1187: -3.7392 | E1187: -3.8721 | F1187: -3.7289 | G1187: -4.0827 | H1187: -3.9013 | I1187: -3.5272 | J1187: -5.1955 | K1187: -5.8009 | L1187: -4.0232 | M1187: -3.2443 | N1187: -3.8813 | O1187: -3.4572 | P1187: -5.3356 | Q1187: -1.6845 | R1187: 0.0094 | S1187: -1.5281 | T1187: -3.28 | U1187: -2.4467 | V1187: 2.2795 | W1187: -0.5613 | X1187: 3.5883 | Y1187: 2.663 | Z1187: -0.8891 | AJ1187: =((1+I1187/100)*$AB1186/$AB1187-1)*100 -> #DIV/0! | AK1187: =((1+J1187/100)*$AB1186/$AB1187-1)*100 -> #DIV/0! | AL1187: =((1+K1187/100)*$AB1186/$AB1187-1)*100 -> #DIV/0! | AM1187: =((1+L1187/100)*$AB1186/$AB1187-1)*100 -> #DIV/0! | AN1187: =((1+M1187/100)*$AB1186/$AB1187-1)*100 -> #DIV/0! | AO1187: =((1+N1187/100)*$AB1186/$AB1187-1)*100 -> #DIV/0! | AP1187: =((1+O1187/100)*$AB1186/$AB1187-1)*100 -> #DIV/0! | AQ1187: =((1+P1187/100)*$AB1186/$AB1187-1)*100 -> #DIV/0! | ... BB1187: =((1+AA1187/100)*$AB1186/$AB1187-1)*100 -> #DIV/0!
A1188: 202402 | B1188: 9.7215 | C1188: 6.8837 | D1188: 11.7568 | E1188: 2.604 | F1188: 4.2906 | G1188: 9.535 | H1188: 6.5273 | I1188: 7.2667 | J1188: 4.2637 | K1188: 0.9755 | L1188: 3.1544 | M1188: 5.5244 | N1188: 5.4394 | O1188: 1.5432 | P1188: 1.2659 | Q1188: 7.1411 | R1188: 8.095 | S1188: 3.3699 | T1188: 4.6102 | U1188: 2.5429 | V1188: 6.066 | W1188: 1.6357 | X1188: 8.0426 | Y1188: 4.9935 | Z1188: 2.9089 | AJ1188: =((1+I1188/100)*$AB1187/$AB1188-1)*100 -> #DIV/0! | AK1188: =((1+J1188/100)*$AB1187/$AB1188-1)*100 -> #DIV/0! | AL1188: =((1+K1188/100)*$AB1187/$AB1188-1)*100 -> #DIV/0! | AM1188: =((1+L1188/100)*$AB1187/$AB1188-1)*100 -> #DIV/0! | AN1188: =((1+M1188/100)*$AB1187/$AB1188-1)*100 -> #DIV/0! | AO1188: =((1+N1188/100)*$AB1187/$AB1188-1)*100 -> #DIV/0! | AP1188: =((1+O1188/100)*$AB1187/$AB1188-1)*100 -> #DIV/0! | AQ1188: =((1+P1188/100)*$AB1187/$AB1188-1)*100 -> #DIV/0! | ... BB1188: =((1+AA1188/100)*$AB1187/$AB1188-1)*100 -> #DIV/0!
A1189: 202403 | B1189: -3.2046 | C1189: 1.6789 | D1189: 0.7347 | E1189: 1.7423 | F1189: 4.6914 | G1189: 0.3121 | H1189: 2.321 | I1189: 2.6231 | J1189: 2.8249 | K1189: 4.232 | L1189: 0.686 | M1189: 2.8369 | N1189: 4.7016 | O1189: 4.6674 | P1189: 6.6387 | Q1189: 3.8431 | R1189: 4.7731 | S1189: 5.0935 | T1189: 8.0963 | U1189: 7.6653 | V1189: 1.6689 | W1189: 6.3211 | X1189: 3.6084 | Y1189: 6.1407 | Z1189: 8.9863 | AJ1189: =((1+I1189/100)*$AB1188/$AB1189-1)*100 -> #DIV/0! | AK1189: =((1+J1189/100)*$AB1188/$AB1189-1)*100 -> #DIV/0! | AL1189: =((1+K1189/100)*$AB1188/$AB1189-1)*100 -> #DIV/0! | AM1189: =((1+L1189/100)*$AB1188/$AB1189-1)*100 -> #DIV/0! | AN1189: =((1+M1189/100)*$AB1188/$AB1189-1)*100 -> #DIV/0! | AO1189: =((1+N1189/100)*$AB1188/$AB1189-1)*100 -> #DIV/0! | AP1189: =((1+O1189/100)*$AB1188/$AB1189-1)*100 -> #DIV/0! | AQ1189: =((1+P1189/100)*$AB1188/$AB1189-1)*100 -> #DIV/0! | ... BB1189: =((1+AA1189/100)*$AB1188/$AB1189-1)*100 -> #DIV/0!
...

Sheet 10years_f
A1: date | B1: SMALL LoBM | C1: ME1 BM2 | D1: ME1 BM3 | E1: ME1 BM4 | F1: SMALL HiBM | G1: ME2 BM1 | H1: ME2 BM2 | I1: ME2 BM3 | J1: ME2 BM4 | K1: ME2 BM5 | L1: ME3 BM1 | M1: ME3 BM2 | N1: ME3 BM3 | O1: ME3 BM4 | P1: ME3 BM5 | Q1: ME4 BM1 | R1: ME4 BM2 | S1: ME4 BM3 | T1: ME4 BM4 | U1: ME4 BM5 | V1: BIG LoBM | W1: ME5 BM2 | X1: ME5 BM3 | Y1: ME5 BM4 | Z1: BIG HiBM | AA1: rf
A2: ='[1]6_Portfolios_2x3'!A539 -> 197001 | B2: {=(PRODUCT(1+'25_Portfolios_5x5'!AC539:AC659/100)^(1/120)-1)*100} -> -0.2079456 | C2: {=(PRODUCT(1+'25_Portfolios_5x5'!AD539:AD659/100)^(1/120)-1)*100} -> 0.13049723 | D2: {=(PRODUCT(1+'25_Portfolios_5x5'!AE539:AE659/100)^(1/120)-1)*100} -> 0.16569778 | E2: {=(PRODUCT(1+'25_Portfolios_5x5'!AF539:AF659/100)^(1/120)-1)*100} -> 0.4715901 | F2: {=(PRODUCT(1+'25_Portfolios_5x5'!AG539:AG659/100)^(1/120)-1)*100} -> 0.70405914 | G2: {=(PRODUCT(1+'25_Portfolios_5x5'!AH539:AH659/100)^(1/120)-1)*100} -> -0.18846731 | H2: {=(PRODUCT(1+'25_Portfolios_5x5'!AI539:AI659/100)^(1/120)-1)*100} -> 0.041074186 | I2: {=(PRODUCT(1+'25_Portfolios_5x5'!AJ539:AJ659/100)^(1/120)-1)*100} -> 0.21246953 | ... AA2: {=(PRODUCT(1+'25_Portfolios_5x5'!BB539:BB659/100)^(1/120)-1)*100} -> -0.089205539
A3: ='[1]6_Portfolios_2x3'!A540 -> 197002 | B3: {=(PRODUCT(1+'25_Portfolios_5x5'!AC540:AC660/100)^(1/120)-1)*100} -> -0.16755457 | C3: {=(PRODUCT(1+'25_Portfolios_5x5'!AD540:AD660/100)^(1/120)-1)*100} -> 0.14955854 | D3: {=(PRODUCT(1+'25_Portfolios_5x5'!AE540:AE660/100)^(1/120)-1)*100} -> 0.17618826 | E3: {=(PRODUCT(1+'25_Portfolios_5x5'!AF540:AF660/100)^(1/120)-1)*100} -> 0.47008497 | F3: {=(PRODUCT(1+'25_Portfolios_5x5'!AG540:AG660/100)^(1/120)-1)*100} -> 0.67880992 | G3: {=(PRODUCT(1+'25_Portfolios_5x5'!AH540:AH660/100)^(1/120)-1)*100} -> -0.14558156 | H3: {=(PRODUCT(1+'25_Portfolios_5x5'!AI540:AI660/100)^(1/120)-1)*100} -> 0.09098189 | I3: {=(PRODUCT(1+'25_Portfolios_5x5'!AJ540:AJ660/100)^(1/120)-1)*100} -> 0.19859251 | ... AA3: {=(PRODUCT(1+'25_Portfolios_5x5'!BB540:BB660/100)^(1/120)-1)*100} -> -0.093009945
A4: ='[1]6_Portfolios_2x3'!A541 -> 197003 | B4: {=(PRODUCT(1+'25_Portfolios_5x5'!AC541:AC661/100)^(1/120)-1)*100} -> -0.39948062 | C4: {=(PRODUCT(1+'25_Portfolios_5x5'!AD541:AD661/100)^(1/120)-1)*100} -> -0.067072379 | D4: {=(PRODUCT(1+'25_Portfolios_5x5'!AE541:AE661/100)^(1/120)-1)*100} -> -0.027270629 | E4: {=(PRODUCT(1+'25_Portfolios_5x5'!AF541:AF661/100)^(1/120)-1)*100} -> 0.29432141 | F4: {=(PRODUCT(1+'25_Portfolios_5x5'!AG541:AG661/100)^(1/120)-1)*100} -> 0.47396449 | G4: {=(PRODUCT(1+'25_Portfolios_5x5'!AH541:AH661/100)^(1/120)-1)*100} -> -0.35082696 | H4: {=(PRODUCT(1+'25_Portfolios_5x5'!AI541:AI661/100)^(1/120)-1)*100} -> -0.087413258 | I4: {=(PRODUCT(1+'25_Portfolios_5x5'!AJ541:AJ661/100)^(1/120)-1)*100} -> 0.015587524 | ... AA4: {=(PRODUCT(1+'25_Portfolios_5x5'!BB541:BB661/100)^(1/120)-1)*100} -> -0.095273072
A5: ='[1]6_Portfolios_2x3'!A542 -> 197004 | B5: {=(PRODUCT(1+'25_Portfolios_5x5'!AC542:AC662/100)^(1/120)-1)*100} -> -0.29598677 | C5: {=(PRODUCT(1+'25_Portfolios_5x5'!AD542:AD662/100)^(1/120)-1)*100} -> 0.024450374 | D5: {=(PRODUCT(1+'25_Portfolios_5x5'!AE542:AE662/100)^(1/120)-1)*100} -> 0.049783532 | E5: {=(PRODUCT(1+'25_Portfolios_5x5'!AF542:AF662/100)^(1/120)-1)*100} -> 0.32636224 | F5: {=(PRODUCT(1+'25_Portfolios_5x5'!AG542:AG662/100)^(1/120)-1)*100} -> 0.53068704 | G5: {=(PRODUCT(1+'25_Portfolios_5x5'!AH542:AH662/100)^(1/120)-1)*100} -> -0.25086174 | H5: {=(PRODUCT(1+'25_Portfolios_5x5'!AI542:AI662/100)^(1/120)-1)*100} -> -0.036146427 | I5: {=(PRODUCT(1+'25_Portfolios_5x5'!AJ542:AJ662/100)^(1/120)-1)*100} -> 0.066028609 | ... AA5: {=(PRODUCT(1+'25_Portfolios_5x5'!BB542:BB662/100)^(1/120)-1)*100} -> -0.093495494
A6: ='[1]6_Portfolios_2x3'!A543 -> 197005 | B6: {=(PRODUCT(1+'25_Portfolios_5x5'!AC543:AC663/100)^(1/120)-1)*100} -> -0.014878173 | C6: {=(PRODUCT(1+'25_Portfolios_5x5'!AD543:AD663/100)^(1/120)-1)*100} -> 0.25080261 | D6: {=(PRODUCT(1+'25_Portfolios_5x5'!AE543:AE663/100)^(1/120)-1)*100} -> 0.23879181 | E6: {=(PRODUCT(1+'25_Portfolios_5x5'!AF543:AF663/100)^(1/120)-1)*100} -> 0.49316975 | F6: {=(PRODUCT(1+'25_Portfolios_5x5'!AG543:AG663/100)^(1/120)-1)*100} -> 0.69633889 | G6: {=(PRODUCT(1+'25_Portfolios_5x5'!AH543:AH663/100)^(1/120)-1)*100} -> 0.031484511 | H6: {=(PRODUCT(1+'25_Portfolios_5x5'!AI543:AI663/100)^(1/120)-1)*100} -> 0.19670717 | I6: {=(PRODUCT(1+'25_Portfolios_5x5'!AJ543:AJ663/100)^(1/120)-1)*100} -> 0.25287198 | ... AA6: {=(PRODUCT(1+'25_Portfolios_5x5'!BB543:BB663/100)^(1/120)-1)*100} -> -0.094787613
A7: ='[1]6_Portfolios_2x3'!A544 -> 197006 | B7: {=(PRODUCT(1+'25_Portfolios_5x5'!AC544:AC664/100)^(1/120)-1)*100} -> 0.10901446 | C7: {=(PRODUCT(1+'25_Portfolios_5x5'!AD544:AD664/100)^(1/120)-1)*100} -> 0.36583494 | D7: {=(PRODUCT(1+'25_Portfolios_5x5'!AE544:AE664/100)^(1/120)-1)*100} -> 0.33926603 | E7: {=(PRODUCT(1+'25_Portfolios_5x5'!AF544:AF664/100)^(1/120)-1)*100} -> 0.59097638 | F7: {=(PRODUCT(1+'25_Portfolios_5x5'!AG544:AG664/100)^(1/120)-1)*100} -> 0.82690189 | G7: {=(PRODUCT(1+'25_Portfolios_5x5'!AH544:AH664/100)^(1/120)-1)*100} -> 0.17569782 | H7: {=(PRODUCT(1+'25_Portfolios_5x5'!AI544:AI664/100)^(1/120)-1)*100} -> 0.32323595 | I7: {=(PRODUCT(1+'25_Portfolios_5x5'!AJ544:AJ664/100)^(1/120)-1)*100} -> 0.37928611 | ... AA7: {=(PRODUCT(1+'25_Portfolios_5x5'!BB544:BB664/100)^(1/120)-1)*100} -> -0.10007811
A8: ='[1]6_Portfolios_2x3'!A545 -> 197007 | B8: {=(PRODUCT(1+'25_Portfolios_5x5'!AC545:AC665/100)^(1/120)-1)*100} -> 0.3179619 | C8: {=(PRODUCT(1+'25_Portfolios_5x5'!AD545:AD665/100)^(1/120)-1)*100} -> 0.53990343 | D8: {=(PRODUCT(1+'25_Portfolios_5x5'!AE545:AE665/100)^(1/120)-1)*100} -> 0.49061845 | E8: {=(PRODUCT(1+'25_Portfolios_5x5'!AF545:AF665/100)^(1/120)-1)*100} -> 0.73141644 | F8: {=(PRODUCT(1+'25_Portfolios_5x5'!AG545:AG665/100)^(1/120)-1)*100} -> 0.95351918 | G8: {=(PRODUCT(1+'25_Portfolios_5x5'!AH545:AH665/100)^(1/120)-1)*100} -> 0.37909845 | H8: {=(PRODUCT(1+'25_Portfolios_5x5'!AI545:AI665/100)^(1/120)-1)*100} -> 0.48661345 | I8: {=(PRODUCT(1+'25_Portfolios_5x5'!AJ545:AJ665/100)^(1/120)-1)*100} -> 0.53232621 | ... AA8: {=(PRODUCT(1+'25_Portfolios_5x5'!BB545:BB665/100)^(1/120)-1)*100} -> -0.097198169
A9: ='[1]6_Portfolios_2x3'!A546 -> 197008 | B9: {=(PRODUCT(1+'25_Portfolios_5x5'!AC546:AC666/100)^(1/120)-1)*100} -> 0.36720128 | C9: {=(PRODUCT(1+'25_Portfolios_5x5'!AD546:AD666/100)^(1/120)-1)*100} -> 0.56435969 | D9: {=(PRODUCT(1+'25_Portfolios_5x5'!AE546:AE666/100)^(1/120)-1)*100} -> 0.49574904 | E9: {=(PRODUCT(1+'25_Portfolios_5x5'!AF546:AF666/100)^(1/120)-1)*100} -> 0.73243036 | F9: {=(PRODUCT(1+'25_Portfolios_5x5'!AG546:AG666/100)^(1/120)-1)*100} -> 0.95973362 | G9: {=(PRODUCT(1+'25_Portfolios_5x5'!AH546:AH666/100)^(1/120)-1)*100} -> 0.38762781 | H9: {=(PRODUCT(1+'25_Portfolios_5x5'!AI546:AI666/100)^(1/120)-1)*100} -> 0.4785255 | I9: {=(PRODUCT(1+'25_Portfolios_5x5'!AJ546:AJ666/100)^(1/120)-1)*100} -> 0.51196948 | ... AA9: {=(PRODUCT(1+'25_Portfolios_5x5'!BB546:BB666/100)^(1/120)-1)*100} -> -0.10008747
A10: ='[1]6_Portfolios_2x3'!A547 -> 197009 | B10: {=(PRODUCT(1+'25_Portfolios_5x5'!AC547:AC667/100)^(1/120)-1)*100} -> 0.37499255 | C10: {=(PRODUCT(1+'25_Portfolios_5x5'!AD547:AD667/100)^(1/120)-1)*100} -> 0.52967088 | D10: {=(PRODUCT(1+'25_Portfolios_5x5'!AE547:AE667/100)^(1/120)-1)*100} -> 0.45755055 | E10: {=(PRODUCT(1+'25_Portfolios_5x5'!AF547:AF667/100)^(1/120)-1)*100} -> 0.68340893 | F10: {=(PRODUCT(1+'25_Portfolios_5x5'!AG547:AG667/100)^(1/120)-1)*100} -> 0.92784368 | G10: {=(PRODUCT(1+'25_Portfolios_5x5'!AH547:AH667/100)^(1/120)-1)*100} -> 0.34540443 | H10: {=(PRODUCT(1+'25_Portfolios_5x5'!AI547:AI667/100)^(1/120)-1)*100} -> 0.4373417 | I10: {=(PRODUCT(1+'25_Portfolios_5x5'!AJ547:AJ667/100)^(1/120)-1)*100} -> 0.47767935 | ... AA10: {=(PRODUCT(1+'25_Portfolios_5x5'!BB547:BB667/100)^(1/120)-1)*100} -> -0.10310512
A11: ='[1]6_Portfolios_2x3'!A548 -> 197010 | B11: {=(PRODUCT(1+'25_Portfolios_5x5'!AC548:AC668/100)^(1/120)-1)*100} -> 0.26469958 | C11: {=(PRODUCT(1+'25_Portfolios_5x5'!AD548:AD668/100)^(1/120)-1)*100} -> 0.44566253 | D11: {=(PRODUCT(1+'25_Portfolios_5x5'!AE548:AE668/100)^(1/120)-1)*100} -> 0.36460131 | E11: {=(PRODUCT(1+'25_Portfolios_5x5'!AF548:AF668/100)^(1/120)-1)*100} -> 0.62097171 | F11: {=(PRODUCT(1+'25_Portfolios_5x5'!AG548:AG668/100)^(1/120)-1)*100} -> 0.84929289 | G11: {=(PRODUCT(1+'25_Portfolios_5x5'!AH548:AH668/100)^(1/120)-1)*100} -> 0.26096598 | H11: {=(PRODUCT(1+'25_Portfolios_5x5'!AI548:AI668/100)^(1/120)-1)*100} -> 0.31854651 | I11: {=(PRODUCT(1+'25_Portfolios_5x5'!AJ548:AJ668/100)^(1/120)-1)*100} -> 0.38292462 | ... AA11: {=(PRODUCT(1+'25_Portfolios_5x5'!BB548:BB668/100)^(1/120)-1)*100} -> -0.10335919
A12: ='[1]6_Portfolios_2x3'!A549 -> 197011 | B12: {=(PRODUCT(1+'25_Portfolios_5x5'!AC549:AC669/100)^(1/120)-1)*100} -> 0.48837203 | C12: {=(PRODUCT(1+'25_Portfolios_5x5'!AD549:AD669/100)^(1/120)-1)*100} -> 0.55303874 | D12: {=(PRODUCT(1+'25_Portfolios_5x5'!AE549:AE669/100)^(1/120)-1)*100} -> 0.50777114 | E12: {=(PRODUCT(1+'25_Portfolios_5x5'!AF549:AF669/100)^(1/120)-1)*100} -> 0.67834305 | F12: {=(PRODUCT(1+'25_Portfolios_5x5'!AG549:AG669/100)^(1/120)-1)*100} -> 0.89967201 | G12: {=(PRODUCT(1+'25_Portfolios_5x5'!AH549:AH669/100)^(1/120)-1)*100} -> 0.4037534 | H12: {=(PRODUCT(1+'25_Portfolios_5x5'!AI549:AI669/100)^(1/120)-1)*100} -> 0.44314906 | I12: {=(PRODUCT(1+'25_Portfolios_5x5'!AJ549:AJ669/100)^(1/120)-1)*100} -> 0.47374924 | ... AA12: {=(PRODUCT(1+'25_Portfolios_5x5'!BB549:BB669/100)^(1/120)-1)*100} -> -0.10378862
A13: ='[1]6_Portfolios_2x3'!A550 -> 197012 | B13: {=(PRODUCT(1+'25_Portfolios_5x5'!AC550:AC670/100)^(1/120)-1)*100} -> 0.46944485 | C13: {=(PRODUCT(1+'25_Portfolios_5x5'!AD550:AD670/100)^(1/120)-1)*100} -> 0.51761077 | D13: {=(PRODUCT(1+'25_Portfolios_5x5'!AE550:AE670/100)^(1/120)-1)*100} -> 0.49312628 | E13: {=(PRODUCT(1+'25_Portfolios_5x5'!AF550:AF670/100)^(1/120)-1)*100} -> 0.64550844 | F13: {=(PRODUCT(1+'25_Portfolios_5x5'!AG550:AG670/100)^(1/120)-1)*100} -> 0.86501721 | G13: {=(PRODUCT(1+'25_Portfolios_5x5'!AH550:AH670/100)^(1/120)-1)*100} -> 0.3479115 | H13: {=(PRODUCT(1+'25_Portfolios_5x5'!AI550:AI670/100)^(1/120)-1)*100} -> 0.40727729 | I13: {=(PRODUCT(1+'25_Portfolios_5x5'!AJ550:AJ670/100)^(1/120)-1)*100} -> 0.43036735 | ... AA13: {=(PRODUCT(1+'25_Portfolios_5x5'!BB550:BB670/100)^(1/120)-1)*100} -> -0.10030352
... A649: ='[1]6_Portfolios_2x3'!A1186 -> 202312 | B649: {=(PRODUCT(1+'25_Portfolios_5x5'!AC1186:AC1306/100)^(1/120)-1)*100} -> 0.11667029 | C649: {=(PRODUCT(1+'25_Portfolios_5x5'!AD1186:AD1306/100)^(1/120)-1)*100} -> 0.12214085 | D649: {=(PRODUCT(1+'25_Portfolios_5x5'!AE1186:AE1306/100)^(1/120)-1)*100} -> 0.11358393 | E649: {=(PRODUCT(1+'25_Portfolios_5x5'!AF1186:AF1306/100)^(1/120)-1)*100} -> 0.12512296 | F649: {=(PRODUCT(1+'25_Portfolios_5x5'!AG1186:AG1306/100)^(1/120)-1)*100} -> 0.11387442 | G649: {=(PRODUCT(1+'25_Portfolios_5x5'!AH1186:AH1306/100)^(1/120)-1)*100} -> 0.093167739 | H649: {=(PRODUCT(1+'25_Portfolios_5x5'!AI1186:AI1306/100)^(1/120)-1)*100} -> 0.10976198 | I649: {=(PRODUCT(1+'25_Portfolios_5x5'!AJ1186:AJ1306/100)^(1/120)-1)*100} -> #DIV/0! | ... AA649: {=(PRODUCT(1+'25_Portfolios_5x5'!BB1186:BB1306/100)^(1/120)-1)*100} -> #DIV/0!

Sheet Exc_R_f
A1: date | B1: SMALL LoBM | C1: ME1 BM2 | D1: ME1 BM3 | E1: ME1 BM4 | F1: SMALL HiBM | G1: ME2 BM1 | H1: ME2 BM2 | I1: ME2 BM3 | J1: ME2 BM4 | K1: ME2 BM5 | L1: ME3 BM1 | M1: ME3 BM2 | N1: ME3 BM3 | O1: ME3 BM4 | P1: ME3 BM5 | Q1: ME4 BM1 | R1: ME4 BM2 | S1: ME4 BM3 | T1: ME4 BM4 | U1: ME4 BM5 | V1: BIG LoBM | W1: ME5 BM2 | X1: ME5 BM3 | Y1: ME5 BM4 | Z1: BIG HiBM
A2: ='[1]6_Portfolios_2x3'!A539 -> 197001 | B2: ='10years_f'!B2-'10years_f'!$AA2 -> -0.11874006 | C2: ='10years_f'!C2-'10years_f'!$AA2 -> 0.21970277 | D2: ='10years_f'!D2-'10years_f'!$AA2 -> 0.25490331 | E2: ='10years_f'!E2-'10years_f'!$AA2 -> 0.56079564 | F2: ='10years_f'!F2-'10years_f'!$AA2 -> 0.79326468 | G2: ='10years_f'!G2-'10years_f'!$AA2 -> -0.099261774 | H2: ='10years_f'!H2-'10years_f'!$AA2 -> 0.13027972 | I2: ='10years_f'!I2-'10years_f'!$AA2 -> 0.30167507 | ... Z2: ='10years_f'!Z2-'10years_f'!$AA2 -> 0.27166978
A3: ='[1]6_Portfolios_2x3'!A540 -> 197002 | B3: ='10years_f'!B3-'10years_f'!$AA3 -> -0.074544624 | C3: ='10years_f'!C3-'10years_f'!$AA3 -> 0.24256848 | D3: ='10years_f'!D3-'10years_f'!$AA3 -> 0.2691982 | E3: ='10years_f'!E3-'10years_f'!$AA3 -> 0.56309491 | F3: ='10years_f'!F3-'10years_f'!$AA3 -> 0.77181986 | G3: ='10years_f'!G3-'10years_f'!$AA3 -> -0.052571613 | H3: ='10years_f'!H3-'10years_f'!$AA3 -> 0.18399184 | I3: ='10years_f'!I3-'10years_f'!$AA3 -> 0.29160245 | ... Z3: ='10years_f'!Z3-'10years_f'!$AA3 -> 0.32616326
A4: ='[1]6_Portfolios_2x3'!A541 -> 197003 | B4: ='10years_f'!B4-'10years_f'!$AA4 -> -0.30420755 | C4: ='10years_f'!C4-'10years_f'!$AA4 -> 0.028200693 | D4: ='10years_f'!D4-'10years_f'!$AA4 -> 0.068002442 | E4: ='10years_f'!E4-'10years_f'!$AA4 -> 0.38959448 | F4: ='10years_f'!F4-'10years_f'!$AA4 -> 0.56923756 | G4: ='10years_f'!G4-'10years_f'!$AA4 -> -0.25555389 | H4: ='10years_f'!H4-'10years_f'!$AA4 -> 0.0078598138 | I4: ='10years_f'!I4-'10years_f'!$AA4 -> 0.1108606 | ... Z4: ='10years_f'!Z4-'10years_f'!$AA4 -> 0.14075108
A5: ='[1]6_Portfolios_2x3'!A542 -> 197004 | B5: ='10years_f'!B5-'10years_f'!$AA5 -> -0.20249128 | C5: ='10years_f'!C5-'10years_f'!$AA5 -> 0.11794587 | D5: ='10years_f'!D5-'10years_f'!$AA5 -> 0.14327903 | E5: ='10years_f'!E5-'10years_f'!$AA5 -> 0.41985774 | F5: ='10years_f'!F5-'10years_f'!$AA5 -> 0.62418254 | G5: ='10years_f'!G5-'10years_f'!$AA5 -> -0.15736625 | H5: ='10years_f'!H5-'10years_f'!$AA5 -> 0.057349067 | I5: ='10years_f'!I5-'10years_f'!$AA5 -> 0.1595241 | ... Z5: ='10years_f'!Z5-'10years_f'!$AA5 -> 0.14543133
A6: ='[1]6_Portfolios_2x3'!A543 -> 197005 | B6: ='10years_f'!B6-'10years_f'!$AA6 -> 0.079909439 | C6: ='10years_f'!C6-'10years_f'!$AA6 -> 0.34559022 | D6: ='10years_f'!D6-'10years_f'!$AA6 -> 0.33357942 | E6: ='10years_f'!E6-'10years_f'!$AA6 -> 0.58795736 | F6: ='10years_f'!F6-'10years_f'!$AA6 -> 0.79112651 | G6: ='10years_f'!G6-'10years_f'!$AA6 -> 0.12627212 | H6: ='10years_f'!H6-'10years_f'!$AA6 -> 0.29149478 | I6: ='10years_f'!I6-'10years_f'!$AA6 -> 0.34765959 | ... Z6: ='10years_f'!Z6-'10years_f'!$AA6 -> 0.26211678
A7: ='[1]6_Portfolios_2x3'!A544 -> 197006 | B7: ='10years_f'!B7-'10years_f'!$AA7 -> 0.20909257 | C7: ='10years_f'!C7-'10years_f'!$AA7 -> 0.46591305 | D7: ='10years_f'!D7-'10years_f'!$AA7 -> 0.43934414 | E7: ='10years_f'!E7-'10years_f'!$AA7 -> 0.69105449 | F7: ='10years_f'!F7-'10years_f'!$AA7 -> 0.92698 | G7: ='10years_f'!G7-'10years_f'!$AA7 -> 0.27577593 | H7: ='10years_f'!H7-'10years_f'!$AA7 -> 0.42331407 | I7: ='10years_f'!I7-'10years_f'!$AA7 -> 0.47936423 | ... Z7: ='10years_f'!Z7-'10years_f'!$AA7 -> 0.29766839
A8: ='[1]6_Portfolios_2x3'!A545 -> 197007 | B8: ='10years_f'!B8-'10years_f'!$AA8 -> 0.41516007 | C8: ='10years_f'!C8-'10years_f'!$AA8 -> 0.6371016 | D8: ='10years_f'!D8-'10years_f'!$AA8 -> 0.58781662 | E8: ='10years_f'!E8-'10years_f'!$AA8 -> 0.82861461 | F8: ='10years_f'!F8-'10years_f'!$AA8 -> 1.0507173 | G8: ='10years_f'!G8-'10years_f'!$AA8 -> 0.47629662 | H8: ='10years_f'!H8-'10years_f'!$AA8 -> 0.58381161 | I8: ='10years_f'!I8-'10years_f'!$AA8 -> 0.62952438 | ... Z8: ='10years_f'!Z8-'10years_f'!$AA8 -> 0.41253658
A9: ='[1]6_Portfolios_2x3'!A546 -> 197008 | B9: ='10years_f'!B9-'10years_f'!$AA9 -> 0.46728875 | C9: ='10years_f'!C9-'10years_f'!$AA9 -> 0.66444716 | D9: ='10years_f'!D9-'10years_f'!$AA9 -> 0.59583651 | E9: ='10years_f'!E9-'10years_f'!$AA9 -> 0.83251783 | F9: ='10years_f'!F9-'10years_f'!$AA9 -> 1.0598211 | G9: ='10years_f'!G9-'10years_f'!$AA9 -> 0.48771528 | H9: ='10years_f'!H9-'10years_f'!$AA9 -> 0.57861297 | I9: ='10years_f'!I9-'10years_f'!$AA9 -> 0.61205695 | ... Z9: ='10years_f'!Z9-'10years_f'!$AA9 -> 0.36159667
A10: ='[1]6_Portfolios_2x3'!A547 -> 197009 | B10: ='10years_f'!B10-'10years_f'!$AA10 -> 0.47809766 | C10: ='10years_f'!C10-'10years_f'!$AA10 -> 0.632776 | D10: ='10years_f'!D10-'10years_f'!$AA10 -> 0.56065567 | E10: ='10years_f'!E10-'10years_f'!$AA10 -> 0.78651405 | F10: ='10years_f'!F10-'10years_f'!$AA10 -> 1.0309488 | G10: ='10years_f'!G10-'10years_f'!$AA10 -> 0.44850954 | H10: ='10years_f'!H10-'10years_f'!$AA10 -> 0.54044681 | I10: ='10years_f'!I10-'10years_f'!$AA10 -> 0.58078446 | ... Z10: ='10years_f'!Z10-'10years_f'!$AA10 -> 0.30810408
A11: ='[1]6_Portfolios_2x3'!A548 -> 197010 | B11: ='10years_f'!B11-'10years_f'!$AA11 -> 0.36805876 | C11: ='10years_f'!C11-'10years_f'!$AA11 -> 0.54902172 | D11: ='10years_f'!D11-'10years_f'!$AA11 -> 0.46796049 | E11: ='10years_f'!E11-'10years_f'!$AA11 -> 0.7243309 | F11: ='10years_f'!F11-'10years_f'!$AA11 -> 0.95265208 | G11: ='10years_f'!G11-'10years_f'!$AA11 -> 0.36432517 | H11: ='10years_f'!H11-'10years_f'!$AA11 -> 0.4219057 | I11: ='10years_f'!I11-'10years_f'!$AA11 -> 0.48628381 | ... Z11: ='10years_f'!Z11-'10years_f'!$AA11 -> 0.27488423
A12: ='[1]6_Portfolios_2x3'!A549 -> 197011 | B12: ='10years_f'!B12-'10years_f'!$AA12 -> 0.59216065 | C12: ='10years_f'!C12-'10years_f'!$AA12 -> 0.65682735 | D12: ='10years_f'!D12-'10years_f'!$AA12 -> 0.61155976 | E12: ='10years_f'!E12-'10years_f'!$AA12 -> 0.78213167 | F12: ='10years_f'!F12-'10years_f'!$AA12 -> 1.0034606 | G12: ='10years_f'!G12-'10years_f'!$AA12 -> 0.50754202 | H12: ='10years_f'!H12-'10years_f'!$AA12 -> 0.54693767 | I12: ='10years_f'!I12-'10years_f'!$AA12 -> 0.57753786 | ... Z12: ='10years_f'!Z12-'10years_f'!$AA12 -> 0.3368291
A13: ='[1]6_Portfolios_2x3'!A550 -> 197012 | B13: ='10years_f'!B13-'10years_f'!$AA13 -> 0.56974836 | C13: ='10years_f'!C13-'10years_f'!$AA13 -> 0.61791428 | D13: ='10years_f'!D13-'10years_f'!$AA13 -> 0.59342979 | E13: ='10years_f'!E13-'10years_f'!$AA13 -> 0.74581195 | F13: ='10years_f'!F13-'10years_f'!$AA13 -> 0.96532073 | G13: ='10years_f'!G13-'10years_f'!$AA13 -> 0.44821501 | H13: ='10years_f'!H13-'10years_f'!$AA13 -> 0.50758081 | I13: ='10years_f'!I13-'10years_f'!$AA13 -> 0.53067087 | ... Z13: ='10years_f'!Z13-'10years_f'!$AA13 -> 0.27745536
... A649: ='[1]6_Portfolios_2x3'!A1186 -> 202312 | B649: ='10years_f'!B649-'10years_f'!$AA649 -> #DIV/0! | C649: ='10years_f'!C649-'10years_f'!$AA649 -> #DIV/0! | D649: ='10years_f'!D649-'10years_f'!$AA649 -> #DIV/0! | E649: ='10years_f'!E649-'10years_f'!$AA649 -> #DIV/0! | F649: ='10years_f'!F649-'10years_f'!$AA649 -> #DIV/0! | G649: ='10years_f'!G649-'10years_f'!$AA649 -> #DIV/0! | H649: ='10years_f'!H649-'10years_f'!$AA649 -> #DIV/0! | I649: ='10years_f'!I649-'10years_f'!$AA649 -> #DIV/0! | ... Z649: ='10years_f'!Z649-'10years_f'!$AA649 -> #DIV/0!
